Workbook

Sheet 怪物基本表
A1: 复制怪物时请复制对应的本体！ | K1: monster.xml | CI1: monster.xml
C2: monster.xml | E2: 中文名 | F2: 图标 | G2: 小地图标识 | J2: 跨场景 | K2: 怪物类型 | L2: BOSS标记 | M2: 共生怪物 | N2: 物理点击 | O2: shader | P2: 种族 | Q2: 受击分类 | R2: 可否多重射击 | S2: 怪物等级 | V2: 音效 | X2: 共生 | Y2: 模型 | AB2: 重量 | AD2: 穿墙 | AE2: 击退 | AF2: 体型特效 | AG2: 受击顿帧 | AH2: 出场动作 | AI2: 出场特效 | AJ2: 出场前特效 | AK2: 阵营 | AL2: AI | AO2: 技能 | AU2: 怪物buff | AV2: 击飞 | AW2: 反击 | AX2: 死亡特效 | AY2: 指定死亡表现 | BB2: 离场 | BD2: 出场音效 | BE2: 战斗音效 | BF2: 属性 | BI2: 速度 | BM2: 受击 | BQ2: 脱战Aiid | BR2: 基础经验 | BS2: 受击动作 | BT2: 刷怪权重 | BV2: 怪物随从 | BZ2: 刷怪 | CH2: 词缀 | CJ2: 产生怪物 | CM2: TC
D3: 怪物id 10101（关卡怪物） 20000玩家召唤物 30000怪物召唤物 | E3: ChineseID | F3: 头像图标 | G3: 特殊的配置在这里 iconID | H3: 怪物名称下方描述 不填没描述 ChineseID | I3: 是否进行部位判断 0或不填 不判断 1 判断 | J3: 跨场景不删除召唤物 默认0：删除 1：不删除 | K3: 0或不填=其他 1=小怪 2=超级暗金怪 3=BOSS 4=女武神（显示头像） 5=召唤物（不显示头像） 6=多头蛇 7=骨牢 8=场景可破坏物件 9=NPC 10=召唤物（可选中） 11=特殊事件怪物（阵型） 12=墙怪物 13=梦魇怪物 | L3: 是否关底BOSS 1-是 0或不填不是 | M3: 当前怪物ID死亡时，配置的关联怪物也会死亡 填怪物ID，不填则没有 | N3: 不可被选取 物理点击，鼠标无法选中 默认0：可选取 1:不可选取 | O3: 是否调用特殊shader 1-暗金 2-蓝名 3-紫色混沌 4 召唤骷髅青色 5-boss紫红色 | P3: （涉及对怪物种类额外伤害） 0-无种族 1-不死 2-恶魔 3-动物 4-天使 5-梦魇 | Q3: （区分怪物受击表现） 1-骷髅 2-昆虫 3-肉体 | R3: 配0或者不配，不会随机到多重射击词缀； 配1，会随机到多重射击词缀 | S3: 普通难度 | T3: （噩梦难度） 只对BOSS有用，其他由场景决定 | U3: （地狱难度） 只对BOSS有用，其他由场景决定 | V3: 怪物音效 （关联MonSound文件） | W3: 作为暗金怪或精英怪时的音效 （关联MonSound文件） | X3: 共生怪物ID | Y3: 模型id | Z3: 模型大小：1000或不填为原始大小，1500为1.5倍 | AA3: 体型尺寸（CM） | AB3: 用于判定布娃娃碰撞球 1 轻型 2 中等 3 重型 | AC3: 控制于boss尺寸影响技能逻辑 0、不填：影响 1：不影响 | AD3: 是否能穿墙受击 1-是，0或不填-否 | AE3: 怪物体型 （判断20008的击退是否生效） 0或不填或1=100%被击退 2=50%被击退 3=25%被击退 4=不会被击退 | AF3: 根据体型大小播放不同特效 1-小体型 2-中体型 3-大体型 | AG3: 根据体型设定倍率，体型越大倍率越大 体型越大的怪顿帧效果越明显 单位：百分比 | AH3: 是否使用出场动作（born_1） 0或不填：不启用（默认） 填时间(ms)：启用，填写出生动作结束时间 用作机关，这个时长会叠加 | AI3: （出场时播放特效，播放born_1时播放的特效事件） 技能特效主ID,事件ID,触发时间 | AJ3: （用以出场前播放特效） 技能特效主ID,事件ID,触发时间 | AK3: 所属阵营 0-怪物 1-玩家 默认为0 | AL3: AI | AM3: AI激活搜索范围 （需要出场动作才填） | AN3: 是否读AI里搜敌范围 否则全图搜敌 1-是 0或不填-否 | AO3: 怪物技能 (注:AI前后端读技能表的pos_i,此处可以不用排序了) | AP3: 技能等级1 | AQ3: 怪物技能 （噩梦难度） | AR3: 技能等级2 | AS3: 怪物技能 （地狱难度） | AT3: 技能等级3 | AU3: buffid：触发概率，持续时间（毫秒） | AV3: 击飞距离，击飞时间 （CM）,（毫秒） | AW3: 触发血量（百分比） 更换目标（百分比） | AX3: 死亡特效播放判断 | AY3: 有指定死亡表现的怪才填 填了本字段其他死亡效果事件都不会播放 技能特效主ID,事件ID,触发时间 | AZ3: 指定死亡方式 填了die_special_s字段其他死亡方式事件都不会播放 不填：没有特殊效果 1：消融消失 2 直接删除 | BA3: 指定死亡方式参数 （和die_way_i对应） 1：开始时间，持续时间（毫秒） | BB3: 离场动作时间（毫秒） | BC3: 离场表现 | BD3: 怪物出现后，播放音效 配置格式：音效ID,进入距离,脱战距离，播放间隔 音效ID：音乐配置表ID 进入距离：距离BOSS多远开始播音乐（单位：厘米） 脱战距离：距离BOSS多远停止播音乐（单位：厘米） 播放间隔：（单位：毫秒） | BE3: 与该怪物进入战斗后，播放BGM 配置格式：音效ID | BF3: 属性表id | BG3: 召唤物属性 | BH3: 波次属性 新 怪物属性=基本属性+波次属性*波数 注意，玩家的召唤物不要配置 | BI3: 切换到跑步的速度值 第1个：移动速度 第2个：跑步速度 第三个：动作阀值 | BJ3: 速度参数 移动，巡逻，观望，逃跑 （单位cm/s） | BK3: 动作速度 100——500 | BL3: 出生旋转角度 | BM3: 是否在实际受击位置播放受击特效 1:在受击位置播放特效 0或空：播放位置不变 | BN3: 受击原点偏移量 填（x,y,z）乘以100 | BO3: 受击半径 / cm | BP3: 受击高度 / cm | BQ3: 进入战斗状态后技能没使用累计时间(ms)，距离出生点距离(cm) | BR3: (受经验加成影响) 需要和怪物等级表算出最终基础经验值 | BS3: 受击时是否播放受击动作 0或空：播放 1：不播放 | BT3: 出现权重 （地图确定怪物时概率） | BU3: 刷出权重 （每个怪区选择怪物时概率） (不能填0） | BV3: 随机怪物ID monsterID | BW3: 固定怪物组 优先级高于随机怪物 怪物ID+数量 | BX3: 随从最少数量 | BY3: 随从最大数量 建议不超过15 | BZ3: 刷出的最小数目 （普通） | CA3: 刷出的最大数目 （普通） | CB3: 刷出的最小数目 （噩梦） | CC3: 刷出的最大数目 （噩梦） | CD3: 刷出的最小数目 （地狱） | CE3: 刷出的最大数目 （地狱） | CF3: 刷出的最小数目 （异界） | CG3: 刷出的最大数目 （异界） | CH3: 固定词缀 填词缀ID 不填没有 | CI3: 随机词缀 数量：词缀ID1，词缀ID2 | CJ3: 此怪物是否可以产生其他怪物 （1可以产生，0或不填不可产生） | CK3: 此怪物可以产生的怪物ID | CL3: 产生的怪物出生位置坐标 | CM3: 掉落包 掉落ID | CN3: 普通怪物精英化掉落 怪物必须是1类型 当精英化为蓝色怪物时读取 | CO3: 首杀掉落包 掉落ID 0或不填则没有 | CP3: 无尽模式掉落包 掉落ID 0或不填则没有 | CQ3: 触发该怪为任务TC的任务ID | CR3: 要触发该怪为任务TC所需要完成的任务ID
D4: id_i | E4: monster_name_i | F4: monster_icon_i | G4: map_icon_i | H4: descstr_i | I4: is_part_judge_i | J4: cross_scene_i | K4: monster_type_i | L4: close_boss_i | M4: symbiosis_monster_l | N4: physical_click_i | O4: shader_i | P4: montype_i | Q4: monrace_i | R4: multi_shot_i | S4: lv_i | T4: lv_n_i | U4: lv_h_i | V4: monsound_i | W4: umonsound_i | X4: symbiotic_monster_l | Y4: model_id_i | Z4: model_scale_i | AA4: shape_i | AB4: weight_i | AC4: model_Logic_i | AD4: through_wall_i | AE4: size_i | AF4: effect_size_i | AG4: hit_pause_i | AH4: exit_action_i | AI4: exit_fx_s | AJ4: fx_skill_s | AK4: faction_i | AL4: ai_id_i | AM4: search_range_i | AN4: ai_search_i | AO4: skill_ids_l | AP4: skill_lv_l | AQ4: skill_ids_2_l | AR4: skill_lv_2_l | AS4: skill_ids_3_l | AT4: skill_lv_3_l | AU4: skill_buff_n | AV4: fly_distance_l | AW4: counter_attack_n | AX4: die_type_l | AY4: die_special_s | AZ4: die_way_i | BA4: die_parameter_l | BB4: leave_time_i | BC4: leave_fx_s | BD4: appear_music_l | BE4: fight_music_i | BF4: property_id_i | BG4: summon_attri_m | BH4: property_wave_m | BI4: act_shift_l | BJ4: base_speed_l | BK4: base_animation_speed_l | BL4: born_face_i | BM4: is_hit_range_i | BN4: be_hit_point_l | BO4: be_hit_radius_i | BP4: be_hit_height_i | BQ4: break_up_action_ai_l | BR4: drop_exp_i | BS4: cant_be_hit_i | BT4: rarity_i | BU4: rarity2_i | BV4: minion_l | BW4: fixed_monster_group_m | BX4: partymin_i | BY4: partymax_i | BZ4: mingrp_i | CA4: maxgrp_i | CB4: mingrp_n_i | CC4: maxgrp_n_i | CD4: mingrp_h_i | CE4: maxgrp_h_i | CF4: mingrp_v_i | CG4: maxgrp_v_i | CH4: fixed_affix_l | CI4: random_affix_n | CJ4: placespawn_i | CK4: spawn_i | CL4: spawnx_n | CM4: treasureclass_i | CN4: blue_treasureclass_i | CO4: firstkill_treasureclass_i | CP4: endless_treasureclass_i | CQ4: tctaskid_i | CR4: tccomtaskid_i
A5: 地图关卡 | B5: 种类 | C5: 特征 | D5: 0 | E5: 0 | F5: 0 | G5: 0 | H5: 0 | I5: 0 | J5: 0 | K5: 0 | L5: 0 | M5: 0 | N5: 0 | O5: 0 | P5: 0 | Q5: 1 | R5: 0 | S5: 0 | T5: 0 | U5: 0 | V5: 0 | W5: 0 | X5: 0 | Y5: 0 | Z5: 1000 | AA5: 0 | AB5: 1 | AD5: 0 | AE5: 0 | AF5: 1 | AG5: 1 | AH5: 2000 | AI5: 0 | AJ5: 0 | AK5: 0 | AL5: 0 | AM5: 0 | AN5: 0 | AO5: 0 | AP5: 0 | AQ5: 0 | AR5: 0 | AS5: 0 | AT5: 0 | AU5: 0:0 | AV5: 0,0 | AW5: 0:0 | AX5: 0,0 | AY5: 100001,2,200 | AZ5: 1 | BA5: 500,2000 | BB5: 2000 | BC5: 100001,2,200 | BD5: 300,1000,5200,10000 | BE5: 300,1000,5200 | BF5: 0 | BG5: 1:1;2:2 | BH5: 202:10;302:20 | BI5: 0,0 | BJ5: 10,2,3,4 | BK5: 100 | BL5: 0 | BM5: 0 | BN5: 0,0,0 | BO5: 0 | BP5: 0 | BQ5: 1,30000,4000 | BR5: 1 | BS5: 0 | BT5: 0 | BU5: 0 | BV5: 0 | BW5: 0:0 | BX5: 0 | BY5: 0 | BZ5: 0 | CA5: 0 | CB5: 0 | CC5: 0 | CD5: 0 | CE5: 0 | CF5: 0 | CG5: 0 | CH5: 0 | CI5: 0:0 | CJ5: 0 | CK5: 0 | CL5: 0:0 | CM5: 0 | CN5: 0 | CO5: 0 | CP5: 0 | CQ5: 0 | CR5: 0
A6: BOSS技能 | B6: 魂魄 | C6: 骸骨之魂——自爆 | D6: 100 | E6: 70051 | H6: 0 | K6: 1 | P6: 1 | Q6: 3 | S6: 1 | T6: 1 | U6: 1 | Y6: 4081 | Z6: 1000 | AA6: 100 | AB6: 1 | AF6: 1 | AG6: 100 | AK6: 0 | AL6: 21001 | AM6: 4000 | AO6: 31104 | AP6: 1 | AQ6: 31104 | AR6: 1 | AS6: 31104 | AT6: 1 | AU6: 13260:10000,-1;31105:10000,-1 | AW6: 3:10;50:50 | AX6: 4,5,6,7,8 | AY6: 1093005,8,0 | AZ6: 2 | BF6: 10011 | BI6: 300,600 | BJ6: 600,100,100,100 | BK6: 100,100,100,200 | BO6: 50 | BP6: 200 | BQ6: 1,30000,4000 | BR6: 1 | BT6: 50 | BU6: 50 | BZ6: 3 | CA6: 4 | CB6: 4 | CC6: 4 | CD6: 4 | CE6: 5 | CF6: 4 | CG6: 4 | CM6: 100005
A7: BOSS技能 | B7: 傀儡蜘蛛 | C7: 骸骨之魂——自爆 | D7: 101 | E7: 70052 | H7: 0 | K7: 1 | P7: 1 | Q7: 3 | S7: 1 | T7: 1 | U7: 1 | Y7: 1540 | Z7: 1000 | AA7: 200 | AB7: 1 | AF7: 1 | AG7: 100 | AK7: 0 | AL7: 21001 | AM7: 4000 | AO7: 31338 | AP7: 1 | AQ7: 31338 | AR7: 1 | AS7: 31338 | AT7: 1 | AU7: 31339:10000,-1 | AW7: 3:10;50:50 | AX7: 4,5,6,7,8 | BF7: 10011 | BI7: 300,600 | BJ7: 600,100,100,100 | BK7: 100,100,100,200 | BO7: 50 | BP7: 200 | BQ7: 1,30000,4000 | BR7: 1 | BT7: 50 | BU7: 50 | BZ7: 3 | CA7: 4 | CB7: 4 | CC7: 4 | CD7: 4 | CE7: 5 | CF7: 4 | CG7: 4 | CM7: 100005
A8: BOSS技能 | B8: 火魂 | C8: 火魂——旋转火 | D8: 102 | E8: 70053 | H8: 0 | K8: 1 | P8: 1 | Q8: 3 | S8: 1 | T8: 1 | U8: 1 | Y8: 12202 | Z8: 1000 | AA8: 10 | AB8: 1 | AF8: 1 | AG8: 100 | AK8: 0 | AL8: 10002 | AM8: 4000 | AO8: 31529 | AP8: 1 | AQ8: 31529 | AR8: 1 | AS8: 31529 | AT8: 1 | AU8: 13260:10000,-1;31529:10000,-1 | AW8: 3:10;50:50 | AX8: 4,5,6,7,8 | BF8: 10011 | BI8: 150,350 | BJ8: 100,100,100,100 | BK8: 100,100,100,200 | BO8: 50 | BP8: 200 | BQ8: 1,30000,4000 | BR8: 1 | BT8: 50 | BU8: 50 | BZ8: 3 | CA8: 4 | CB8: 4 | CC8: 4 | CD8: 4 | CE8: 5 | CF8: 4 | CG8: 4 | CM8: 100005
A9: 难度符文怪物 | B9: 盗宝地精 | D9: 1001 | E9: 70031 | G9: 301 | K9: 2 | O9: 1 | P9: 2 | Q9: 3 | S9: 1 | T9: 1 | U9: 1 | Y9: 1347 | Z9: 1000 | AA9: 300 | AB9: 3 | AF9: 1 | AG9: 100 | AK9: 0 | AL9: 20004 | AM9: 1000 | AO9: 30001 | AP9: 1 | AQ9: 30001 | AR9: 1 | AS9: 30001 | AT9: 1 | AV9: 450,500 | AW9: 3:10;50:50 | AX9: 4,5,6,7,8 | BF9: 1001 | BH9: 202:15;302:60 | BI9: 200,500 | BJ9: 650,100,100,100 | BK9: 100,100,100,200 | BO9: 150 | BP9: 200 | BQ9: 1,30000,4000 | BR9: 1 | BT9: 50 | BU9: 50 | BZ9: 3 | CA9: 3 | CB9: 2 | CC9: 3 | CD9: 6 | CE9: 8 | CF9: 2 | CG9: 3 | CM9: 116001 | CP9: 116001
A10: 难度符文怪物 | B10: 猎狗 | D10: 1002 | E10: 70011 | H10: 0 | K10: 1 | P10: 3 | Q10: 3 | S10: 1 | T10: 1 | U10: 1 | Y10: 1202 | Z10: 1000 | AA10: 200 | AB10: 1 | AF10: 1 | AG10: 100 | AK10: 0 | AL10: 21001 | AM10: 1000 | AO10: 30001,30002 | AP10: 1,1 | AQ10: 30001,30002 | AR10: 1,1 | AS10: 30001,30002 | AT10: 1,1 | AV10: 550,700 | AW10: 3:10;50:50 | AX10: 4,5,6,7,8 | BF10: 10521 | BH10: 202:5;302:30 | BI10: 300,600 | BJ10: 500,100,100,100 | BK10: 100,100,100,200 | BO10: 100 | BP10: 200 | BQ10: 1,30000,4000 | BR10: 1 | BT10: 50 | BU10: 10 | BZ10: 2 | CA10: 2 | CB10: 3 | CC10: 3 | CD10: 4 | CE10: 4 | CF10: 3 | CG10: 3 | CM10: 100005 | CP10: 100005
A11: 难度符文怪物 | B11: 灵魂追击 | D11: 1003 | E11: 70054 | H11: 0 | K11: 1 | P11: 1 | Q11: 3 | S11: 1 | T11: 1 | U11: 1 | Y11: 4081 | Z11: 1000 | AA11: 100 | AB11: 1 | AF11: 1 | AG11: 100 | AK11: 0 | AL11: 21001 | AM11: 4000 | AO11: 31104 | AP11: 1 | AQ11: 31104 | AR11: 1 | AS11: 31104 | AT11: 1 | AU11: 13260:10000,-1;31106:10000,-1 | AW11: 3:10;50:50 | AX11: 4,5,6,7,8 | AY11: 1093005,8,0 | AZ11: 2 | BF11: 10011 | BI11: 150,350 | BJ11: 500,100,100,100 | BK11: 100,100,100,200 | BO11: 50 | BP11: 200 | BQ11: 1,30000,4000 | BR11: 1 | BT11: 50 | BU11: 50 | BZ11: 3 | CA11: 4 | CB11: 4 | CC11: 4 | CD11: 4 | CE11: 5 | CF11: 4 | CG11: 4 | CM11: 100005 | CP11: 100005
A12: 难度符文怪物 | B12: 雷电陷阱 | D12: 1004 | E12: 70118 | K12: 1 | P12: 1 | Q12: 1 | S12: 1 | T12: 1 | U12: 1 | Y12: 4070 | Z12: 1000 | AA12: 100 | AB12: 1 | AF12: 1 | AG12: 100 | AK12: 0 | AL12: 21099 | AM12: 1000 | AO12: 45001 | AP12: 1 | AQ12: 45001 | AR12: 1 | AS12: 45001 | AT12: 1 | AU12: 13260:10000,-1 | AW12: 3:10;50:50 | AX12: 4,5,6,7,8 | BF12: 11501 | BH12: 202:5;302:30 | BI12: 150,300 | BJ12: 400,100,100,100 | BK12: 100,100,100,200 | BO12: 100 | BP12: 200 | BQ12: 1,30000,4000 | BR12: 1 | BT12: 50 | BU12: 40 | CM12: 100005 | CP12: 100005
A13: 场景机制用 | B13: BOSS连线 | D13: 1011 | E13: 70118 | K13: 1 | P13: 1 | Q13: 1 | S13: 1 | T13: 1 | U13: 1 | Y13: 1101 | Z13: 1000 | AA13: 100 | AB13: 1 | AF13: 1 | AG13: 100 | AK13: 0 | AL13: 12007 | AM13: 1000 | AO13: 45001 | AP13: 1 | AQ13: 45001 | AR13: 1 | AS13: 45001 | AT13: 1 | AU13: 13260:10000,-1;33125:10000,-1 | AW13: 3:10;50:50 | AX13: 4,5,6,7,8 | BF13: 11501 | BH13: 202:5;302:30 | BI13: 150,300 | BJ13: 400,100,100,100 | BK13: 100,100,100,200 | BO13: 100 | BP13: 200 | BQ13: 1,30000,4000 | BR13: 1 | BT13: 50 | BU13: 40
A14: ACT1新 | B14: 普通骷髅 | D14: 10001 | E14: 70001 | H14: 0 | K14: 1 | P14: 1 | Q14: 1 | S14: 1 | T14: 1 | U14: 1 | Y14: 1002 | Z14: 1000 | AA14: 200 | AB14: 1 | AF14: 1 | AG14: 100 | AK14: 0 | AL14: 21001 | AM14: 1000 | AO14: 30001,30002 | AP14: 1,1 | AQ14: 10011,10012 | AR14: 1,1 | AS14: 10011,10012 | AT14: 1,1 | AW14: 3:10;50:50 | AX14: 4,5,6,7,8 | BF14: 10001 | BH14: 202:5;302:30 | BI14: 150,350 | BJ14: 300,100,100,100 | BK14: 100,100,100,200 | BO14: 50 | BP14: 200 | BQ14: 1,30000,4000 | BR14: 1 | BT14: 50 | BU14: 50 | BZ14: 3 | CA14: 4 | CB14: 4 | CC14: 4 | CD14: 4 | CE14: 5 | CF14: 4 | CG14: 4 | CH14: 1 | CI14: 1:3 | CM14: 100005 | CN14: 100057 | CP14: 100005
B15: 骷髅盾卫 | D15: 10011 | E15: 70002 | H15: 0 | K15: 1 | P15: 1 | Q15: 1 | S15: 1 | T15: 1 | U15: 1 | Y15: 1095 | Z15: 1300 | AA15: 200 | AB15: 2 | AF15: 1 | AG15: 100 | AK15: 0 | AL15: 21001 | AM15: 1000 | AO15: 30001,30002 | AP15: 1,1 | AQ15: 10011,10012 | AR15: 1,1 | AS15: 10011,10012 | AT15: 1,1 | AW15: 3:10;50:50 | AX15: 4,5,6,7,8 | BF15: 10011 | BH15: 202:5;302:30 | BI15: 200,350 | BJ15: 300,100,100,100 | BK15: 100,100,100,200 | BO15: 50 | BP15: 200 | BQ15: 1,30000,4000 | BR15: 1 | BT15: 50 | BU15: 50 | BZ15: 3 | CA15: 4 | CB15: 4 | CC15: 4 | CD15: 5 | CE15: 6 | CF15: 4 | CG15: 4 | CH15: 3 | CI15: 1:5 | CM15: 100005 | CN15: 100057 | CP15: 100005
B16: 骷髅战士 | D16: 10021 | E16: 70003 | H16: 0 | K16: 1 | P16: 1 | Q16: 1 | S16: 1 | T16: 1 | U16: 1 | Y16: 1040 | Z16: 1000 | AA16: 200 | AB16: 1 | AF16: 1 | AG16: 100 | AK16: 0 | AL16: 21003 | AM16: 1000 | AO16: 30013,30014 | AP16: 1,1 | AQ16: 10411,10412 | AR16: 1,1 | AS16: 10411,10412 | AT16: 1,1 | AW16: 3:10;50:50 | AX16: 4,5,6,7,8 | BF16: 10021 | BH16: 202:5;302:30 | BI16: 200,400 | BJ16: 320,100,100,100 | BK16: 100,100,100,200 | BO16: 100 | BP16: 200 | BQ16: 1,30000,4000 | BR16: 1 | BT16: 50 | BU16: 50 | BZ16: 2 | CA16: 3 | CB16: 3 | CC16: 4 | CD16: 4 | CE16: 5 | CF16: 3 | CG16: 4 | CH16: 1 | CI16: 1:11 | CM16: 100005 | CN16: 100057 | CP16: 100005
B17: 骷髅弓手 | D17: 10031 | E17: 70004 | H17: 0 | K17: 1 | P17: 1 | Q17: 1 | S17: 1 | T17: 1 | U17: 1 | Y17: 1004 | Z17: 1000 | AA17: 200 | AB17: 1 | AF17: 1 | AG17: 100 | AK17: 0 | AL17: 21009 | AM17: 1000 | AO17: 46041 | AP17: 1 | AQ17: 46041 | AR17: 1 | AS17: 46041 | AT17: 1 | AW17: 3:10;50:50 | AX17: 4,5,6,7,8 | BF17: 10031 | BH17: 202:5;302:30 | BI17: 150,350 | BJ17: 450,100,100,100 | BK17: 100,100,100,200 | BO17: 100 | BP17: 200 | BQ17: 1,30000,4000 | BR17: 1 | BT17: 50 | BU17: 50 | BZ17: 2 | CA17: 3 | CB17: 3 | CC17: 3 | CD17: 3 | CE17: 4 | CF17: 3 | CG17: 3 | CH17: 4 | CI17: 1:6 | CM17: 100005 | CN17: 100057 | CP17: 100005
B18: 骷髅法师 | D18: 10041 | E18: 70005 | K18: 1 | P18: 1 | Q18: 1 | S18: 1 | T18: 1 | U18: 1 | Y18: 1020 | Z18: 1000 | AA18: 300 | AB18: 1 | AF18: 1 | AG18: 100 | AK18: 0 | AL18: 21005 | AM18: 1000 | AO18: 30073 | AP18: 1 | AQ18: 30073 | AR18: 1 | AS18: 30073 | AT18: 1 | AV18: 450,500 | AW18: 3:10;50:50 | AX18: 4,5,6,7,8 | BF18: 10041 | BH18: 202:5;302:30 | BI18: 150,300 | BJ18: 350,100,100,100 | BK18: 100,100,100,200 | BO18: 100 | BP18: 200 | BQ18: 1,30000,4000 | BR18: 1 | BT18: 50 | BU18: 40 | BZ18: 1 | CA18: 1 | CB18: 1 | CC18: 1 | CD18: 1 | CE18: 1 | CF18: 1 | CG18: 1 | CH18: 14 | CI18: 1:15 | CM18: 100005 | CN18: 100057 | CP18: 100005
B19: 骷髅刺客 | D19: 10051 | E19: 70006 | H19: 0 | K19: 1 | P19: 1 | Q19: 1 | S19: 1 | T19: 1 | U19: 1 | Y19: 1007 | Z19: 1000 | AA19: 200 | AB19: 1 | AF19: 1 | AG19: 100 | AK19: 0 | AL19: 21007 | AM19: 1000 | AO19: 30001,30002 | AP19: 1,1 | AQ19: 10071,10072 | AR19: 1,1 | AS19: 10071,10072 | AT19: 1,1 | AV19: 450,500 | AW19: 3:10;50:50 | AX19: 4,5,6,7,8 | BF19: 10051 | BH19: 202:5;302:30 | BI19: 150,350 | BJ19: 400,100,100,100 | BK19: 100,100,100,200 | BO19: 100 | BP19: 200 | BQ19: 1,30000,4000 | BR19: 1 | BT19: 50 | BU19: 50 | BZ19: 3 | CA19: 4 | CB19: 4 | CC19: 4 | CD19: 4 | CE19: 5 | CF19: 4 | CG19: 4 | CH19: 11 | CI19: 1:27 | CM19: 100005 | CN19: 100057 | CP19: 100005
B20: 中级骷髅战士 | D20: 10061 | E20: 70007 | H20: 0 | K20: 1 | P20: 1 | Q20: 1 | S20: 1 | T20: 1 | U20: 1 | Y20: 1003 | Z20: 1000 | AA20: 200 | AB20: 2 | AF20: 1 | AG20: 100 | AK20: 0 | AL20: 21003 | AM20: 1000 | AO20: 30009,30010 | AP20: 1,1 | AQ20: 10031,10032 | AR20: 1,1 | AS20: 10031,10032 | AT20: 1,1 | AW20: 3:10;50:50 | AX20: 4,5,6,7,8 | BF20: 10061 | BH20: 202:5;302:30 | BI20: 150,350 | BJ20: 300,100,100,100 | BK20: 100,100,100,200 | BO20: 100 | BP20: 200 | BQ20: 1,30000,4000 | BR20: 1 | BT20: 50 | BU20: 50 | BZ20: 2 | CA20: 3 | CB20: 3 | CC20: 4 | CD20: 4 | CE20: 5 | CF20: 3 | CG20: 4 | CH20: 1 | CI20: 1:11 | CM20: 100005 | CN20: 100057 | CP20: 100005
B21: 骷髅长刀 | D21: 10071 | E21: 70008 | H21: 0 | K21: 1 | P21: 1 | Q21: 1 | S21: 1 | T21: 1 | U21: 1 | Y21: 1041 | Z21: 1000 | AA21: 200 | AB21: 2 | AF21: 1 | AG21: 100 | AK21: 0 | AL21: 21003 | AM21: 1000 | AO21: 30013,30014 | AP21: 1,1 | AQ21: 10411,10412 | AR21: 1,1 | AS21: 10411,10412 | AT21: 1,1 | AW21: 3:10;50:50 | AX21: 4,5,6,7,8 | BF21: 10071 | BH21: 202:5;302:30 | BI21: 200,400 | BJ21: 320,100,100,100 | BK21: 100,100,100,200 | BO21: 100 | BP21: 200 | BQ21: 1,30000,4000 | BR21: 1 | BT21: 50 | BU21: 50 | BZ21: 2 | CA21: 3 | CB21: 3 | CC21: 4 | CD21: 4 | CE21: 5 | CF21: 3 | CG21: 4 | CH21: 25 | CI21: 1:8 | CM21: 100005 | CN21: 100057 | CP21: 100005
B22: 行尸 | D22: 10501 | E22: 70009 | H22: 0 | K22: 1 | P22: 1 | Q22: 3 | S22: 1 | T22: 1 | U22: 1 | Y22: 1101 | Z22: 1000 | AA22: 200 | AB22: 1 | AF22: 1 | AG22: 100 | AK22: 0 | AL22: 21010 | AM22: 1000 | AO22: 30022 | AP22: 1 | AQ22: 11011 | AR22: 1 | AS22: 11011 | AT22: 1 | AV22: 450,500 | AW22: 3:10;50:50 | AX22: 4,5,6,7,8 | BF22: 10501 | BH22: 202:5;302:30 | BI22: 150,300 | BJ22: 300,100,100,100 | BK22: 100,100,100,200 | BO22: 50 | BP22: 200 | BQ22: 1,30000,4000 | BR22: 1 | BT22: 50 | BU22: 40 | BZ22: 2 | CA22: 3 | CB22: 4 | CC22: 4 | CD22: 5 | CE22: 5 | CF22: 4 | CG22: 4 | CH22: 5 | CI22: 1:10 | CM22: 100005 | CN22: 100057 | CP22: 100005
B23: 高级行尸 | D23: 10511 | E23: 70010 | H23: 0 | K23: 1 | P23: 1 | Q23: 3 | S23: 1 | T23: 1 | U23: 1 | Y23: 1104 | Z23: 1000 | AA23: 200 | AB23: 1 | AF23: 1 | AG23: 100 | AK23: 0 | AL23: 21011 | AM23: 1100 | AO23: 30025 | AP23: 1 | AQ23: 11041 | AR23: 1 | AS23: 11041 | AT23: 1 | AV23: 450,500 | AW23: 3:10;50:50 | AX23: 4,5,6,7,8 | BF23: 10511 | BH23: 202:5;302:30 | BI23: 282,282 | BJ23: 350,100,100,100 | BK23: 100,100,100,200 | BO23: 100 | BP23: 200 | BQ23: 1,30000,4000 | BR23: 1 | BT23: 50 | BU23: 50 | BZ23: 1 | CA23: 1 | CB23: 1 | CC23: 2 | CD23: 2 | CE23: 2 | CF23: 1 | CG23: 2 | CH23: 5 | CI23: 1:10,16 | CM23: 100005 | CN23: 100057 | CP23: 100005
B24: 食腐犬 | D24: 10521 | E24: 70011 | H24: 0 | K24: 1 | P24: 3 | Q24: 3 | S24: 1 | T24: 1 | U24: 1 | Y24: 1202 | Z24: 1000 | AA24: 200 | AB24: 1 | AF24: 1 | AG24: 100 | AK24: 0 | AL24: 21001 | AM24: 1000 | AO24: 30001,30002 | AP24: 1,1 | AQ24: 30001,30002 | AR24: 1,1 | AS24: 30001,30002 | AT24: 1,1 | AV24: 550,700 | AW24: 3:10;50:50 | AX24: 4,5,6,7,8 | BF24: 10521 | BH24: 202:5;302:30 | BI24: 300,600 | BJ24: 500,100,100,100 | BK24: 100,100,100,200 | BO24: 100 | BP24: 200 | BQ24: 1,30000,4000 | BR24: 1 | BT24: 50 | BU24: 10 | BZ24: 2 | CA24: 2 | CB24: 3 | CC24: 3 | CD24: 4 | CE24: 4 | CF24: 3 | CG24: 3 | CH24: 5 | CI24: 1:13,26 | CM24: 100005 | CN24: 100057 | CP24: 100005
B25: 自爆僵尸 | D25: 10531 | E25: 70012 | H25: 0 | K25: 1 | P25: 1 | Q25: 3 | S25: 1 | T25: 1 | U25: 1 | Y25: 11101 | Z25: 1000 | AA25: 300 | AB25: 1 | AF25: 1 | AG25: 100 | AK25: 0 | AL25: 21014 | AM25: 1000 | AO25: 30026,30027 | AP25: 1,1 | AQ25: 11101,11102 | AR25: 1,1 | AS25: 11101,11102 | AT25: 1,1 | AW25: 3:10;50:50 | AX25: 4,5,6,7,8 | AY25: 1110002,6,1000 | AZ25: 1 | BA25: 1000,100 | BF25: 10531 | BH25: 202:5;302:30 | BI25: 150,300 | BJ25: 450,100,100,100 | BK25: 100,100,100,200 | BO25: 100 | BP25: 200 | BQ25: 1,30000,4000 | BR25: 1 | BT25: 50 | BU25: 50 | BZ25: 3 | CA25: 4 | CB25: 4 | CC25: 5 | CD25: 5 | CE25: 6 | CF25: 4 | CG25: 5 | CH25: 10 | CI25: 1:13,2 | CM25: 100005 | CN25: 100057 | CP25: 100005
B26: 火焰恶魔 | D26: 10541 | E26: 70013 | K26: 1 | P26: 2 | Q26: 3 | S26: 1 | T26: 1 | U26: 1 | Y26: 1613 | Z26: 1000 | AA26: 200 | AB26: 1 | AF26: 1 | AG26: 100 | AK26: 0 | AL26: 21001 | AM26: 1000 | AO26: 30001,30002 | AP26: 1,1 | AQ26: 30001,30002 | AR26: 1,1 | AS26: 30001,30002 | AT26: 1,1 | AV26: 450,500 | AW26: 3:10;50:50 | AX26: 4,5,6,7,8 | BF26: 10541 | BH26: 202:5;302:30 | BI26: 200,500 | BJ26: 350,100,100,100 | BK26: 100,100,100,200 | BO26: 100 | BP26: 200 | BQ26: 1,30000,4000 | BR26: 1 | BT26: 50 | BU26: 30 | BZ26: 1 | CA26: 1 | CB26: 1 | CC26: 1 | CD26: 1 | CE26: 1 | CF26: 1 | CG26: 1 | CI26: 1:15,18 | CM26: 100005 | CN26: 100057 | CP26: 100005
B27: 冲锋怪物 | D27: 10551 | E27: 70014 | H27: 0 | K27: 11 | P27: 1 | Q27: 1 | S27: 1 | T27: 1 | U27: 1 | Y27: 1020 | Z27: 1000 | AA27: 300 | AB27: 1 | AF27: 1 | AG27: 100 | AK27: 0 | AL27: 23023 | AM27: 1000 | AO27: 30001,30002 | AP27: 1,1 | AQ27: 10011,10012 | AR27: 1,1 | AS27: 10011,10012 | AT27: 1,1 | AW27: 3:10;50:50 | AX27: 4,5,6,7,8 | BF27: 10551 | BH27: 202:5;302:30 | BI27: 200,350 | BJ27: 600,100,100,100 | BK27: 100,100,100,200 | BO27: 50 | BP27: 200 | BQ27: 1,30000,4000 | BR27: 1 | BT27: 50 | BU27: 50 | BZ27: 3 | CA27: 4 | CB27: 4 | CC27: 4 | CD27: 5 | CE27: 6 | CF27: 4 | CG27: 4 | CM27: 100005 | CN27: 100057 | CP27: 100005
B28: 骷髅精英战士 | D28: 10601 | E28: 70015 | H28: 0 | K28: 2 | O28: 1 | P28: 1 | Q28: 1 | S28: 1 | T28: 1 | U28: 1 | Y28: 1003 | Z28: 1300 | AA28: 200 | AB28: 2 | AE28: 4 | AF28: 1 | AG28: 100 | AK28: 0 | AL28: 21003 | AM28: 1000 | AO28: 30151,30010 | AP28: 1,1 | AQ28: 30151,30010 | AR28: 1,1 | AS28: 30151,30010 | AT28: 1,1 | AU28: 2009:10000,-1 | AW28: 3:10;50:50 | AX28: 4,5,6,7,8 | BF28: 10601 | BH28: 202:5;302:50 | BI28: 150,350 | BJ28: 500,100,100,100 | BK28: 100,100,100,200 | BO28: 100 | BP28: 200 | BQ28: 1,30000,4000 | BR28: 2 | BT28: 50 | BU28: 50 | BZ28: 2 | CA28: 3 | CB28: 3 | CC28: 4 | CD28: 4 | CE28: 5 | CF28: 3 | CG28: 4 | CI28: 1:13,3 | CM28: 110101 | CP28: 110101
B29: 精英骷髅法师 | D29: 10611 | E29: 70016 | K29: 2 | O29: 1 | P29: 1 | Q29: 1 | S29: 1 | T29: 1 | U29: 1 | Y29: 1020 | Z29: 1300 | AA29: 300 | AB29: 2 | AE29: 4 | AF29: 1 | AG29: 100 | AK29: 0 | AL29: 21005 | AM29: 1000 | AO29: 30070,30071 | AP29: 1,1 | AQ29: 30070,30071,30072 | AR29: 1,1,1 | AS29: 30070,30071,30072 | AT29: 1,1,1 | AU29: 2009:10000,-1 | AV29: 450,500 | AW29: 3:10;50:50 | AX29: 4,5,6,7,8 | BF29: 10611 | BH29: 202:5;302:50 | BI29: 150,300 | BJ29: 450,100,100,100 | BK29: 100,100,100,200 | BO29: 100 | BP29: 200 | BQ29: 1,30000,4000 | BR29: 2 | BT29: 50 | BU29: 40 | BZ29: 1 | CA29: 1 | CB29: 1 | CC29: 1 | CD29: 1 | CE29: 1 | CF29: 1 | CG29: 1 | CH29: 35 | CI29: 1:18,22 | CM29: 110102 | CP29: 110102
B30: 魔弓 | D30: 10621 | E30: 70017 | H30: 0 | K30: 2 | O30: 1 | P30: 1 | Q30: 1 | S30: 1 | T30: 1 | U30: 1 | Y30: 1004 | Z30: 1500 | AA30: 200 | AB30: 2 | AE30: 4 | AF30: 1 | AG30: 100 | AK30: 0 | AL30: 21009 | AM30: 1000 | AO30: 30082,30081 | AP30: 1,1 | AQ30: 30082,30081 | AR30: 1,1 | AS30: 30082,30081 | AT30: 1,1 | AU30: 2009:10000,-1 | AW30: 3:10;50:50 | AX30: 4,5,6,7,8 | BF30: 10621 | BH30: 202:5;302:50 | BI30: 150,350 | BJ30: 450,100,100,100 | BK30: 100,100,100,200 | BO30: 100 | BP30: 200 | BQ30: 1,30000,4000 | BR30: 2 | BT30: 50 | BU30: 50 | BZ30: 2 | CA30: 3 | CB30: 3 | CC30: 3 | CD30: 3 | CE30: 4 | CF30: 3 | CG30: 3 | CH30: 32 | CI30: 1:17,23,6 | CM30: 110103 | CP30: 110103
B31: 骷髅将领 | D31: 10701 | E31: 70018 | G31: 302 | H31: 0 | K31: 3 | M31: 10811 | O31: 5 | P31: 1 | Q31: 1 | S31: 1 | T31: 1 | U31: 1 | Y31: 1005 | Z31: 1500 | AA31: 300 | AB31: 3 | AE31: 4 | AF31: 1 | AG31: 100 | AK31: 0 | AL31: 21005 | AM31: 1000 | AO31: 30019,30020,300201 | AP31: 1,1,1 | AQ31: 30019,30020,300201 | AR31: 1,1,1 | AS31: 30019,30020,300201 | AT31: 1,1,1 | AU31: 2009:10000,-1 | AW31: 3:10;50:50 | AX31: 4,5,6,7,8 | BE31: 1003 | BF31: 10701 | BH31: 202:5;302:50 | BI31: 150,350 | BJ31: 550,100,100,100 | BK31: 100,100,100,200 | BO31: 100 | BP31: 200 | BQ31: 1,30000,4000 | BR31: 3 | BT31: 50 | BU31: 50 | BZ31: 1 | CA31: 1 | CB31: 1 | CC31: 1 | CD31: 1 | CE31: 1 | CF31: 1 | CG31: 1 | CM31: 110201 | CO31: 100064 | CP31: 110201
B32: 缝合巨尸 | D32: 10711 | E32: 70019 | G32: 302 | H32: 0 | K32: 3 | M32: 10812 | O32: 5 | P32: 1 | Q32: 3 | S32: 1 | T32: 1 | U32: 1 | Y32: 1092 | Z32: 1000 | AA32: 500 | AB32: 3 | AE32: 4 | AF32: 1 | AG32: 100 | AH32: 2000 | AJ32: 1408008,4,0 | AK32: 0 | AL32: 21005 | AM32: 1000 | AO32: 30039,30041,30042 | AP32: 1,1,1 | AQ32: 30039,30041,30042 | AR32: 1,1,1 | AS32: 30039,30041,30042 | AT32: 1,1,1,1 | AU32: 2009:10000,-1 | AW32: 3:10;50:50 | AX32: 4,5,6,7,8 | BE32: 1003 | BF32: 10711 | BH32: 202:5;302:50 | BI32: 300,500 | BJ32: 550,100,100,100 | BK32: 100,100,100,200 | BO32: 100 | BP32: 200 | BQ32: 1,30000,4000 | BR32: 3 | BT32: 50 | BU32: 50 | BZ32: 1 | CA32: 1 | CB32: 1 | CC32: 1 | CD32: 1 | CE32: 1 | CF32: 1 | CG32: 1 | CM32: 110202 | CP32: 110202
B33: 骷髅王 | D33: 10721 | E33: 70020 | G33: 302 | H33: 0 | K33: 3 | M33: 10813 | O33: 5 | P33: 2 | Q33: 3 | S33: 1 | T33: 1 | U33: 1 | Y33: 1093 | Z33: 1500 | AA33: 400 | AB33: 3 | AE33: 4 | AF33: 2 | AG33: 150 | AH33: 5300 | AK33: 0 | AL33: 8002 | AM33: 1100 | AO33: 31106,31101,31102,31103 | AP33: 1,1,1,1 | AQ33: 31106,31101,31102,31103 | AR33: 1,1,1,1 | AS33: 31106,31101,31102,31103 | AT33: 1,1,1,1 | AU33: 2009:10000,-1 | AW33: 3:10;50:50 | AX33: 4,5,6,7,8 | AY33: 2002006,2,0 | BE33: 1003 | BF33: 10721 | BH33: 202:5;302:50 | BI33: 150,400 | BJ33: 550,100,100,100 | BK33: 100,100,100,200 | BO33: 100 | BP33: 200 | BQ33: 1,30000,4000 | BR33: 3 | BT33: 50 | BU33: 50 | BZ33: 1 | CA33: 1 | CB33: 1 | CC33: 1 | CD33: 1 | CE33: 1 | CF33: 1 | CG33: 1 | CM33: 110203 | CP33: 110203
B34: 地狱炎魔王 | D34: 10731 | E34: 70021 | G34: 302 | K34: 3 | L34: 1 | M34: 10814 | O34: 5 | P34: 2 | Q34: 3 | S34: 1 | T34: 1 | U34: 1 | Y34: 1094 | Z34: 1800 | AA34: 400 | AB34: 3 | AE34: 4 | AF34: 1 | AG34: 100 | AK34: 0 | AL34: 21010 | AM34: 1000 | AO34: 31114 | AP34: 1 | AQ34: 31114 | AR34: 1 | AS34: 31114 | AT34: 1 | AU34: 2009:10000,-1;31110:10000,-1;31112:10000,-1;31115:10000,-1 | AW34: 3:10;50:50 | AX34: 4,5,6,7,8 | BE34: 1003 | BF34: 10731 | BH34: 202:5;302:50 | BI34: 300,600 | BJ34: 550,100,100,100 | BK34: 100,100,100,200 | BO34: 100 | BP34: 200 | BQ34: 1,30000,4000 | BR34: 3 | BT34: 50 | BU34: 40 | BZ34: 1 | CA34: 2 | CB34: 1 | CC34: 2 | CD34: 1 | CE34: 1 | CF34: 1 | CG34: 1 | CM34: 110204 | CP34: 110204
B35: 骷髅盾卫 | C35: 快速模式 | D35: 10790 | E35: 70002 | H35: 0 | K35: 1 | P35: 1 | Q35: 1 | S35: 1 | T35: 1 | U35: 1 | Y35: 1095 | Z35: 1300 | AA35: 200 | AB35: 2 | AF35: 1 | AG35: 100 | AK35: 0 | AL35: 21001 | AM35: 1000 | AO35: 30001,30002 | AP35: 1,1 | AQ35: 10011,10012 | AR35: 1,1 | AS35: 10011,10012 | AT35: 1,1 | AW35: 3:10;50:50 | AX35: 4,5,6,7,8 | BF35: 10011 | BH35: 202:5;302:30 | BI35: 200,350 | BJ35: 300,100,100,100 | BK35: 100,100,100,200 | BO35: 50 | BP35: 200 | BQ35: 1,30000,4000 | BR35: 1 | BT35: 50 | BU35: 50 | BZ35: 3 | CA35: 4 | CB35: 4 | CC35: 4 | CD35: 5 | CE35: 6 | CF35: 4 | CG35: 4 | CH35: 3 | CI35: 1:5 | CM35: 100005 | CN35: 100057 | CP35: 100005
B36: 骷髅将领 | C36: 快速模式 | D36: 10791 | E36: 70018 | G36: 302 | H36: 0 | K36: 3 | M36: 10811 | O36: 5 | P36: 1 | Q36: 1 | S36: 1 | T36: 1 | U36: 1 | Y36: 1005 | Z36: 1500 | AA36: 300 | AB36: 3 | AE36: 4 | AF36: 1 | AG36: 100 | AK36: 0 | AL36: 21005 | AM36: 1000 | AO36: 30019,30020,300201 | AP36: 1,1,1 | AQ36: 30019,30020,300201 | AR36: 1,1,1 | AS36: 30019,30020,300201 | AT36: 1,1,1 | AU36: 2009:10000,-1 | AW36: 3:10;50:50 | AX36: 4,5,6,7,8 | BE36: 1003 | BF36: 10701 | BH36: 202:5;302:50 | BI36: 150,350 | BJ36: 550,100,100,100 | BK36: 100,100,100,200 | BO36: 100 | BP36: 200 | BQ36: 1,30000,4000 | BR36: 3 | BT36: 50 | BU36: 50 | BZ36: 1 | CA36: 1 | CB36: 1 | CC36: 1 | CD36: 1 | CE36: 1 | CF36: 1 | CG36: 1 | CM36: 1200000 | CO36: 100064 | CP36: 1200000
B37: 缝合巨尸 | C37: 快速模式 | D37: 10792 | E37: 70019 | G37: 302 | H37: 0 | K37: 3 | M37: 10812 | O37: 5 | P37: 1 | Q37: 3 | S37: 1 | T37: 1 | U37: 1 | Y37: 1092 | Z37: 1000 | AA37: 500 | AB37: 3 | AE37: 4 | AF37: 1 | AG37: 100 | AH37: 2000 | AJ37: 1408008,4,0 | AK37: 0 | AL37: 21005 | AM37: 1000 | AO37: 30039,30041,30042 | AP37: 1,1,1 | AQ37: 30039,30041,30042 | AR37: 1,1,1 | AS37: 30039,30041,30042 | AT37: 1,1,1,1 | AU37: 2009:10000,-1 | AW37: 3:10;50:50 | AX37: 4,5,6,7,8 | BE37: 1003 | BF37: 10711 | BH37: 202:5;302:50 | BI37: 300,500 | BJ37: 550,100,100,100 | BK37: 100,100,100,200 | BO37: 100 | BP37: 200 | BQ37: 1,30000,4000 | BR37: 3 | BT37: 50 | BU37: 50 | BZ37: 1 | CA37: 1 | CB37: 1 | CC37: 1 | CD37: 1 | CE37: 1 | CF37: 1 | CG37: 1 | CM37: 1200001 | CP37: 1200001
B38: 骷髅王 | C38: 快速模式 | D38: 10793 | E38: 70020 | G38: 302 | H38: 0 | K38: 3 | M38: 10813 | O38: 5 | P38: 2 | Q38: 3 | S38: 1 | T38: 1 | U38: 1 | Y38: 1093 | Z38: 1500 | AA38: 400 | AB38: 3 | AE38: 4 | AF38: 2 | AG38: 150 | AH38: 5300 | AK38: 0 | AL38: 8002 | AM38: 1100 | AO38: 31106,31101,31102,31103 | AP38: 1,1,1,1 | AQ38: 31106,31101,31102,31103 | AR38: 1,1,1,1 | AS38: 31106,31101,31102,31103 | AT38: 1,1,1,1 | AU38: 2009:10000,-1 | AW38: 3:10;50:50 | AX38: 4,5,6,7,8 | AY38: 2002006,2,0 | BE38: 1003 | BF38: 10721 | BH38: 202:5;302:50 | BI38: 150,400 | BJ38: 550,100,100,100 | BK38: 100,100,100,200 | BO38: 100 | BP38: 200 | BQ38: 1,30000,4000 | BR38: 3 | BT38: 50 | BU38: 50 | BZ38: 1 | CA38: 1 | CB38: 1 | CC38: 1 | CD38: 1 | CE38: 1 | CF38: 1 | CG38: 1 | CM38: 1200002 | CP38: 1200002
B39: 地狱炎魔王 | C39: 快速模式 | D39: 10794 | E39: 70021 | G39: 302 | K39: 3 | L39: 1 | M39: 10814 | O39: 5 | P39: 2 | Q39: 3 | S39: 1 | T39: 1 | U39: 1 | Y39: 1094 | Z39: 1800 | AA39: 400 | AB39: 3 | AE39: 4 | AF39: 1 | AG39: 100 | AK39: 0 | AL39: 21010 | AM39: 1000 | AO39: 31114 | AP39: 1 | AQ39: 31114 | AR39: 1 | AS39: 31114 | AT39: 1 | AU39: 2009:10000,-1;31110:10000,-1;31112:10000,-1;31115:10000,-1 | AW39: 3:10;50:50 | AX39: 4,5,6,7,8 | BE39: 1003 | BF39: 10731 | BH39: 202:5;302:50 | BI39: 300,600 | BJ39: 550,100,100,100 | BK39: 100,100,100,200 | BO39: 100 | BP39: 200 | BQ39: 1,30000,4000 | BR39: 3 | BT39: 50 | BU39: 40 | BZ39: 1 | CA39: 2 | CB39: 1 | CC39: 2 | CD39: 1 | CE39: 1 | CF39: 1 | CG39: 1 | CM39: 1200003 | CP39: 1200003
B40: 骷髅将领 | C40: 无尽-终BOSS | D40: 10950 | E40: 70018 | G40: 302 | H40: 0 | K40: 3 | L40: 1 | M40: 10811 | O40: 5 | P40: 1 | Q40: 1 | S40: 1 | T40: 1 | U40: 1 | Y40: 1005 | Z40: 1500 | AA40: 300 | AB40: 3 | AE40: 4 | AF40: 1 | AG40: 100 | AK40: 0 | AL40: 21005 | AM40: 1000 | AO40: 30019,30020,300201 | AP40: 1,1,1 | AQ40: 30019,30020,300201 | AR40: 1,1,1 | AS40: 30019,30020,300201 | AT40: 1,1,1 | AU40: 2009:10000,-1 | AW40: 3:10;50:50 | AX40: 4,5,6,7,8 | BE40: 1003 | BF40: 10701 | BH40: 202:5;302:50 | BI40: 150,350 | BJ40: 550,100,100,100 | BK40: 100,100,100,200 | BO40: 100 | BP40: 200 | BQ40: 1,30000,4000 | BR40: 3 | BT40: 50 | BU40: 50 | BZ40: 1 | CA40: 1 | CB40: 1 | CC40: 1 | CD40: 1 | CE40: 1 | CF40: 1 | CG40: 1 | CM40: 1210000 | CP40: 1210000
...

Sheet 怪物属性表
A1: monster_value.xml
E3: 攻击力 201 | F3: 生命值 300 | G3: 生命回复速度 303 | H3: 护盾值 307 | I3: 护盾回复速度 309 | J3: 护甲值 305 | K3: 格挡率 313 | L3: 闪避% 311 | M3: 物理抗性% 320 | N3: 冰霜抗性% 316 | O3: 火焰抗性% 317 | P3: 闪电抗性% 318 | Q3: 混沌抗性% 319 | R3: 命中率% 226 | S3: 暴击几率% 219 | T3: 暴击伤害% 220 | U3: 护盾回复时间 | V3: 移动速度% 412 | W3: 流血系数 240 | X3: 灼烧系数 241 | Y3: 中毒系数 242 | Z3: 近战范围 430 | AA3: 区域范围 432 | AB3: 弹道范围 434
D4: id_i | E4: ATK_i | F4: HP_i | G4: HP_REG_i | H4: SHD_i | I4: SHD_REG_i | J4: ARM_i | K4: block_rate_i | L4: EVA_RATE_PER_i | M4: PHY_DR_PER_i | N4: FIRE_RES_PER_i | O4: FIR_RES_PER_i | P4: LTN_RES_PER_i | Q4: CHA_RES_PER_i | R4: ACC_PER_i | S4: CRIT_RATE_PER_i | T4: CRIT_DMG_PER_i | U4: SHLD_CD_i | V4: SPEED_PER_i | W4: BLEED_i | X4: BURN_i | Y4: POISON_i | Z4: ATK_RNG_PER_i | AA4: AOE_RNG_PER_i | AB4: BAT_RNG_PER_i
D5: 0 | E5: 0 | F5: 0 | G5: 0 | H5: 0 | I5: 0 | J5: 0 | K5: 0 | L5: 0 | M5: 0 | N5: 0 | O5: 0 | P5: 0 | Q5: 0 | R5: 0 | S5: 0 | T5: 0 | U5: 0 | V5: 0 | W5: 0 | X5: 0 | Y5: 0 | Z5: 0 | AA5: 0 | AB5: 0
D6: 1 | E6: 1 | F6: 10 | G6: 1 | H6: 0 | I6: 1 | J6: 100 | L6: 5 | M6: 0 | N6: 10 | O6: 0 | P6: 0 | Q6: 0 | R6: 100 | S6: 5 | T6: 150 | U6: 10 | V6: 0 | W6: 20 | X6: 30 | Y6: 20 | Z6: 0 | AA6: 0 | AB6: 0
D7: 2 | E7: 20 | F7: 300 | G7: 1 | H7: 10 | I7: 1 | J7: 100 | L7: 10 | M7: 10 | N7: 20 | O7: 20 | P7: 20 | Q7: 20 | R7: 100 | S7: 5 | T7: 150 | U7: 10 | V7: 0 | W7: 20 | X7: 30 | Y7: 20 | Z7: 0 | AA7: 0 | AB7: 0
D8: 3 | E8: 30 | F8: 500 | G8: 1 | H8: 10 | I8: 1 | J8: 100 | L8: 10 | M8: 10 | N8: 20 | O8: 20 | P8: 20 | Q8: 20 | R8: 100 | S8: 5 | T8: 150 | U8: 10 | V8: 0 | W8: 20 | X8: 30 | Y8: 20 | Z8: 0 | AA8: 0 | AB8: 0
D9: 4 | E9: 40 | F9: 1000 | G9: 1 | H9: 10 | I9: 1 | J9: 100 | L9: 10 | M9: 10 | N9: 20 | O9: 20 | P9: 20 | Q9: 20 | R9: 100 | S9: 5 | T9: 150 | U9: 10 | V9: 0 | W9: 20 | X9: 30 | Y9: 20 | Z9: 0 | AA9: 0 | AB9: 0
D10: 5 | E10: 50 | F10: 2000 | G10: 1 | H10: 10 | I10: 1 | J10: 100 | L10: 10 | M10: 10 | N10: 20 | O10: 20 | P10: 20 | Q10: 20 | R10: 100 | S10: 5 | T10: 150 | U10: 10 | V10: 0 | W10: 20 | X10: 30 | Y10: 20 | Z10: 0 | AA10: 0 | AB10: 0
B11: 梦魇怪物-梦魇眼球 | D11: 99994 | E11: 30 | F11: 1500 | G11: 0 | H11: 0 | I11: 0 | J11: 1000000 | L11: 0 | M11: 100 | N11: 100 | O11: 100 | P11: 100 | Q11: 100 | R11: 200 | S11: 25 | T11: 200 | U11: 10 | V11: 0 | W11: 20 | X11: 30 | Y11: 20 | Z11: 0 | AA11: 0 | AB11: 0
B12: 木桩怪 | D12: 99999 | E12: 1 | F12: 99999999 | G12: 1 | H12: 0 | I12: 0 | J12: 0 | L12: 0 | M12: 0 | N12: 0 | O12: 0 | P12: 0 | Q12: 0 | R12: 100 | S12: 5 | T12: 150 | U12: 10 | V12: 0 | W12: 20 | X12: 30 | Y12: 20 | Z12: 0 | AA12: 0 | AB12: 0
B13: 木桩怪 | D13: 99998 | E13: 1 | F13: 99999999 | G13: 1 | H13: 0 | I13: 0 | J13: 0 | L13: 50 | M13: 0 | N13: 0 | O13: 0 | P13: 0 | Q13: 0 | R13: 100 | S13: 5 | T13: 150 | U13: 10 | V13: 0 | W13: 20 | X13: 30 | Y13: 20 | Z13: 0 | AA13: 0 | AB13: 0
B14: 小怪近战 | D14: 101 | E14: 5 | F14: 10 | G14: 0 | H14: 0 | I14: 0 | J14: 200 | L14: 0 | M14: 0 | N14: 0 | O14: 0 | P14: 0 | Q14: 0 | R14: 100 | S14: 5 | T14: 200 | U14: 10 | V14: 0 | W14: 20 | X14: 30 | Y14: 20 | Z14: 0 | AA14: 0 | AB14: 0
B15: 小怪远程 | D15: 201 | E15: 10 | F15: 5 | G15: 0 | H15: 0 | I15: 0 | J15: 0 | L15: 10 | M15: 0 | N15: 0 | O15: 0 | P15: 0 | Q15: 0 | R15: 110 | S15: 10 | T15: 150 | U15: 10 | V15: 0 | W15: 20 | X15: 30 | Y15: 20 | Z15: 0 | AA15: 0 | AB15: 0
B16: 精英怪 | D16: 301 | E16: 20 | F16: 300 | G16: 1 | H16: 0 | I16: 0 | J16: 200 | L16: 20 | M16: 20 | N16: 20 | O16: 20 | P16: 20 | Q16: 20 | R16: 120 | S16: 25 | T16: 200 | U16: 10 | V16: 0 | W16: 20 | X16: 30 | Y16: 20 | Z16: 0 | AA16: 0 | AB16: 0
B17: Boss | D17: 401 | E17: 20 | F17: 1000 | G17: 1 | H17: 0 | I17: 0 | J17: 200 | L17: 20 | M17: 50 | N17: 50 | O17: 50 | P17: 50 | Q17: 50 | R17: 150 | S17: 25 | T17: 200 | U17: 10 | V17: 0 | W17: 20 | X17: 30 | Y17: 20 | Z17: 0 | AA17: 0 | AB17: 0
B18: 盗宝地精 | D18: 1001 | E18: 1 | F18: 3000 | G18: 1 | H18: 0 | I18: 0 | J18: 200 | L18: 20 | M18: 0 | N18: 0 | O18: 0 | P18: 0 | Q18: 0 | R18: 100 | S18: 0 | T18: 100 | U18: 10 | V18: 0 | W18: 20 | X18: 30 | Y18: 20 | Z18: 0 | AA18: 0 | AB18: 0
A19: ACT1怪物属性 | B19: 普通骷髅 | D19: 10001 | E19: 10 | F19: 50 | G19: 0 | H19: 0 | I19: 0 | J19: 0 | M19: 10 | N19: 10 | O19: 10 | P19: 10 | Q19: 10 | R19: 100 | S19: 0 | T19: 200 | U19: 10 | V19: 0 | W19: 20 | X19: 30 | Y19: 20 | Z19: 0 | AA19: 0 | AB19: 0
B20: 盾牌骷髅 | D20: 10011 | E20: 10 | F20: 200 | G20: 0 | H20: 100 | I20: 0 | J20: 0 | M20: 10 | N20: 10 | O20: 10 | P20: 10 | Q20: 10 | R20: 100 | S20: 0 | T20: 200 | U20: 10 | V20: 0 | W20: 20 | X20: 30 | Y20: 20 | Z20: 0 | AA20: 0 | AB20: 0
B21: 骷髅战士 | D21: 10021 | E21: 15 | F21: 300 | G21: 0 | H21: 0 | I21: 0 | J21: 0 | M21: 10 | N21: 10 | O21: 10 | P21: 10 | Q21: 10 | R21: 100 | S21: 5 | T21: 200 | U21: 10 | V21: 0 | W21: 20 | X21: 30 | Y21: 20 | Z21: 0 | AA21: 0 | AB21: 0
B22: 骷髅弓手 | D22: 10031 | E22: 20 | F22: 150 | G22: 0 | H22: 0 | I22: 0 | J22: 0 | M22: 10 | N22: 10 | O22: 10 | P22: 10 | Q22: 10 | R22: 100 | S22: 10 | T22: 200 | U22: 10 | V22: 0 | W22: 20 | X22: 30 | Y22: 20 | Z22: 0 | AA22: 0 | AB22: 0
B23: 骷髅法师 | D23: 10041 | E23: 15 | F23: 200 | G23: 0 | H23: 0 | I23: 0 | J23: 0 | M23: 10 | N23: 10 | O23: 10 | P23: 10 | Q23: 10 | R23: 100 | S23: 5 | T23: 200 | U23: 10 | V23: 0 | W23: 20 | X23: 30 | Y23: 20 | Z23: 0 | AA23: 0 | AB23: 0
B24: 骷髅刺客 | D24: 10051 | E24: 15 | F24: 75 | G24: 0 | H24: 0 | I24: 0 | J24: 0 | L24: 25 | M24: 10 | N24: 10 | O24: 10 | P24: 10 | Q24: 10 | R24: 100 | S24: 10 | T24: 200 | U24: 10 | V24: 0 | W24: 20 | X24: 30 | Y24: 20 | Z24: 0 | AA24: 0 | AB24: 0
B25: 中级骷髅战士 | D25: 10061 | E25: 15 | F25: 600 | G25: 0 | H25: 0 | I25: 0 | J25: 0 | L25: 10 | M25: 10 | N25: 10 | O25: 10 | P25: 10 | Q25: 10 | R25: 100 | S25: 5 | T25: 200 | U25: 10 | V25: 0 | W25: 20 | X25: 30 | Y25: 20 | Z25: 0 | AA25: 0 | AB25: 0
B26: 骷髅长刀 | D26: 10071 | E26: 20 | F26: 300 | G26: 0 | H26: 0 | I26: 0 | J26: 0 | L26: 10 | M26: 10 | N26: 10 | O26: 10 | P26: 10 | Q26: 10 | R26: 100 | S26: 10 | T26: 200 | U26: 10 | V26: 0 | W26: 20 | X26: 30 | Y26: 20 | Z26: 0 | AA26: 0 | AB26: 0
B27: 行尸 | D27: 10501 | E27: 10 | F27: 100 | G27: 0 | H27: 0 | I27: 0 | J27: 0 | M27: 10 | N27: 10 | O27: 10 | P27: 10 | Q27: 10 | R27: 100 | S27: 0 | T27: 200 | U27: 10 | V27: 0 | W27: 20 | X27: 30 | Y27: 20 | Z27: 0 | AA27: 0 | AB27: 0
B28: 高级行尸 | D28: 10511 | E28: 10 | F28: 1000 | G28: 0 | H28: 0 | I28: 0 | J28: 0 | M28: 10 | N28: 10 | O28: 10 | P28: 10 | Q28: 10 | R28: 100 | S28: 0 | T28: 200 | U28: 10 | V28: 0 | W28: 20 | X28: 30 | Y28: 20 | Z28: 0 | AA28: 0 | AB28: 0
B29: 食腐犬 | D29: 10521 | E29: 20 | F29: 200 | G29: 0 | H29: 0 | I29: 0 | J29: 0 | L29: 25 | M29: 10 | N29: 10 | O29: 10 | P29: 10 | Q29: 10 | R29: 100 | S29: 10 | T29: 200 | U29: 10 | V29: 0 | W29: 20 | X29: 30 | Y29: 20 | Z29: 0 | AA29: 0 | AB29: 0
B30: 自爆僵尸 | D30: 10531 | E30: 10 | F30: 500 | G30: 0 | H30: 0 | I30: 0 | J30: 0 | M30: 10 | N30: 10 | O30: 10 | P30: 10 | Q30: 10 | R30: 100 | S30: 0 | T30: 200 | U30: 10 | V30: 0 | W30: 20 | X30: 30 | Y30: 20 | Z30: 0 | AA30: 0 | AB30: 0
B31: 火焰恶魔 | D31: 10541 | E31: 15 | F31: 500 | G31: 0 | H31: 0 | I31: 0 | J31: 0 | M31: 10 | N31: 10 | O31: 10 | P31: 10 | Q31: 10 | R31: 100 | S31: 0 | T31: 200 | U31: 10 | V31: 0 | W31: 20 | X31: 30 | Y31: 20 | Z31: 0 | AA31: 0 | AB31: 0
B32: 冲锋怪物 | D32: 10551 | E32: 20 | F32: 100 | G32: 0 | H32: 0 | I32: 0 | J32: 0 | M32: 10 | N32: 10 | O32: 10 | P32: 10 | Q32: 10 | R32: 100 | S32: 0 | T32: 200 | U32: 10 | V32: 0 | W32: 20 | X32: 30 | Y32: 20 | Z32: 0 | AA32: 0 | AB32: 0
B33: 骷髅精英战士 | D33: 10601 | E33: 20 | F33: 1500 | G33: 0 | H33: 500 | I33: 0 | J33: 0 | L33: 10 | M33: 10 | N33: 10 | O33: 10 | P33: 10 | Q33: 10 | R33: 100 | S33: 5 | T33: 200 | U33: 10 | V33: 0 | W33: 20 | X33: 30 | Y33: 20 | Z33: 0 | AA33: 0 | AB33: 0
B34: 精英骷髅法师 | D34: 10611 | E34: 20 | F34: 2200 | G34: 0 | H34: 800 | I34: 0 | J34: 0 | L34: 10 | M34: 10 | N34: 10 | O34: 10 | P34: 10 | Q34: 10 | R34: 100 | S34: 5 | T34: 200 | U34: 10 | V34: 0 | W34: 20 | X34: 30 | Y34: 20 | Z34: 0 | AA34: 0 | AB34: 0
B35: 魔弓 | D35: 10621 | E35: 20 | F35: 3000 | G35: 0 | H35: 1000 | I35: 0 | J35: 0 | L35: 20 | M35: 10 | N35: 10 | O35: 10 | P35: 10 | Q35: 10 | R35: 100 | S35: 5 | T35: 200 | U35: 10 | V35: 0 | W35: 20 | X35: 30 | Y35: 20 | Z35: 0 | AA35: 0 | AB35: 0
B36: 骷髅将领 | D36: 10701 | E36: 20 | F36: 5000 | G36: 0 | H36: 1000 | I36: 0 | J36: 0 | L36: 10 | M36: 10 | N36: 10 | O36: 10 | P36: 10 | Q36: 10 | R36: 100 | S36: 5 | T36: 200 | U36: 10 | V36: 0 | W36: 20 | X36: 30 | Y36: 20 | Z36: 0 | AA36: 0 | AB36: 0
B37: 缝合巨尸 | D37: 10711 | E37: 20 | F37: 5500 | G37: 0 | H37: 1500 | I37: 0 | J37: 0 | L37: 10 | M37: 10 | N37: 10 | O37: 10 | P37: 10 | Q37: 10 | R37: 100 | S37: 5 | T37: 200 | U37: 10 | V37: 0 | W37: 20 | X37: 30 | Y37: 20 | Z37: 0 | AA37: 0 | AB37: 0
B38: 骷髅王 | D38: 10721 | E38: 20 | F38: 6000 | G38: 0 | H38: 2000 | I38: 0 | J38: 0 | L38: 20 | M38: 10 | N38: 10 | O38: 10 | P38: 10 | Q38: 10 | R38: 100 | S38: 10 | T38: 200 | U38: 10 | V38: 0 | W38: 20 | X38: 30 | Y38: 20 | Z38: 0 | AA38: 0 | AB38: 0
B39: 地狱炎魔王 | D39: 10731 | E39: 20 | F39: 7000 | G39: 0 | H39: 3000 | I39: 0 | J39: 0 | L39: 20 | M39: 10 | N39: 10 | O39: 10 | P39: 10 | Q39: 10 | R39: 100 | S39: 10 | T39: 200 | U39: 10 | V39: 0 | W39: 20 | X39: 30 | Y39: 20 | Z39: 0 | AA39: 0 | AB39: 0
A40: ACT2怪物属性 | B40: 原住民 | D40: 11001 | E40: 10 | F40: 60 | G40: 0 | H40: 0 | I40: 0 | J40: 0 | M40: 10 | N40: 10 | O40: 10 | P40: 15 | Q40: 10 | R40: 100 | T40: 200 | U40: 10 | V40: 0 | W40: 20 | X40: 30 | Y40: 20 | Z40: 0 | AA40: 0 | AB40: 0
B41: 原住民胖子 | D41: 11011 | E41: 10 | F41: 500 | G41: 0 | H41: 0 | I41: 0 | J41: 0 | M41: 10 | N41: 10 | O41: 10 | P41: 20 | Q41: 10 | R41: 100 | T41: 200 | U41: 10 | V41: 0 | W41: 20 | X41: 30 | Y41: 20 | Z41: 0 | AA41: 0 | AB41: 0
...

Sheet Sheet3
A1: 1: | B1: 300010 | C1: ;2: | D1: 300011 | E1: ;3: | F1: 300012 | G1: ;4: | H1: 300013 | I1: ;5: | J1: 300014 | K1: ;6: | L1: 300015 | M1: ;7: | N1: 300016 | O1: ;8: | P1: 300017 | Q1: ;9: | R1: 300018 | S1: ;10: | T1: 300019 | U1: =A1&B1&C1&D1&E1&F1&G1&H1&I1&J1&K1&L1&M1&N1&O1&P1&Q1&R1&S1&T1 -> 1:300010;2:300011;3:300012;4:300013;5:300014;6:300015;7:300016;8:300017;9:300018;10:300019
A2: 1: | B2: 300020 | C2: ;2: | D2: 300021 | E2: ;3: | F2: 300022 | G2: ;4: | H2: 300023 | I2: ;5: | J2: 300024 | K2: ;6: | L2: 300025 | M2: ;7: | N2: 300026 | O2: ;8: | P2: 300027 | Q2: ;9: | R2: 300028 | S2: ;10: | T2: 300029 | U2: =A2&B2&C2&D2&E2&F2&G2&H2&I2&J2&K2&L2&M2&N2&O2&P2&Q2&R2&S2&T2 -> 1:300020;2:300021;3:300022;4:300023;5:300024;6:300025;7:300026;8:300027;9:300028;10:300029
A3: 1: | B3: 300030 | C3: ;2: | D3: 300031 | E3: ;3: | F3: 300032 | G3: ;4: | H3: 300033 | I3: ;5: | J3: 300034 | K3: ;6: | L3: 300035 | M3: ;7: | N3: 300036 | O3: ;8: | P3: 300037 | Q3: ;9: | R3: 300038 | S3: ;10: | T3: 300039 | U3: =A3&B3&C3&D3&E3&F3&G3&H3&I3&J3&K3&L3&M3&N3&O3&P3&Q3&R3&S3&T3 -> 1:300030;2:300031;3:300032;4:300033;5:300034;6:300035;7:300036;8:300037;9:300038;10:300039
A4: 1: | B4: 300040 | C4: ;2: | D4: 300041 | E4: ;3: | F4: 300042 | G4: ;4: | H4: 300043 | I4: ;5: | J4: 300044 | K4: ;6: | L4: 300045 | M4: ;7: | N4: 300046 | O4: ;8: | P4: 300047 | Q4: ;9: | R4: 300048 | S4: ;10: | T4: 300049 | U4: =A4&B4&C4&D4&E4&F4&G4&H4&I4&J4&K4&L4&M4&N4&O4&P4&Q4&R4&S4&T4 -> 1:300040;2:300041;3:300042;4:300043;5:300044;6:300045;7:300046;8:300047;9:300048;10:300049
A5: 1: | B5: 300050 | C5: ;2: | D5: 300051 | E5: ;3: | F5: 300052 | G5: ;4: | H5: 300053 | I5: ;5: | J5: 300054 | K5: ;6: | L5: 300055 | M5: ;7: | N5: 300056 | O5: ;8: | P5: 300057 | Q5: ;9: | R5: 300058 | S5: ;10: | T5: 300059 | U5: =A5&B5&C5&D5&E5&F5&G5&H5&I5&J5&K5&L5&M5&N5&O5&P5&Q5&R5&S5&T5 -> 1:300050;2:300051;3:300052;4:300053;5:300054;6:300055;7:300056;8:300057;9:300058;10:300059
A6: 1: | B6: 300060 | C6: ;2: | D6: 300061 | E6: ;3: | F6: 300062 | G6: ;4: | H6: 300063 | I6: ;5: | J6: 300064 | K6: ;6: | L6: 300065 | M6: ;7: | N6: 300066 | O6: ;8: | P6: 300067 | Q6: ;9: | R6: 300068 | S6: ;10: | T6: 300069 | U6: =A6&B6&C6&D6&E6&F6&G6&H6&I6&J6&K6&L6&M6&N6&O6&P6&Q6&R6&S6&T6 -> 1:300060;2:300061;3:300062;4:300063;5:300064;6:300065;7:300066;8:300067;9:300068;10:300069
A7: 1: | B7: 300070 | C7: ;2: | D7: 300071 | E7: ;3: | F7: 300072 | G7: ;4: | H7: 300073 | I7: ;5: | J7: 300074 | K7: ;6: | L7: 300075 | M7: ;7: | N7: 300076 | O7: ;8: | P7: 300077 | Q7: ;9: | R7: 300078 | S7: ;10: | T7: 300079 | U7: =A7&B7&C7&D7&E7&F7&G7&H7&I7&J7&K7&L7&M7&N7&O7&P7&Q7&R7&S7&T7 -> 1:300070;2:300071;3:300072;4:300073;5:300074;6:300075;7:300076;8:300077;9:300078;10:300079
A8: 1: | B8: 300080 | C8: ;2: | D8: 300081 | E8: ;3: | F8: 300082 | G8: ;4: | H8: 300083 | I8: ;5: | J8: 300084 | K8: ;6: | L8: 300085 | M8: ;7: | N8: 300086 | O8: ;8: | P8: 300087 | Q8: ;9: | R8: 300088 | S8: ;10: | T8: 300089 | U8: =A8&B8&C8&D8&E8&F8&G8&H8&I8&J8&K8&L8&M8&N8&O8&P8&Q8&R8&S8&T8 -> 1:300080;2:300081;3:300082;4:300083;5:300084;6:300085;7:300086;8:300087;9:300088;10:300089
A9: 1: | B9: 300090 | C9: ;2: | D9: 300091 | E9: ;3: | F9: 300092 | G9: ;4: | H9: 300093 | I9: ;5: | J9: 300094 | K9: ;6: | L9: 300095 | M9: ;7: | N9: 300096 | O9: ;8: | P9: 300097 | Q9: ;9: | R9: 300098 | S9: ;10: | T9: 300099 | U9: =A9&B9&C9&D9&E9&F9&G9&H9&I9&J9&K9&L9&M9&N9&O9&P9&Q9&R9&S9&T9 -> 1:300090;2:300091;3:300092;4:300093;5:300094;6:300095;7:300096;8:300097;9:300098;10:300099
A10: 1: | B10: 300100 | C10: ;2: | D10: 300101 | E10: ;3: | F10: 300102 | G10: ;4: | H10: 300103 | I10: ;5: | J10: 300104 | K10: ;6: | L10: 300105 | M10: ;7: | N10: 300106 | O10: ;8: | P10: 300107 | Q10: ;9: | R10: 300108 | S10: ;10: | T10: 300109 | U10: =A10&B10&C10&D10&E10&F10&G10&H10&I10&J10&K10&L10&M10&N10&O10&P10&Q10&R10&S10&T10 -> 1:300100;2:300101;3:300102;4:300103;5:300104;6:300105;7:300106;8:300107;9:300108;10:300109
A11: 1: | B11: 300110 | C11: ;2: | D11: 300111 | E11: ;3: | F11: 300112 | G11: ;4: | H11: 300113 | I11: ;5: | J11: 300114 | K11: ;6: | L11: 300115 | M11: ;7: | N11: 300116 | O11: ;8: | P11: 300117 | Q11: ;9: | R11: 300118 | S11: ;10: | T11: 300119 | U11: =A11&B11&C11&D11&E11&F11&G11&H11&I11&J11&K11&L11&M11&N11&O11&P11&Q11&R11&S11&T11 -> 1:300110;2:300111;3:300112;4:300113;5:300114;6:300115;7:300116;8:300117;9:300118;10:300119
A12: 1: | B12: 300120 | C12: ;2: | D12: 300121 | E12: ;3: | F12: 300122 | G12: ;4: | H12: 300123 | I12: ;5: | J12: 300124 | K12: ;6: | L12: 300125 | M12: ;7: | N12: 300126 | O12: ;8: | P12: 300127 | Q12: ;9: | R12: 300128 | S12: ;10: | T12: 300129 | U12: =A12&B12&C12&D12&E12&F12&G12&H12&I12&J12&K12&L12&M12&N12&O12&P12&Q12&R12&S12&T12 -> 1:300120;2:300121;3:300122;4:300123;5:300124;6:300125;7:300126;8:300127;9:300128;10:300129
... A41: 1: | B41: 300410 | C41: ;2: | D41: 300411 | E41: ;3: | F41: 300412 | G41: ;4: | H41: 300413 | I41: ;5: | J41: 300414 | K41: ;6: | L41: 300415 | M41: ;7: | N41: 300416 | O41: ;8: | P41: 300417 | Q41: ;9: | R41: 300418 | S41: ;10: | T41: 300419 | U41: =A41&B41&C41&D41&E41&F41&G41&H41&I41&J41&K41&L41&M41&N41&O41&P41&Q41&R41&S41&T41 -> 1:300410;2:300411;3:300412;4:300413;5:300414;6:300415;7:300416;8:300417;9:300418;10:300419
A46: 45 | B46: 1.6 | C46: =A46*B46 -> 72
A47: 54 | B47: 1.6 | C47: =A47*B47 -> 86.4
A48: 60 | B48: 1.6 | C48: =A48*B48 -> 96
A49: 75 | B49: 1.6 | C49: =A49*B49 -> 120
A50: 90 | B50: 1.6 | C50: =A50*B50 -> 144
A51: 99 | B51: 1.6 | C51: =A51*B51 -> 158.4
A52: 105 | B52: 1.6 | C52: =A52*B52 -> 168
A53: 120 | B53: 1.6 | C53: =A53*B53 -> 192
A54: 135 | B54: 1.6 | C54: =A54*B54 -> 216
A55: 150 | B55: 1.6 | C55: =A55*B55 -> 240

Sheet 怪物词缀投放
P1: 1:
A2: 地图 | B2: 怪物名 | C2: 怪物类型 | D2: 怪物ID | E2: 怪物技能 | F2: 怪物技能 | G2: 伤害类型 | H2: 固定词缀 | I2: 随机词缀1 | J2: 随机词缀2 | K2: 随机词缀3 | L2: 固定词缀配置 | M2: 随机词缀配置 | N2: 随机词缀配置 | O2: 随机词缀配置 | P2: 随机词缀输出
A3: ACT1新 | B3: 火焰恶魔 | C3: 小怪 | D3: 10541 | E3: =VLOOKUP(D3,怪物基本表!$D$7:$AO$276,38,FALSE) -> 30001,30002 | F3: =SUBSTITUTE(IFERROR(VLOOKUP(INT(LEFT($E3,5)),$S$3:$T$177,2,FALSE),"xxx")&","&IFERROR(VLOOKUP(INT(MID($E3,7,5)),$S$3:$T$177,2,FALSE),"xxx")&IFERROR(VLOOKUP(INT(MID($E3,13,5)),$S$3:$T$177,2,FALSE),"xxx")&IFERROR(VLOOKUP(INT(MID($E3,19,5)),$S$3:$T$177,2,FALSE),"xxx"),"x","") -> , | G3: 物理 | L3: =_xlfn.IFNA(VLOOKUP(H3,$V$3:$W$38,2,FALSE),"xxx") -> xxx | M3: =_xlfn.IFNA(VLOOKUP(I3,$V$3:$W$38,2,FALSE),"xxx") -> xxx | N3: =_xlfn.IFNA(VLOOKUP(J3,$V$3:$W$38,2,FALSE),"xxx") -> xxx | O3: =_xlfn.IFNA(VLOOKUP(K3,$V$3:$W$38,2,FALSE),"xxx") -> xxx | P3: =$P$1&M3&","&N3&","&O3 -> 1:xxx,xxx,xxx | S3: 10001 | T3: 火球术 | V3: 词缀名称 | W3: 词缀ID
B4: 骷髅精英战士 | C4: 特殊精英 | D4: 10601 | E4: =VLOOKUP(D4,怪物基本表!$D$7:$AO$276,38,FALSE) -> 30151,30010 | F4: =SUBSTITUTE(IFERROR(VLOOKUP(INT(LEFT($E4,5)),$S$3:$T$177,2,FALSE),"xxx")&","&IFERROR(VLOOKUP(INT(MID($E4,7,5)),$S$3:$T$177,2,FALSE),"xxx")&IFERROR(VLOOKUP(INT(MID($E4,13,5)),$S$3:$T$177,2,FALSE),"xxx")&IFERROR(VLOOKUP(INT(MID($E4,19,5)),$S$3:$T$177,2,FALSE),"xxx"),"x","") -> , | G4: 物理 | I4: 狂暴 | J4: 皮肤硬化 | L4: =_xlfn.IFNA(VLOOKUP(H4,$V$3:$W$38,2,FALSE),"xxx") -> xxx | M4: =_xlfn.IFNA(VLOOKUP(I4,$V$3:$W$38,2,FALSE),"xxx") -> 13 | N4: =_xlfn.IFNA(VLOOKUP(J4,$V$3:$W$38,2,FALSE),"xxx") -> 3 | O4: =_xlfn.IFNA(VLOOKUP(K4,$V$3:$W$38,2,FALSE),"xxx") -> xxx | P4: =$P$1&M4&","&N4&","&O4 -> 1:13,3,xxx | S4: 10002 | T4: 炼狱之火 | V4: 特别强壮 | W4: 1
B5: 精英骷髅法师 | C5: 特殊精英 | D5: 10611 | E5: =VLOOKUP(D5,怪物基本表!$D$7:$AO$276,38,FALSE) -> 30070,30071 | F5: =SUBSTITUTE(IFERROR(VLOOKUP(INT(LEFT($E5,5)),$S$3:$T$177,2,FALSE),"xxx")&","&IFERROR(VLOOKUP(INT(MID($E5,7,5)),$S$3:$T$177,2,FALSE),"xxx")&IFERROR(VLOOKUP(INT(MID($E5,13,5)),$S$3:$T$177,2,FALSE),"xxx")&IFERROR(VLOOKUP(INT(MID($E5,19,5)),$S$3:$T$177,2,FALSE),"xxx"),"x","") -> , | G5: 火球 | H5: 【光环】抗性 | I5: 火焰强化 | J5: 火焰护甲 | L5: =_xlfn.IFNA(VLOOKUP(H5,$V$3:$W$38,2,FALSE),"xxx") -> 35 | M5: =_xlfn.IFNA(VLOOKUP(I5,$V$3:$W$38,2,FALSE),"xxx") -> 18 | N5: =_xlfn.IFNA(VLOOKUP(J5,$V$3:$W$38,2,FALSE),"xxx") -> 22 | O5: =_xlfn.IFNA(VLOOKUP(K5,$V$3:$W$38,2,FALSE),"xxx") -> xxx | P5: =$P$1&M5&","&N5&","&O5 -> 1:18,22,xxx | S5: 10003 | T5: 寒冰球 | V5: 特别快速 | W5: 2
B6: 魔弓 | C6: 特殊精英 | D6: 10621 | E6: =VLOOKUP(D6,怪物基本表!$D$7:$AO$276,38,FALSE) -> 30082,30081 | F6: =SUBSTITUTE(IFERROR(VLOOKUP(INT(LEFT($E6,5)),$S$3:$T$177,2,FALSE),"xxx")&","&IFERROR(VLOOKUP(INT(MID($E6,7,5)),$S$3:$T$177,2,FALSE),"xxx")&IFERROR(VLOOKUP(INT(MID($E6,13,5)),$S$3:$T$177,2,FALSE),"xxx")&IFERROR(VLOOKUP(INT(MID($E6,19,5)),$S$3:$T$177,2,FALSE),"xxx"),"x","") -> , | G6: 冰弓 | H6: 【光环】精准 | I6: 冰冻强化 | J6: 冰霜护甲 | K6: 多重射击 | L6: =_xlfn.IFNA(VLOOKUP(H6,$V$3:$W$38,2,FALSE),"xxx") -> 32 | M6: =_xlfn.IFNA(VLOOKUP(I6,$V$3:$W$38,2,FALSE),"xxx") -> 17 | N6: =_xlfn.IFNA(VLOOKUP(J6,$V$3:$W$38,2,FALSE),"xxx") -> 23 | O6: =_xlfn.IFNA(VLOOKUP(K6,$V$3:$W$38,2,FALSE),"xxx") -> 6 | P6: =$P$1&M6&","&N6&","&O6 -> 1:17,23,6 | S6: 10004 | T6: 电能弹 | V6: 皮肤硬化 | W6: 3
B7: 骷髅将领 | C7: boss | D7: 10701 | E7: =VLOOKUP(D7,怪物基本表!$D$7:$AO$276,38,FALSE) -> 30019,30020,300201 | F7: =SUBSTITUTE(IFERROR(VLOOKUP(INT(LEFT($E7,5)),$S$3:$T$177,2,FALSE),"xxx")&","&IFERROR(VLOOKUP(INT(MID($E7,7,5)),$S$3:$T$177,2,FALSE),"xxx")&IFERROR(VLOOKUP(INT(MID($E7,13,5)),$S$3:$T$177,2,FALSE),"xxx")&IFERROR(VLOOKUP(INT(MID($E7,19,5)),$S$3:$T$177,2,FALSE),"xxx"),"x","") -> , | L7: =_xlfn.IFNA(VLOOKUP(H7,$V$3:$W$38,2,FALSE),"xxx") -> xxx | M7: =_xlfn.IFNA(VLOOKUP(I7,$V$3:$W$38,2,FALSE),"xxx") -> xxx | N7: =_xlfn.IFNA(VLOOKUP(J7,$V$3:$W$38,2,FALSE),"xxx") -> xxx | O7: =_xlfn.IFNA(VLOOKUP(K7,$V$3:$W$38,2,FALSE),"xxx") -> xxx | P7: =$P$1&M7&","&N7&","&O7 -> 1:xxx,xxx,xxx | S7: 10005 | T7: 连锁闪电 | V7: 精准 | W7: 4
B8: 缝合巨尸 | C8: boss | D8: 10711 | E8: =VLOOKUP(D8,怪物基本表!$D$7:$AO$276,38,FALSE) -> 30039,30041,30042 | F8: =SUBSTITUTE(IFERROR(VLOOKUP(INT(LEFT($E8,5)),$S$3:$T$177,2,FALSE),"xxx")&","&IFERROR(VLOOKUP(INT(MID($E8,7,5)),$S$3:$T$177,2,FALSE),"xxx")&IFERROR(VLOOKUP(INT(MID($E8,13,5)),$S$3:$T$177,2,FALSE),"xxx")&IFERROR(VLOOKUP(INT(MID($E8,19,5)),$S$3:$T$177,2,FALSE),"xxx"),"x","") -> , | L8: =_xlfn.IFNA(VLOOKUP(H8,$V$3:$W$38,2,FALSE),"xxx") -> xxx | M8: =_xlfn.IFNA(VLOOKUP(I8,$V$3:$W$38,2,FALSE),"xxx") -> xxx | N8: =_xlfn.IFNA(VLOOKUP(J8,$V$3:$W$38,2,FALSE),"xxx") -> xxx | O8: =_xlfn.IFNA(VLOOKUP(K8,$V$3:$W$38,2,FALSE),"xxx") -> xxx | P8: =$P$1&M8&","&N8&","&O8 -> 1:xxx,xxx,xxx | S8: 10006 | T8: 枯萎 | V8: 生命再生 | W8: 5
B9: 骷髅王 | C9: boss | D9: 10721 | E9: =VLOOKUP(D9,怪物基本表!$D$7:$AO$276,38,FALSE) -> 31106,31101,31102,31103 | F9: =SUBSTITUTE(IFERROR(VLOOKUP(INT(LEFT($E9,5)),$S$3:$T$177,2,FALSE),"xxx")&","&IFERROR(VLOOKUP(INT(MID($E9,7,5)),$S$3:$T$177,2,FALSE),"xxx")&IFERROR(VLOOKUP(INT(MID($E9,13,5)),$S$3:$T$177,2,FALSE),"xxx")&IFERROR(VLOOKUP(INT(MID($E9,19,5)),$S$3:$T$177,2,FALSE),"xxx"),"x","") -> , | L9: =_xlfn.IFNA(VLOOKUP(H9,$V$3:$W$38,2,FALSE),"xxx") -> xxx | M9: =_xlfn.IFNA(VLOOKUP(I9,$V$3:$W$38,2,FALSE),"xxx") -> xxx | N9: =_xlfn.IFNA(VLOOKUP(J9,$V$3:$W$38,2,FALSE),"xxx") -> xxx | O9: =_xlfn.IFNA(VLOOKUP(K9,$V$3:$W$38,2,FALSE),"xxx") -> xxx | P9: =$P$1&M9&","&N9&","&O9 -> 1:xxx,xxx,xxx | S9: 10007 | T9: 骸骨之魂 | V9: 多重射击 | W9: 6
B10: 地狱炎魔王 | C10: boss | D10: 10731 | E10: =VLOOKUP(D10,怪物基本表!$D$7:$AO$276,38,FALSE) -> 31114 | F10: =SUBSTITUTE(IFERROR(VLOOKUP(INT(LEFT($E10,5)),$S$3:$T$177,2,FALSE),"xxx")&","&IFERROR(VLOOKUP(INT(MID($E10,7,5)),$S$3:$T$177,2,FALSE),"xxx")&IFERROR(VLOOKUP(INT(MID($E10,13,5)),$S$3:$T$177,2,FALSE),"xxx")&IFERROR(VLOOKUP(INT(MID($E10,19,5)),$S$3:$T$177,2,FALSE),"xxx"),"x","") -> , | L10: =_xlfn.IFNA(VLOOKUP(H10,$V$3:$W$38,2,FALSE),"xxx") -> xxx | M10: =_xlfn.IFNA(VLOOKUP(I10,$V$3:$W$38,2,FALSE),"xxx") -> xxx | N10: =_xlfn.IFNA(VLOOKUP(J10,$V$3:$W$38,2,FALSE),"xxx") -> xxx | O10: =_xlfn.IFNA(VLOOKUP(K10,$V$3:$W$38,2,FALSE),"xxx") -> xxx | P10: =$P$1&M10&","&N10&","&O10 -> 1:xxx,xxx,xxx | S10: 100071 | T10: 骸骨之魂——自爆 | V10: 护盾 | W10: 7
B11: 任务-怨灵 | D11: 10991 | E11: =VLOOKUP(D11,怪物基本表!$D$7:$AO$276,38,FALSE) -> 30070,30071 | F11: =SUBSTITUTE(IFERROR(VLOOKUP(INT(LEFT($E11,5)),$S$3:$T$177,2,FALSE),"xxx")&","&IFERROR(VLOOKUP(INT(MID($E11,7,5)),$S$3:$T$177,2,FALSE),"xxx")&IFERROR(VLOOKUP(INT(MID($E11,13,5)),$S$3:$T$177,2,FALSE),"xxx")&IFERROR(VLOOKUP(INT(MID($E11,19,5)),$S$3:$T$177,2,FALSE),"xxx"),"x","") -> , | L11: =_xlfn.IFNA(VLOOKUP(H11,$V$3:$W$38,2,FALSE),"xxx") -> xxx | M11: =_xlfn.IFNA(VLOOKUP(I11,$V$3:$W$38,2,FALSE),"xxx") -> xxx | N11: =_xlfn.IFNA(VLOOKUP(J11,$V$3:$W$38,2,FALSE),"xxx") -> xxx | O11: =_xlfn.IFNA(VLOOKUP(K11,$V$3:$W$38,2,FALSE),"xxx") -> xxx | P11: =$P$1&M11&","&N11&","&O11 -> 1:xxx,xxx,xxx | S11: 10008 | T11: 猛击 左 | V11: 无法眩晕 | W11: 8
A12: ACT2新 | B12: 野蛮巨猩 | C12: 特殊精英 | D12: 11601 | E12: =VLOOKUP(D12,怪物基本表!$D$7:$AO$276,38,FALSE) -> 30001 | F12: =SUBSTITUTE(IFERROR(VLOOKUP(INT(LEFT($E12,5)),$S$3:$T$177,2,FALSE),"xxx")&","&IFERROR(VLOOKUP(INT(MID($E12,7,5)),$S$3:$T$177,2,FALSE),"xxx")&IFERROR(VLOOKUP(INT(MID($E12,13,5)),$S$3:$T$177,2,FALSE),"xxx")&IFERROR(VLOOKUP(INT(MID($E12,19,5)),$S$3:$T$177,2,FALSE),"xxx"),"x","") -> , | I12: 狂暴 | J12: 元素抗性 | L12: =_xlfn.IFNA(VLOOKUP(H12,$V$3:$W$38,2,FALSE),"xxx") -> xxx | M12: =_xlfn.IFNA(VLOOKUP(I12,$V$3:$W$38,2,FALSE),"xxx") -> 13 | N12: =_xlfn.IFNA(VLOOKUP(J12,$V$3:$W$38,2,FALSE),"xxx") -> 15 | O12: =_xlfn.IFNA(VLOOKUP(K12,$V$3:$W$38,2,FALSE),"xxx") -> xxx | P12: =$P$1&M12&","&N12&","&O12 -> 1:13,15,xxx | S12: 10009 | T12: 猛击 右 | V12: 无法冻结 | W12: 9
B13: 蚀魂雷蛛 | C13: 特殊精英 | D13: 11611 | E13: =VLOOKUP(D13,怪物基本表!$D$7:$AO$276,38,FALSE) -> 30025 | F13: =SUBSTITUTE(IFERROR(VLOOKUP(INT(LEFT($E13,5)),$S$3:$T$177,2,FALSE),"xxx")&","&IFERROR(VLOOKUP(INT(MID($E13,7,5)),$S$3:$T$177,2,FALSE),"xxx")&IFERROR(VLOOKUP(INT(MID($E13,13,5)),$S$3:$T$177,2,FALSE),"xxx")&IFERROR(VLOOKUP(INT(MID($E13,19,5)),$S$3:$T$177,2,FALSE),"xxx"),"x","") -> , | I13: 混沌强化 | J13: 恶毒 | K13: 衰老 | L13: =_xlfn.IFNA(VLOOKUP(H13,$V$3:$W$38,2,FALSE),"xxx") -> xxx | M13: =_xlfn.IFNA(VLOOKUP(I13,$V$3:$W$38,2,FALSE),"xxx") -> 20 | N13: =_xlfn.IFNA(VLOOKUP(J13,$V$3:$W$38,2,FALSE),"xxx") -> 26 | O13: =_xlfn.IFNA(VLOOKUP(K13,$V$3:$W$38,2,FALSE),"xxx") -> 25 | P13: =$P$1&M13&","&N13&","&O13 -> 1:20,26,25 | S13: 10010 | T13: 闪电惩击 | V13: 免疫异常 | W13: 10
B14: 虫人毒师 | C14: 特殊精英 | D14: 11621 | E14: =VLOOKUP(D14,怪物基本表!$D$7:$AO$276,38,FALSE) -> 30025 | F14: =SUBSTITUTE(IFERROR(VLOOKUP(INT(LEFT($E14,5)),$S$3:$T$177,2,FALSE),"xxx")&","&IFERROR(VLOOKUP(INT(MID($E14,7,5)),$S$3:$T$177,2,FALSE),"xxx")&IFERROR(VLOOKUP(INT(MID($E14,13,5)),$S$3:$T$177,2,FALSE),"xxx")&IFERROR(VLOOKUP(INT(MID($E14,19,5)),$S$3:$T$177,2,FALSE),"xxx"),"x","") -> , | H14: 【光环】生命回复 | I14: 混沌强化 | J14: 衰老 | K14: 复仇者 | L14: =_xlfn.IFNA(VLOOKUP(H14,$V$3:$W$38,2,FALSE),"xxx") -> 34 | M14: =_xlfn.IFNA(VLOOKUP(I14,$V$3:$W$38,2,FALSE),"xxx") -> 20 | N14: =_xlfn.IFNA(VLOOKUP(J14,$V$3:$W$38,2,FALSE),"xxx") -> 25 | O14: =_xlfn.IFNA(VLOOKUP(K14,$V$3:$W$38,2,FALSE),"xxx") -> 11 | P14: =$P$1&M14&","&N14&","&O14 -> 1:20,25,11 | S14: 10011 | T14: 重击 | V14: 复仇者 | W14: 11
B15: 奴隶-野猪队长 | C15: boss | D15: 11701 | E15: =VLOOKUP(D15,怪物基本表!$D$7:$AO$276,38,FALSE) -> 31201,31202 | F15: =SUBSTITUTE(IFERROR(VLOOKUP(INT(LEFT($E15,5)),$S$3:$T$177,2,FALSE),"xxx")&","&IFERROR(VLOOKUP(INT(MID($E15,7,5)),$S$3:$T$177,2,FALSE),"xxx")&IFERROR(VLOOKUP(INT(MID($E15,13,5)),$S$3:$T$177,2,FALSE),"xxx")&IFERROR(VLOOKUP(INT(MID($E15,19,5)),$S$3:$T$177,2,FALSE),"xxx"),"x","") -> , | L15: =_xlfn.IFNA(VLOOKUP(H15,$V$3:$W$38,2,FALSE),"xxx") -> xxx | M15: =_xlfn.IFNA(VLOOKUP(I15,$V$3:$W$38,2,FALSE),"xxx") -> xxx | N15: =_xlfn.IFNA(VLOOKUP(J15,$V$3:$W$38,2,FALSE),"xxx") -> xxx | O15: =_xlfn.IFNA(VLOOKUP(K15,$V$3:$W$38,2,FALSE),"xxx") -> xxx | P15: =$P$1&M15&","&N15&","&O15 -> 1:xxx,xxx,xxx | S15: 10012 | T15: 雷神之怒 | V15: 衰变之刃 | W15: 12
B16: 电刑者 | C16: boss | D16: 11711 | E16: =VLOOKUP(D16,怪物基本表!$D$7:$AO$276,38,FALSE) -> 31211 | F16: =SUBSTITUTE(IFERROR(VLOOKUP(INT(LEFT($E16,5)),$S$3:$T$177,2,FALSE),"xxx")&","&IFERROR(VLOOKUP(INT(MID($E16,7,5)),$S$3:$T$177,2,FALSE),"xxx")&IFERROR(VLOOKUP(INT(MID($E16,13,5)),$S$3:$T$177,2,FALSE),"xxx")&IFERROR(VLOOKUP(INT(MID($E16,19,5)),$S$3:$T$177,2,FALSE),"xxx"),"x","") -> , | L16: =_xlfn.IFNA(VLOOKUP(H16,$V$3:$W$38,2,FALSE),"xxx") -> xxx | M16: =_xlfn.IFNA(VLOOKUP(I16,$V$3:$W$38,2,FALSE),"xxx") -> xxx | N16: =_xlfn.IFNA(VLOOKUP(J16,$V$3:$W$38,2,FALSE),"xxx") -> xxx | O16: =_xlfn.IFNA(VLOOKUP(K16,$V$3:$W$38,2,FALSE),"xxx") -> xxx | P16: =$P$1&M16&","&N16&","&O16 -> 1:xxx,xxx,xxx | S16: 10013 | T16: 旋风横扫 | V16: 狂暴 | W16: 13
B17: 殖民者-统领 | C17: boss | D17: 11721 | E17: =VLOOKUP(D17,怪物基本表!$D$7:$AO$276,38,FALSE) -> 31221,31222,31223,31224 | F17: =SUBSTITUTE(IFERROR(VLOOKUP(INT(LEFT($E17,5)),$S$3:$T$177,2,FALSE),"xxx")&","&IFERROR(VLOOKUP(INT(MID($E17,7,5)),$S$3:$T$177,2,FALSE),"xxx")&IFERROR(VLOOKUP(INT(MID($E17,13,5)),$S$3:$T$177,2,FALSE),"xxx")&IFERROR(VLOOKUP(INT(MID($E17,19,5)),$S$3:$T$177,2,FALSE),"xxx"),"x","") -> , | L17: =_xlfn.IFNA(VLOOKUP(H17,$V$3:$W$38,2,FALSE),"xxx") -> xxx | M17: =_xlfn.IFNA(VLOOKUP(I17,$V$3:$W$38,2,FALSE),"xxx") -> xxx | N17: =_xlfn.IFNA(VLOOKUP(J17,$V$3:$W$38,2,FALSE),"xxx") -> xxx | O17: =_xlfn.IFNA(VLOOKUP(K17,$V$3:$W$38,2,FALSE),"xxx") -> xxx | P17: =$P$1&M17&","&N17&","&O17 -> 1:xxx,xxx,xxx | S17: 10014 | T17: 冰霜之刃 | V17: 元素附体 | W17: 14
B18: 殖民者-领主 | C18: boss | D18: 11731 | E18: =VLOOKUP(D18,怪物基本表!$D$7:$AO$276,38,FALSE) -> 31231,31232,31233 | F18: =SUBSTITUTE(IFERROR(VLOOKUP(INT(LEFT($E18,5)),$S$3:$T$177,2,FALSE),"xxx")&","&IFERROR(VLOOKUP(INT(MID($E18,7,5)),$S$3:$T$177,2,FALSE),"xxx")&IFERROR(VLOOKUP(INT(MID($E18,13,5)),$S$3:$T$177,2,FALSE),"xxx")&IFERROR(VLOOKUP(INT(MID($E18,19,5)),$S$3:$T$177,2,FALSE),"xxx"),"x","") -> , | L18: =_xlfn.IFNA(VLOOKUP(H18,$V$3:$W$38,2,FALSE),"xxx") -> xxx | M18: =_xlfn.IFNA(VLOOKUP(I18,$V$3:$W$38,2,FALSE),"xxx") -> xxx | N18: =_xlfn.IFNA(VLOOKUP(J18,$V$3:$W$38,2,FALSE),"xxx") -> xxx | O18: =_xlfn.IFNA(VLOOKUP(K18,$V$3:$W$38,2,FALSE),"xxx") -> xxx | P18: =$P$1&M18&","&N18&","&O18 -> 1:xxx,xxx,xxx | S18: 10015 | T18: 剑气斩 | V18: 元素抗性 | W18: 15
B19: 任务-电刑者 | D19: 11901 | E19: =VLOOKUP(D19,怪物基本表!$D$7:$AO$276,38,FALSE) -> 31211 | F19: =SUBSTITUTE(IFERROR(VLOOKUP(INT(LEFT($E19,5)),$S$3:$T$177,2,FALSE),"xxx")&","&IFERROR(VLOOKUP(INT(MID($E19,7,5)),$S$3:$T$177,2,FALSE),"xxx")&IFERROR(VLOOKUP(INT(MID($E19,13,5)),$S$3:$T$177,2,FALSE),"xxx")&IFERROR(VLOOKUP(INT(MID($E19,19,5)),$S$3:$T$177,2,FALSE),"xxx"),"x","") -> , | L19: =_xlfn.IFNA(VLOOKUP(H19,$V$3:$W$38,2,FALSE),"xxx") -> xxx | M19: =_xlfn.IFNA(VLOOKUP(I19,$V$3:$W$38,2,FALSE),"xxx") -> xxx | N19: =_xlfn.IFNA(VLOOKUP(J19,$V$3:$W$38,2,FALSE),"xxx") -> xxx | O19: =_xlfn.IFNA(VLOOKUP(K19,$V$3:$W$38,2,FALSE),"xxx") -> xxx | P19: =$P$1&M19&","&N19&","&O19 -> 1:xxx,xxx,xxx | S19: 10016 | T19: 复仇 | V19: 幽灵 | W19: 16
B20: 任务-封印者 | D20: 11911 | E20: =VLOOKUP(D20,怪物基本表!$D$7:$AO$276,38,FALSE) -> 31211 | F20: =SUBSTITUTE(IFERROR(VLOOKUP(INT(LEFT($E20,5)),$S$3:$T$177,2,FALSE),"xxx")&","&IFERROR(VLOOKUP(INT(MID($E20,7,5)),$S$3:$T$177,2,FALSE),"xxx")&IFERROR(VLOOKUP(INT(MID($E20,13,5)),$S$3:$T$177,2,FALSE),"xxx")&IFERROR(VLOOKUP(INT(MID($E20,19,5)),$S$3:$T$177,2,FALSE),"xxx"),"x","") -> , | L20: =_xlfn.IFNA(VLOOKUP(H20,$V$3:$W$38,2,FALSE),"xxx") -> xxx | M20: =_xlfn.IFNA(VLOOKUP(I20,$V$3:$W$38,2,FALSE),"xxx") -> xxx | N20: =_xlfn.IFNA(VLOOKUP(J20,$V$3:$W$38,2,FALSE),"xxx") -> xxx | O20: =_xlfn.IFNA(VLOOKUP(K20,$V$3:$W$38,2,FALSE),"xxx") -> xxx | P20: =$P$1&M20&","&N20&","&O20 -> 1:xxx,xxx,xxx | S20: 10018 | T20: 冰霜之锤1 | V20: 冰冻强化 | W20: 17
B21: 任务-雷祭司亡魂 | D21: 11921 | E21: =VLOOKUP(D21,怪物基本表!$D$7:$AO$276,38,FALSE) -> 30070,30071 | F21: =SUBSTITUTE(IFERROR(VLOOKUP(INT(LEFT($E21,5)),$S$3:$T$177,2,FALSE),"xxx")&","&IFERROR(VLOOKUP(INT(MID($E21,7,5)),$S$3:$T$177,2,FALSE),"xxx")&IFERROR(VLOOKUP(INT(MID($E21,13,5)),$S$3:$T$177,2,FALSE),"xxx")&IFERROR(VLOOKUP(INT(MID($E21,19,5)),$S$3:$T$177,2,FALSE),"xxx"),"x","") -> , | L21: =_xlfn.IFNA(VLOOKUP(H21,$V$3:$W$38,2,FALSE),"xxx") -> xxx | M21: =_xlfn.IFNA(VLOOKUP(I21,$V$3:$W$38,2,FALSE),"xxx") -> xxx | N21: =_xlfn.IFNA(VLOOKUP(J21,$V$3:$W$38,2,FALSE),"xxx") -> xxx | O21: =_xlfn.IFNA(VLOOKUP(K21,$V$3:$W$38,2,FALSE),"xxx") -> xxx | P21: =$P$1&M21&","&N21&","&O21 -> 1:xxx,xxx,xxx | S21: 10021 | T21: 烈火斩击 | V21: 火焰强化 | W21: 18
