Workbook

Sheet 装备表
B1: equipment.xml | H1: equipment.xml | R1: equipment.xml | W1: equipment.xml | AD1: equipment.xml
E3: 道具ID 1~9999 装备ID 10000+ | F3: 装备名称 | G3: 装备描述 | H3: 装备图标 | I3: 占用物品栏 宽度 | J3: 占用物品栏 高度 | K3: 装备类型 1-单手剑 2-单手斧 3-单手锤 4-匕首 5-双手剑 6-双手斧 7-双手锤 8-法杖 9-弓 10-长柄 11-盾牌 21-头盔 22-衣服 23-手套 24-鞋子 25-腰带 31-项链 32-戒指 98-魂灯 99-火炬 | L3: 稀有度 1-普通 2-精良 3-稀有 4-史诗 5-传奇 6-套装 | M3: 套装ID 能够激活哪个套装 | N3: 装备基础价格 | O3: 掉落权重 当前：3/5/1 这个字段不生效，全靠掉落表参数 | P3: 商店随机权重 当前：3/5/1 | Q3: 赌博权重 当前：0/60/30/8/2 | R3: 职业限制 0或不填-无限制 1-野蛮人 2-女巫 3-圣骑士 4-死灵法师 5-游侠 6-刺客 7-死亡骑士 8-萨满 | S3: 基础属性 武器基础属性：最小攻击力-最大攻击力 防具基础属性：护甲值 火炬基础照亮范围和时间 | T3: 词缀中文id | U3: 词缀属性 1:属性表--id,min,max 2:buff--id 3:passive--id 4:bd--id | V3: 随机词缀的类 填id表示允许出现这些类别 | W3: 装备技能 武器上自带的主动技能ID | X3: 装备buff 自带buff 火炬开关会导致buff上或者下 | Y3: 武器攻速 攻击间隔(MS) | Z3: 装备重量 （待定） | AA3: 穿戴模型 | AB3: 装备特效 特效文件尾号 | AC3: 掉落模型 | AD3: 掉落音效 | AE3: 拾取音效 | AF3: 是否地图专属掉落 1-是 0-不填不是 | AG3: 是否可丢弃 1-不可丢弃 0或不填可丢弃 | AH3: 是否可分解 1-不可分解 0或不填可分解 | AI3: 任务道具关联的任务ID (控制道具是否继续掉落）
E4: id_i | F4: name_i | G4: desc_i | H4: icon_l | I4: invwidth_i | J4: invheight_i | K4: type_i | L4: rarity_i | M4: set_id_i | N4: base_price_i | O4: chance_i | P4: shop_chance_i | Q4: gamble_chance_i | R4: vocation_i | S4: base_attri_m | T4: chinese_i | U4: affix_attri_n | V4: item_affix_l | W4: weapon_skill_i | X4: weapon_buff_l | Y4: weapon_atkspeed_i | Z4: weight_i | AA4: wearmodel_i | AB4: effect_s | AC4: dropmodel_i | AD4: dropsound_i | AE4: pickupsound_i | AF4: exclusive_i | AG4: discard_i | AH4: disassemble_i | AI4: task_id_i
E5: 0 | F5: 0 | G5: 0 | H5: 0 | I5: 0 | J5: 0 | K5: 0 | L5: 1 | M5: 0 | N5: 0 | O5: 0 | P5: 0 | Q5: 0 | R5: 0 | S5: 0:0 | T5: 0 | U5: 0:0 | V5: 0 | W5: 0 | X5: 0 | Y5: 0 | Z5: 0 | AA5: 0 | AB5: 0 | AC5: 0 | AD5: 0 | AE5: 0 | AF5: 0 | AG5: 0 | AH5: 0 | AI5: 0
B6: 测试装备:三骰子,血量,幸运 | E6: 90000 | F6: 11672 | G6: 12672 | H6: 5504 | I6: 1 | J6: 1 | K6: 32 | L6: 1 | M6: 0 | N6: 999999 | O6: 0 | P6: 0 | Q6: 0 | R6: 0 | S6: 0:0 | T6: 0 | U6: 1:501,999,999,502,999,999,517,999,999,300,999999,999999,104,9999,9999 | V6: 9999 | W6: 0 | X6: 0 | Y6: 0 | Z6: 0 | AA6: 0 | AC6: 1026 | AD6: 0 | AE6: 0 | AF6: 0 | AG6: 0 | AH6: 0 | AI6: 0
B7: 武器 | C7: 单手剑 | E7: 10001 | F7: 10001 | G7: 0 | H7: 6561,6562,6563,6564,6565 | I7: 1 | J7: 3 | K7: 1 | L7: 1 | M7: 0 | N7: 5 | O7: 100 | P7: 100 | Q7: 0 | R7: 0 | S7: 233:4;234:8;219:8 | T7: 0 | U7: 0:0 | V7: 9999 | W7: 10049 | Y7: 1200 | Z7: 0 | AA7: 1090101 | AB7: _06 | AC7: 1001 | AD7: 0 | AE7: 0 | AF7: 0 | AG7: 0 | AH7: 0 | AI7: 0
C8: 单手斧 | E8: 10201 | F8: 10002 | G8: 0 | H8: 6541,6542,6543,6544,6545 | I8: 2 | J8: 3 | K8: 2 | L8: 1 | M8: 0 | N8: 5 | O8: 100 | P8: 100 | Q8: 0 | R8: 0 | S8: 233:3;234:9;219:10 | T8: 0 | U8: 0:0 | V8: 9999 | W8: 10008 | Y8: 1100 | Z8: 0 | AA8: 1090401 | AB8: _03 | AC8: 1003 | AD8: 0 | AE8: 0 | AF8: 0 | AG8: 0 | AH8: 0 | AI8: 0
C9: 单手锤 | E9: 10301 | F9: 10003 | G9: 0 | H9: 6521,6522,6523,6524,6525 | I9: 1 | J9: 3 | K9: 3 | L9: 1 | M9: 0 | N9: 5 | O9: 100 | P9: 100 | Q9: 0 | R9: 0 | S9: 233:3;234:10;219:5 | T9: 0 | U9: 0:0 | V9: 9999 | W9: 10051 | Y9: 1100 | Z9: 0 | AA9: 1092001 | AB9: _03 | AC9: 1007 | AD9: 0 | AE9: 0 | AF9: 0 | AG9: 0 | AH9: 0 | AI9: 0
C10: 匕首 | E10: 10401 | F10: 10004 | G10: 0 | H10: 6501,6502,6503,6504,6505 | I10: 1 | J10: 3 | K10: 4 | L10: 1 | M10: 0 | N10: 5 | O10: 100 | P10: 100 | Q10: 0 | R10: 0 | S10: 233:3;234:5;219:8 | T10: 0 | U10: 0:0 | V10: 9999 | W10: 10024 | Y10: 800 | Z10: 0 | AA10: 1090501 | AB10: _03 | AC10: 1001 | AD10: 0 | AE10: 0 | AF10: 0 | AG10: 0 | AH10: 0 | AI10: 0
C11: 双手剑 | E11: 10501 | F11: 10005 | G11: 0 | H11: 6681,6682,6683,6684,6685 | I11: 1 | J11: 4 | K11: 5 | L11: 1 | M11: 0 | N11: 5 | O11: 100 | P11: 100 | Q11: 0 | R11: 0 | S11: 233:6;234:13;219:15 | T11: 0 | U11: 0:0 | V11: 9999 | W11: 10053 | Y11: 1300 | Z11: 0 | AA11: 1090201 | AB11: _10 | AC11: 1002 | AD11: 0 | AE11: 0 | AF11: 0 | AG11: 0 | AH11: 0 | AI11: 0
C12: 双手斧 | E12: 10601 | F12: 10006 | G12: 0 | H12: 6661,6662,6663,6664,6665 | I12: 2 | J12: 3 | K12: 6 | L12: 1 | M12: 0 | N12: 5 | O12: 100 | P12: 100 | Q12: 0 | R12: 0 | S12: 233:6;234:15;219:20 | T12: 0 | U12: 0:0 | V12: 9999 | W12: 10055 | Y12: 1400 | Z12: 0 | AA12: 1091021 | AB12: _10 | AC12: 1004 | AD12: 0 | AE12: 0 | AF12: 0 | AG12: 0 | AH12: 0 | AI12: 0
C13: 双手锤 | E13: 10701 | F13: 10007 | G13: 0 | H13: 6641,6642,6643,6644,6645 | I13: 2 | J13: 4 | K13: 7 | L13: 1 | M13: 0 | N13: 5 | O13: 100 | P13: 100 | Q13: 0 | R13: 0 | S13: 233:4;234:20;219:12 | T13: 0 | U13: 0:0 | V13: 9999 | W13: 10057 | Y13: 1500 | Z13: 0 | AA13: 1092101 | AB13: _10 | AC13: 1021 | AD13: 0 | AE13: 0 | AF13: 0 | AG13: 0 | AH13: 0 | AI13: 0
C14: 火法杖 | E14: 10801 | F14: 10008 | G14: 0 | H14: 6601,6602,6603,6604,6605 | I14: 1 | J14: 4 | K14: 8 | L14: 1 | M14: 0 | N14: 5 | O14: 100 | P14: 100 | Q14: 0 | R14: 0 | S14: 233:5;234:10;219:15 | T14: 0 | U14: 0:0 | V14: 9999 | W14: 10001 | Y14: 1000 | Z14: 0 | AA14: 1091302 | AB14: _08 | AC14: 1013 | AD14: 0 | AE14: 0 | AF14: 0 | AG14: 0 | AH14: 0 | AI14: 0
C15: 弓 | E15: 10901 | F15: 10009 | G15: 0 | H15: 6621,6622,6623,6624,6625 | I15: 2 | J15: 3 | K15: 9 | L15: 1 | M15: 0 | N15: 5 | O15: 100 | P15: 100 | Q15: 0 | R15: 0 | S15: 233:6;234:12;219:20 | T15: 0 | U15: 0:0 | V15: 9999 | W15: 10026 | Y15: 1400 | Z15: 0 | AA15: 1091701 | AB15: _13 | AC15: 1017 | AD15: 0 | AE15: 0 | AF15: 0 | AG15: 0 | AH15: 0 | AI15: 0
C16: 长柄武器 | E16: 11001 | F16: 10010 | G16: 0 | H16: 6701,6702,6703,6704,6705 | I16: 2 | J16: 4 | K16: 10 | L16: 1 | M16: 0 | N16: 5 | O16: 100 | P16: 100 | Q16: 0 | R16: 0 | S16: 233:8;234:15;219:15 | T16: 0 | U16: 0:0 | V16: 9999 | W16: 10048 | Y16: 1650 | Z16: 0 | AA16: 1091002 | AB16: _12 | AC16: 1010 | AD16: 0 | AE16: 0 | AF16: 0 | AG16: 0 | AH16: 0 | AI16: 0
C17: 盾牌 | E17: 11101 | F17: 10011 | G17: 0 | H17: 6581,6582,6583,6584,6585 | I17: 2 | J17: 2 | K17: 11 | L17: 1 | M17: 0 | N17: 5 | O17: 100 | P17: 100 | Q17: 0 | R17: 0 | S17: 305:102;313:10 | T17: 0 | U17: 0:0 | V17: 9999 | W17: 0 | Y17: 0 | Z17: 0 | AA17: 1091901 | AC17: 1019 | AD17: 0 | AE17: 0 | AF17: 0 | AG17: 0 | AH17: 0 | AI17: 0
C18: 冰法杖 | E18: 11201 | F18: 10008 | G18: 0 | H18: 6601,6602,6603,6604,6605 | I18: 1 | J18: 4 | K18: 8 | L18: 1 | M18: 0 | N18: 5 | O18: 100 | P18: 100 | Q18: 0 | R18: 0 | S18: 233:5;234:10;219:15 | T18: 0 | U18: 0:0 | V18: 9999 | W18: 10003 | Y18: 1200 | Z18: 0 | AA18: 1091302 | AB18: _08 | AC18: 1013 | AD18: 0 | AE18: 0 | AF18: 0 | AG18: 0 | AH18: 0 | AI18: 0
C19: 雷法杖 | E19: 11301 | F19: 10008 | G19: 0 | H19: 6601,6602,6603,6604,6605 | I19: 1 | J19: 4 | K19: 8 | L19: 1 | M19: 0 | N19: 5 | O19: 100 | P19: 100 | Q19: 0 | R19: 0 | S19: 233:5;234:10;219:15 | T19: 0 | U19: 0:0 | V19: 9999 | W19: 10004 | Y19: 1500 | Z19: 0 | AA19: 1091302 | AB19: _08 | AC19: 1013 | AD19: 0 | AE19: 0 | AF19: 0 | AG19: 0 | AH19: 0 | AI19: 0
C20: 毒法杖 | E20: 11401 | F20: 10008 | G20: 0 | H20: 6601,6602,6603,6604,6605 | I20: 1 | J20: 4 | K20: 8 | L20: 1 | M20: 0 | N20: 5 | O20: 100 | P20: 100 | Q20: 0 | R20: 0 | S20: 233:5;234:10;219:11 | T20: 0 | U20: 0:0 | V20: 9999 | W20: 10006 | Y20: 1200 | Z20: 0 | AA20: 1091302 | AB20: _08 | AC20: 1013 | AD20: 0 | AE20: 0 | AF20: 0 | AG20: 0 | AH20: 0 | AI20: 0
C21: 骨魂法杖 | E21: 11501 | F21: 10008 | G21: 0 | H21: 6601,6602,6603,6604,6605 | I21: 1 | J21: 4 | K21: 8 | L21: 1 | M21: 0 | N21: 5 | O21: 100 | P21: 100 | Q21: 0 | R21: 0 | S21: 233:5;234:10;219:6 | T21: 0 | U21: 0:0 | V21: 9999 | W21: 10007 | Y21: 1500 | Z21: 0 | AA21: 1091302 | AB21: _08 | AC21: 1013 | AD21: 0 | AE21: 0 | AF21: 0 | AG21: 0 | AH21: 0 | AI21: 0
B22: 防具 | C22: 头盔 | E22: 12101 | F22: 10012 | G22: 0 | H22: 5401,5416,5431 | I22: 2 | J22: 2 | K22: 21 | L22: 1 | M22: 0 | N22: 5 | O22: 100 | P22: 100 | Q22: 0 | R22: 0 | S22: 305:30 | T22: 0 | U22: 0:0 | V22: 9999 | W22: 0 | Y22: 0 | Z22: 0 | AA22: 0 | AC22: 1023 | AD22: 0 | AE22: 0 | AF22: 0 | AG22: 0 | AH22: 0 | AI22: 0
C23: 衣服 | E23: 12201 | F23: 10013 | G23: 0 | H23: 5801,5816,5831 | I23: 2 | J23: 3 | K23: 22 | L23: 1 | M23: 0 | N23: 5 | O23: 100 | P23: 100 | Q23: 0 | R23: 0 | S23: 305:60 | T23: 0 | U23: 0:0 | V23: 9999 | W23: 0 | Y23: 0 | Z23: 0 | AA23: 0 | AC23: 1022 | AD23: 0 | AE23: 0 | AF23: 0 | AG23: 0 | AH23: 0 | AI23: 0
C24: 手套 | E24: 12301 | F24: 10014 | G24: 0 | H24: 5301,5316,5331 | I24: 2 | J24: 2 | K24: 23 | L24: 1 | M24: 0 | N24: 5 | O24: 100 | P24: 100 | Q24: 0 | R24: 0 | S24: 305:30 | T24: 0 | U24: 0:0 | V24: 9999 | W24: 0 | Y24: 0 | Z24: 0 | AA24: 0 | AC24: 1028 | AD24: 0 | AE24: 0 | AF24: 0 | AG24: 0 | AH24: 0 | AI24: 0
C25: 鞋子 | E25: 12401 | F25: 10015 | G25: 0 | H25: 5601,5616,5631 | I25: 2 | J25: 2 | K25: 24 | L25: 1 | M25: 0 | N25: 5 | O25: 100 | P25: 100 | Q25: 0 | R25: 0 | S25: 305:40 | T25: 0 | U25: 0:0 | V25: 9999 | W25: 0 | Y25: 0 | Z25: 0 | AA25: 0 | AC25: 1025 | AD25: 0 | AE25: 0 | AF25: 0 | AG25: 0 | AH25: 0 | AI25: 0
C26: 腰带 | E26: 12501 | F26: 10016 | G26: 0 | H26: 5701,5716,5731 | I26: 2 | J26: 1 | K26: 25 | L26: 1 | M26: 0 | N26: 5 | O26: 100 | P26: 100 | Q26: 0 | R26: 0 | S26: 305:30 | T26: 0 | U26: 0:0 | V26: 9999 | W26: 0 | Y26: 0 | Z26: 0 | AA26: 0 | AC26: 1024 | AD26: 0 | AE26: 0 | AF26: 0 | AG26: 0 | AH26: 0 | AI26: 0
B27: 首饰 | C27: 项链 | E27: 13101 | F27: 10017 | G27: 0 | H27: 5501,5502,5503 | I27: 1 | J27: 1 | K27: 31 | L27: 1 | M27: 0 | N27: 5 | O27: 0 | P27: 0 | Q27: 0 | R27: 0 | S27: 0:0 | T27: 0 | U27: 0:0 | V27: 9999 | W27: 0 | Y27: 0 | Z27: 0 | AA27: 0 | AC27: 1026 | AD27: 0 | AE27: 0 | AF27: 0 | AG27: 0 | AH27: 0 | AI27: 0
C28: 戒指 | E28: 13201 | F28: 10018 | G28: 0 | H28: 5516,5517,5518 | I28: 1 | J28: 1 | K28: 32 | L28: 1 | M28: 0 | N28: 5 | O28: 0 | P28: 0 | Q28: 0 | R28: 0 | S28: 0:0 | T28: 0 | U28: 0:0 | V28: 9999 | W28: 0 | Y28: 0 | Z28: 0 | AA28: 0 | AC28: 1027 | AD28: 0 | AE28: 0 | AF28: 0 | AG28: 0 | AH28: 0 | AI28: 0
B29: 武器 | C29: 单手剑 | E29: 10002 | F29: 10019 | G29: 0 | H29: 6561,6562,6563,6564,6565 | I29: 1 | J29: 3 | K29: 1 | L29: 2 | M29: 0 | N29: 10 | O29: 34 | P29: 34 | Q29: 1289 | R29: 0 | S29: 233:5;234:10;219:8 | T29: 0 | U29: 0:0 | V29: 101 | W29: 10049 | Y29: 1200 | Z29: 0 | AA29: 1090101 | AB29: _06 | AC29: 1001 | AD29: 0 | AE29: 0 | AF29: 0 | AG29: 0 | AH29: 0 | AI29: 0
C30: 单手斧 | E30: 10202 | F30: 10020 | G30: 0 | H30: 6541,6542,6543,6544,6545 | I30: 2 | J30: 3 | K30: 2 | L30: 2 | M30: 0 | N30: 10 | O30: 34 | P30: 34 | Q30: 1289 | R30: 0 | S30: 233:4;234:12;219:10 | T30: 0 | U30: 0:0 | V30: 201 | W30: 10008 | Y30: 1100 | Z30: 0 | AA30: 1090401 | AB30: _03 | AC30: 1003 | AD30: 0 | AE30: 0 | AF30: 0 | AG30: 0 | AH30: 0 | AI30: 0
C31: 单手锤 | E31: 10302 | F31: 10021 | G31: 0 | H31: 6521,6522,6523,6524,6525 | I31: 1 | J31: 3 | K31: 3 | L31: 2 | M31: 0 | N31: 10 | O31: 34 | P31: 34 | Q31: 1289 | R31: 0 | S31: 233:4;234:13;219:5 | T31: 0 | U31: 0:0 | V31: 301 | W31: 10051 | Y31: 1100 | Z31: 0 | AA31: 1092001 | AB31: _03 | AC31: 1007 | AD31: 0 | AE31: 0 | AF31: 0 | AG31: 0 | AH31: 0 | AI31: 0
C32: 匕首 | E32: 10402 | F32: 10022 | G32: 0 | H32: 6501,6502,6503,6504,6505 | I32: 1 | J32: 3 | K32: 4 | L32: 2 | M32: 0 | N32: 10 | O32: 34 | P32: 34 | Q32: 1289 | R32: 0 | S32: 233:4;234:6;219:8 | T32: 0 | U32: 0:0 | V32: 401 | W32: 10024 | Y32: 800 | Z32: 0 | AA32: 1090501 | AB32: _03 | AC32: 1001 | AD32: 0 | AE32: 0 | AF32: 0 | AG32: 0 | AH32: 0 | AI32: 0
C33: 双手剑 | E33: 10502 | F33: 10023 | G33: 0 | H33: 6681,6682,6683,6684,6685 | I33: 1 | J33: 4 | K33: 5 | L33: 2 | M33: 0 | N33: 10 | O33: 34 | P33: 34 | Q33: 1289 | R33: 0 | S33: 233:8;234:18;219:15 | T33: 0 | U33: 0:0 | V33: 501 | W33: 10053 | Y33: 1300 | Z33: 0 | AA33: 1090201 | AB33: _10 | AC33: 1002 | AD33: 0 | AE33: 0 | AF33: 0 | AG33: 0 | AH33: 0 | AI33: 0
C34: 双手斧 | E34: 10602 | F34: 10024 | G34: 0 | H34: 6661,6662,6663,6664,6665 | I34: 2 | J34: 3 | K34: 6 | L34: 2 | M34: 0 | N34: 10 | O34: 34 | P34: 34 | Q34: 1289 | R34: 0 | S34: 233:8;234:21;219:20 | T34: 0 | U34: 0:0 | V34: 601 | W34: 10055 | Y34: 1400 | Z34: 0 | AA34: 1091021 | AB34: _10 | AC34: 1004 | AD34: 0 | AE34: 0 | AF34: 0 | AG34: 0 | AH34: 0 | AI34: 0
C35: 双手锤 | E35: 10702 | F35: 10025 | G35: 0 | H35: 6641,6642,6643,6644,6645 | I35: 2 | J35: 4 | K35: 7 | L35: 2 | M35: 0 | N35: 10 | O35: 34 | P35: 34 | Q35: 1289 | R35: 0 | S35: 233:6;234:29;219:12 | T35: 0 | U35: 0:0 | V35: 701 | W35: 10057 | Y35: 1500 | Z35: 0 | AA35: 1092101 | AB35: _10 | AC35: 1021 | AD35: 0 | AE35: 0 | AF35: 0 | AG35: 0 | AH35: 0 | AI35: 0
C36: 火法杖 | E36: 10802 | F36: 10026 | G36: 0 | H36: 6601,6602,6603,6604,6605 | I36: 1 | J36: 4 | K36: 8 | L36: 2 | M36: 0 | N36: 10 | O36: 34 | P36: 34 | Q36: 1289 | R36: 0 | S36: 233:7;234:14;219:15 | T36: 0 | U36: 0:0 | V36: 801 | W36: 10001 | Y36: 1000 | Z36: 0 | AA36: 1091302 | AB36: _08 | AC36: 1013 | AD36: 0 | AE36: 0 | AF36: 0 | AG36: 0 | AH36: 0 | AI36: 0
C37: 弓 | E37: 10902 | F37: 10027 | G37: 0 | H37: 6621,6622,6623,6624,6625 | I37: 2 | J37: 3 | K37: 9 | L37: 2 | M37: 0 | N37: 10 | O37: 34 | P37: 34 | Q37: 1289 | R37: 0 | S37: 233:8;234:17;219:20 | T37: 0 | U37: 0:0 | V37: 901 | W37: 10026 | Y37: 1400 | Z37: 0 | AA37: 1091701 | AB37: _13 | AC37: 1017 | AD37: 0 | AE37: 0 | AF37: 0 | AG37: 0 | AH37: 0 | AI37: 0
C38: 长柄武器 | E38: 11002 | F38: 10028 | G38: 0 | H38: 6701,6702,6703,6704,6705 | I38: 2 | J38: 4 | K38: 10 | L38: 2 | M38: 0 | N38: 10 | O38: 34 | P38: 34 | Q38: 1289 | R38: 0 | S38: 233:11;234:21;219:15 | T38: 0 | U38: 0:0 | V38: 1001 | W38: 10048 | Y38: 1650 | Z38: 0 | AA38: 1091002 | AB38: _12 | AC38: 1010 | AD38: 0 | AE38: 0 | AF38: 0 | AG38: 0 | AH38: 0 | AI38: 0
C39: 盾牌 | E39: 11102 | F39: 10029 | G39: 0 | H39: 6581,6582,6583,6584,6585 | I39: 2 | J39: 2 | K39: 11 | L39: 2 | M39: 0 | N39: 10 | O39: 34 | P39: 34 | Q39: 1289 | R39: 0 | S39: 305:186;313:12 | T39: 0 | U39: 0:0 | V39: 1101 | W39: 0 | Y39: 0 | Z39: 0 | AA39: 1091901 | AC39: 1019 | AD39: 0 | AE39: 0 | AF39: 0 | AG39: 0 | AH39: 0 | AI39: 0
C40: 冰法杖 | E40: 11202 | F40: 10026 | G40: 0 | H40: 6601,6602,6603,6604,6605 | I40: 1 | J40: 4 | K40: 8 | L40: 2 | M40: 0 | N40: 10 | O40: 34 | P40: 34 | Q40: 1289 | R40: 0 | S40: 233:7;234:14;219:15 | T40: 0 | U40: 0:0 | V40: 801 | W40: 10003 | Y40: 1200 | Z40: 0 | AA40: 1091302 | AB40: _08 | AC40: 1013 | AD40: 0 | AE40: 0 | AF40: 0 | AG40: 0 | AH40: 0 | AI40: 0
C41: 雷法杖 | E41: 11302 | F41: 10026 | G41: 0 | H41: 6601,6602,6603,6604,6605 | I41: 1 | J41: 4 | K41: 8 | L41: 2 | M41: 0 | N41: 10 | O41: 34 | P41: 34 | Q41: 1289 | R41: 0 | S41: 233:7;234:14;219:15 | T41: 0 | U41: 0:0 | V41: 801 | W41: 10004 | Y41: 1500 | Z41: 0 | AA41: 1091302 | AB41: _08 | AC41: 1013 | AD41: 0 | AE41: 0 | AF41: 0 | AG41: 0 | AH41: 0 | AI41: 0
...

Sheet 套装属性表
A1: set_equip.xml
C2: 流水ID | D2: 套装ID | E2: 套装名称 | F2: 激活套装件数 | G2: 效果描述 (中文ID1,中文ID2） | H2: 套装属性( 类型：值） 1:属性表--id,x 2:buff--id 3:passive--id 4:bd--id | I2: 第二个 | J2: 第三个 | K2: 第四个 | L2: 第五个 | M2: 第六个
C3: id_i | D3: set_id_i | E3: set_name_i | F3: activate_num_l | G3: desc_l | H3: set_attri_fir_n | I3: set_attri_sec_n | J3: set_attri_thi_n | K3: set_attri_fou_n | L3: set_attri_fif_n | M3: set_attri_six_n
C4: 0 | D4: 0 | E4: 0 | F4: 0,1 | G4: 0 | H4: 0:0 | I4: 0:0 | J4: 0:0 | K4: 0:0 | L4: 0:0 | M4: 0:0
A5: 马卡多的教诲 | C5: 1 | D5: 1 | E5: 600001 | F5: 2,4,6 | G5: 610007,610008,610009 | H5: 3:10003 | I5: 1:252,40 | J5: 4:40013
A6: 先祖庇护 | C6: 2 | D6: 2 | E6: 600014 | F6: 2,4,6 | G6: 610016,610017,610018 | H6: 1:305,500,247,30 | I6: 2:41006 | J6: 3:10004
A7: 秘火阿诺 | C7: 3 | D7: 3 | E7: 600027 | F7: 2,4,6 | G7: 610025,610026,610027 | H7: 1:241,10 | I7: 4:40016 | J7: 4:40017
A8: 奔腾行者 | C8: 4 | D8: 4 | E8: 600040 | F8: 2,4,6 | G8: 610034,610035,610036 | H8: 1:412,10 | I8: 2:41011 | J8: 2:41013
A9: 猎神门徒 | C9: 5 | D9: 5 | E9: 600053 | F9: 2,4,6 | G9: 610043,610044,610045 | H9: 4:40018 | I9: 2:41014;4:40019 | J9: 3:10007,10012
A10: 荒原生存者 | C10: 6 | D10: 6 | E10: 600066 | F10: 2,4,6 | G10: 610052,610053,610054 | H10: 4:40020 | I10: 3:10008,10013 | J10: 3:10009
A11: 混沌伟力 | C11: 7 | D11: 7 | E11: 600079 | F11: 2,4,6 | G11: 610061,610062,610063 | H11: 1:211,30,216,30 | I11: 4:40021 | J11: 3:10010
A12: 死者永生 | C12: 8 | D12: 8 | E12: 600092 | F12: 2,4,6 | G12: 610070,610071,610072 | H12: 1:702,30,721,30 | I12: 4:40022 | J12: 3:10011,10014
A13: 荆棘之王的非难 | C13: 9 | D13: 9 | E13: 600105 | F13: 2 | G13: 610075 | H13: 1:413,100
A14: 黑暗学者 | C14: 10 | D14: 10 | E14: 600110 | F14: 3 | G14: 610079 | H14: 1:401,50
A15: 盗墓者的遗志 | C15: 11 | D15: 11 | E15: 600117 | F15: 3 | G15: 610083 | H15: 1:403,50
A16: 盗宝地精之赐 | C16: 12 | D16: 12 | E16: 600124 | F16: 3 | G16: 610087 | H16: 1:421,200
A17: 冰冻山巅 | C17: 13 | D17: 13 | E17: 600131 | F17: 2,4,6 | G17: 610094,610095,610096 | H17: 4:40048 | I17: 4:40049 | J17: 4:40050
A18: 狂怒 | C18: 14 | D18: 14 | E18: 600144 | F18: 2,4,6 | G18: 610103,610104,610105 | H18: 3:10020 | I18: 4:40055 | J18: 3:10021
A19: 雷光彼岸花 | C19: 15 | D19: 15 | E19: 600157 | F19: 2,4,6 | G19: 610112,610113,610114 | H19: 4:40058 | I19: 4:40059 | J19: 4:40060
A20: 诅咒师的阴谋 | C20: 16 | D20: 16 | E20: 600170 | F20: 2,4,6 | G20: 610121,610122,610123 | H20: 4:40067,40068 | I20: 3:10023 | J20: 3:10024
A21: 圣山朝拜 | C21: 17 | D21: 17 | E21: 600183 | F21: 2,4,6 | G21: 610130,610131,610132 | H21: 4:40076 | I21: 3:10028 | J21: 4:40077,40078
A22: 不朽堡垒 | C22: 18 | D22: 18 | E22: 600196 | F22: 2,4,6 | G22: 610139,610140,610141 | H22: 3:10029 | I22: 3:10030 | J22: 4:40079
A23: 天使联盟 | C23: 19 | D23: 19 | E23: 600209 | F23: 2,4,6 | G23: 610148,610149,610150 | H23: 1:211,30,215,30 | I23: 3:10031 | J23: 3:10032
A24: 刺客庭的审判 | C24: 20 | D24: 20 | E24: 600222 | F24: 2,4,6 | G24: 610157,610148,610159 | H24: 4:40094 | I24: 4:40095 | J24: 3:10034
A25: 暗杀纲领 | C25: 21 | D25: 21 | E25: 600235 | F25: 2,4,6 | G25: 610166,610167,610168 | H25: 4:40096 | I25: 3:10035 | J25: 4:40097
A26: 陷阱大师的教诲 | C26: 22 | D26: 22 | E26: 600248 | F26: 2,4,6 | G26: 610175,610176,610177 | H26: 4:40098 | I26: 4:40099 | J26: 4:40100,40101,40102

Sheet 暴击率219设置
G2: 暴击率
E3: 1 | F3: 单手剑 | G3: 8
E4: 2 | F4: 单手斧 | G4: 10
E5: 3 | F5: 单手锤 | G5: 5
E6: 4 | F6: 匕首 | G6: 8
E7: 5 | F7: 双手剑 | G7: 15
E8: 6 | F8: 双手斧 | G8: 20
E9: 7 | F9: 双手锤 | G9: 12
E10: 8 | F10: 法杖 | G10: 15
E11: 9 | F11: 弓 | G11: 20
E12: 10 | F12: 长柄 | G12: 15
E13: 11 | F13: 盾牌
E14: 21 | F14: 头盔
E15: 22 | F15: 衣服
E16: 23 | F16: 手套
E17: 24 | F17: 鞋子
E18: 25 | F18: 腰带
E19: 31 | F19: 项链
E20: 32 | F20: 戒指
E21: 99 | F21: 火炬

Sheet 传说装备设计
F1: -1 | I1: =COUNTIF($E$8:$E$179,F1) -> 9
F2: 1 | H2: 死 | I2: =COUNTIF($E$8:$E$179,F2) -> 13
C3: 低 | D3: 8 | F3: 2 | H3: 雷 | I3: =COUNTIF($E$8:$E$179,F3) -> 12
C4: 中 | D4: 10 | F4: 3 | H4: 腐 | I4: =COUNTIF($E$8:$E$179,F4) -> 12
C5: 强 | D5: 12 | F5: 4 | H5: 冰 | I5: =COUNTIF($E$8:$E$179,F5) -> 12 | AF5: CHAR(10)
F6: 5 | H6: 炎 | I6: =COUNTIF($E$8:$E$179,F6) -> 12 | J6: 0 | M6: 1 | P6: 2 | S6: 3 | V6: 4 | Y6: 5
C7: 装备ID | D7: 装备中文名 | E7: 专属掉落地图 | F7: 部位 | H7: 强度总和 | I7: 属性1名称 | J7: 属性1值 | K7: 随机空间 | L7: 属性2名称 | M7: 属性2值 | N7: 随机空间 | O7: 属性3名称 | P7: 属性3值 | Q7: 随机空间 | R7: 属性4名称 | S7: 属性4值 | T7: 随机空间 | U7: 属性5名称 | V7: 属性5值 | W7: 随机空间 | X7: 属性6名称 | Y7: 属性6值 | Z7: 随机空间 | AB7: 最终属性配置 | AC7: 中文描述 | AS7: 中文最终输出 | BE7: 属性名称 | BF7: 数值类型 | BG7: 属性ID | BH7: 标准值 | BI7: 频率 | BJ7: 最大偏差值
C8: 14694 | D8: 焚灵之杖 | E8: 5 | F8: 法杖 | H8: 11 | I8: 火焰伤害 | J8: 2 | K8: 0.2 | L8: 智力 | M8: 2 | N8: 0.2 | O8: 火焰伤害% | P8: 2 | Q8: 0.2 | R8: 火焰减抗% | S8: 2 | T8: 0.2 | U8: 暴击率增幅 | V8: 2 | W8: 0 | X8: 刷新次数 | Y8: 1 | Z8: 0 | AA8: ="1:"&IF(I8<>"",VLOOKUP(I8,$BE$8:$BH$260,3,FALSE)&","&VLOOKUP(I8,$BE$8:$BH$260,4,FALSE)*(1-K8)*J8&","&VLOOKUP(I8,$BE$8:$BH$260,4,FALSE)*(1+K8)*J8&",","xxx")&IF(L8<>"",VLOOKUP(L8,$BE$8:$BH$260,3,FALSE)&","&VLOOKUP(L8,$BE$8:$BH$260,4,FALSE)*(1-N8)*M8&","&VLOOKUP(L8,$BE$8:$BH$260,4,FALSE)*(1+N8)*M8&",","xxx")&IF(O8<>"",VLOOKUP(O8,$BE$8:$BH$260,3,FALSE)&","&VLOOKUP(O8,$BE$8:$BH$260,4,FALSE)*(1-Q8)*P8&","&VLOOKUP(O8,$BE$8:$BH$260,4,FALSE)*(1+Q8)*P8&",","xxx")&IF(R8<>"",VLOOKUP(R8,$BE$8:$BH$260,3,FALSE)&","&VLOOKUP(R8,$BE$8:$BH$260,4,FALSE)*(1-T8)*S8&","&VLOOKUP(R8,$BE$8:$BH$260,4,FALSE)*(1+T8)*S8&",","xxx")&IF(U8<>"",VLOOKUP(U8,$BE$8:$BH$260,3,FALSE)&","&VLOOKUP(U8,$BE$8:$BH$260,4,FALSE)*(1-W8)*V8&","&VLOOKUP(U8,$BE$8:$BH$260,4,FALSE)*(1+W8)*V8&",","xxx")&IF(X8<>"",VLOOKUP(X8,$BE$8:$BH$260,3,FALSE)&","&VLOOKUP(X8,$BE$8:$BH$260,4,FALSE)*(1-Z8)*Y8&","&VLOOKUP(X8,$BE$8:$BH$260,4,FALSE)*(1+Z8)*Y8&",","xxx") -> 1:207,16,24,103,16,24,214,16,24,223,8,12,257,20,20,501,2,2, | AB8: =D249 -> 马卡多的手杖 | AC8: =IF(J8>0,I8&" "&"{"&J$6&"}","xxx") -> 火焰伤害 {0} | AD8: =IF(M8>0,L8&" "&"{"&M$6&"}","xxx") -> 智力 {1} | AE8: =IF(P8>0,O8&" "&"{"&P$6&"}","xxx") -> 火焰伤害% {2} | AF8: =IF(S8>0,R8&" "&"{"&S$6&"}","xxx") -> 火焰减抗% {3} | AG8: =IF(V8>0,U8&" "&"{"&V$6&"}","xxx") -> 暴击率增幅 {4} | AH8: =IF(Y8>0,X8&" "&"{"&Y$6&"}","xxx") -> 刷新次数 {5} | AI8: =_xlfn.IFNA(IF(AC8="xxx","xxx",IF(VLOOKUP(I8,$BE$8:$BK$260,7,FALSE)=1,AC8&CHAR(10),SUBSTITUTE(AC8,"%","")&"%"&CHAR(10))),"xxx") -> 火焰伤害 {0} | AJ8: =_xlfn.IFNA(IF(AC8="xxx","xxx",IF(VLOOKUP(L8,$BE$8:$BK$260,7,FALSE)=1,AD8&CHAR(10),SUBSTITUTE(AD8,"%","")&"%"&CHAR(10))),"xxx") -> 智力 {1} | AK8: =_xlfn.IFNA(IF(AC8="xxx","xxx",IF(VLOOKUP(O8,$BE$8:$BK$260,7,FALSE)=1,AE8&CHAR(10),SUBSTITUTE(AE8,"%","")&"%"&CHAR(10))),"xxx") -> 火焰伤害 {2}% | AL8: =_xlfn.IFNA(IF(AC8="xxx","xxx",IF(VLOOKUP(R8,$BE$8:$BK$260,7,FALSE)=1,AF8&CHAR(10),SUBSTITUTE(AF8,"%","")&"%"&CHAR(10))),"xxx") -> 火焰减抗 {3}% | AM8: =_xlfn.IFNA(IF(AC8="xxx","xxx",IF(VLOOKUP(U8,$BE$8:$BK$260,7,FALSE)=1,AG8&CHAR(10),SUBSTITUTE(AG8,"%","")&"%"&CHAR(10))),"xxx") -> 暴击率增幅 {4}% | AN8: =_xlfn.IFNA(IF(AC8="xxx","xxx",IF(VLOOKUP(X8,$BE$8:$BK$260,7,FALSE)=1,AH8&CHAR(10),SUBSTITUTE(AH8,"%","")&"%"&CHAR(10))),"xxx") -> 刷新次数 {5} | AO8: =_xlfn.CONCAT(AI8:AN8) -> 火焰伤害 {0} 智力 {1} 火焰伤害 {2}% 火焰减抗 {3}% 暴击率增幅 {4}% 刷新次数 {5} | AP8: =SUBSTITUTE(AO8,"xxx","") -> 火焰伤害 {0} 智力 {1} 火焰伤害 {2}% 火焰减抗 {3}% 暴击率增幅 {4}% 刷新次数 {5} | AQ8: 火焰伤害提升（20%~30%） 灼烧对精英和首领的伤害提升（30%~50%） 每击杀一名灼烧中的敌人（25%~35%）概率回复1点生命 | AR8: =IFERROR(IF(AP8="",AQ8,AP8),AP8) -> 火焰伤害 {0} 智力 {1} 火焰伤害 {2}% 火焰减抗 {3}% 暴击率增幅 {4}% 刷新次数 {5} | AS8: =IF(AR8<>AQ8,IF(ISNUMBER(SEARCH(CHAR(10),AR8)),SUBSTITUTE(AR8,CHAR(10),"",LEN(AR8)-LEN(SUBSTITUTE(AR8,CHAR(10),""))),AR8),AR8) -> 火焰伤害 {0} 智力 {1} 火焰伤害 {2}% 火焰减抗 {3}% 暴击率增幅 {4}% 刷新次数 {5} | BE8: 力量 | BF8: 固定值 | BG8: 101 | BH8: 10 | BI8: =COUNTIF($I$8:$I$1040,BE8)/COUNT($C$8:$C$1040)+COUNTIF($L$8:$L$1040,BE8)/COUNT($C$8:$C$1040)+COUNTIF($O$8:$O$1040,BE8)/COUNT($C$8:$C$1040)+COUNTIF($R$8:$R$1040,BE8)/COUNT($C$8:$C$1040)+COUNTIF($U$8:$U$1040,BE8)/COUNT($C$8:$C$1040)+COUNTIF($X$8:$X$1040,BE8)/COUNT($C$8:$C$1040) -> 0.068627451 | BK8: 1
C9: 14695 | D9: 灰烬使者 | E9: 6 | F9: 法杖 | H9: 10 | I9: 火焰伤害% | J9: 4 | K9: 0.2 | L9: 火焰减抗% | M9: 2 | N9: 0.2 | O9: 施加灼烧时间提升 | P9: 1 | Q9: 0 | R9: 灼烧系数 | S9: 1 | T9: 0.5 | U9: 附加火焰伤害% | V9: 2 | W9: 0 | AA9: ="1:"&IF(I9<>"",VLOOKUP(I9,$BE$8:$BH$260,3,FALSE)&","&VLOOKUP(I9,$BE$8:$BH$260,4,FALSE)*(1-K9)*J9&","&VLOOKUP(I9,$BE$8:$BH$260,4,FALSE)*(1+K9)*J9&",","xxx")&IF(L9<>"",VLOOKUP(L9,$BE$8:$BH$260,3,FALSE)&","&VLOOKUP(L9,$BE$8:$BH$260,4,FALSE)*(1-N9)*M9&","&VLOOKUP(L9,$BE$8:$BH$260,4,FALSE)*(1+N9)*M9&",","xxx")&IF(O9<>"",VLOOKUP(O9,$BE$8:$BH$260,3,FALSE)&","&VLOOKUP(O9,$BE$8:$BH$260,4,FALSE)*(1-Q9)*P9&","&VLOOKUP(O9,$BE$8:$BH$260,4,FALSE)*(1+Q9)*P9&",","xxx")&IF(R9<>"",VLOOKUP(R9,$BE$8:$BH$260,3,FALSE)&","&VLOOKUP(R9,$BE$8:$BH$260,4,FALSE)*(1-T9)*S9&","&VLOOKUP(R9,$BE$8:$BH$260,4,FALSE)*(1+T9)*S9&",","xxx")&IF(U9<>"",VLOOKUP(U9,$BE$8:$BH$260,3,FALSE)&","&VLOOKUP(U9,$BE$8:$BH$260,4,FALSE)*(1-W9)*V9&","&VLOOKUP(U9,$BE$8:$BH$260,4,FALSE)*(1+W9)*V9&",","xxx")&IF(X9<>"",VLOOKUP(X9,$BE$8:$BH$260,3,FALSE)&","&VLOOKUP(X9,$BE$8:$BH$260,4,FALSE)*(1-Z9)*Y9&","&VLOOKUP(X9,$BE$8:$BH$260,4,FALSE)*(1+Z9)*Y9&",","xxx") -> 1:214,32,48,223,8,12,251,10,10,241,5,15,237,20,20,xxx | AB9: =IF(LEFT(SUBSTITUTE(AA9,"x",""),LEN(SUBSTITUTE(AA9,"x",""))-1)="1","",LEFT(SUBSTITUTE(AA9,"x",""),LEN(SUBSTITUTE(AA9,"x",""))-1)) -> 1:214,32,48,223,8,12,251,10,10,241,5,15,237,20,20 | AC9: =IF(J9>0,I9&" "&"{"&J$6&"}","xxx") -> 火焰伤害% {0} | AD9: =IF(M9>0,L9&" "&"{"&M$6&"}","xxx") -> 火焰减抗% {1} | AE9: =IF(P9>0,O9&" "&"{"&P$6&"}","xxx") -> 施加灼烧时间提升 {2} | AF9: =IF(S9>0,R9&" "&"{"&S$6&"}","xxx") -> 灼烧系数 {3} | AG9: =IF(V9>0,U9&" "&"{"&V$6&"}","xxx") -> 附加火焰伤害% {4} | AH9: =IF(Y9>0,X9&" "&"{"&Y$6&"}","xxx") -> xxx | AI9: =_xlfn.IFNA(IF(AC9="xxx","xxx",IF(VLOOKUP(I9,$BE$8:$BK$260,7,FALSE)=1,AC9&CHAR(10),SUBSTITUTE(AC9,"%","")&"%"&CHAR(10))),"xxx") -> 火焰伤害 {0}% | AJ9: =_xlfn.IFNA(IF(AC9="xxx","xxx",IF(VLOOKUP(L9,$BE$8:$BK$260,7,FALSE)=1,AD9&CHAR(10),SUBSTITUTE(AD9,"%","")&"%"&CHAR(10))),"xxx") -> 火焰减抗 {1}% | AK9: =_xlfn.IFNA(IF(AC9="xxx","xxx",IF(VLOOKUP(O9,$BE$8:$BK$260,7,FALSE)=1,AE9&CHAR(10),SUBSTITUTE(AE9,"%","")&"%"&CHAR(10))),"xxx") -> 施加灼烧时间提升 {2}% | AL9: =_xlfn.IFNA(IF(AC9="xxx","xxx",IF(VLOOKUP(R9,$BE$8:$BK$260,7,FALSE)=1,AF9&CHAR(10),SUBSTITUTE(AF9,"%","")&"%"&CHAR(10))),"xxx") -> 灼烧系数 {3}% | AM9: =_xlfn.IFNA(IF(AC9="xxx","xxx",IF(VLOOKUP(U9,$BE$8:$BK$260,7,FALSE)=1,AG9&CHAR(10),SUBSTITUTE(AG9,"%","")&"%"&CHAR(10))),"xxx") -> 附加火焰伤害 {4}% | AN9: =_xlfn.IFNA(IF(AC9="xxx","xxx",IF(VLOOKUP(X9,$BE$8:$BK$260,7,FALSE)=1,AH9&CHAR(10),SUBSTITUTE(AH9,"%","")&"%"&CHAR(10))),"xxx") -> xxx | AO9: =_xlfn.CONCAT(AI9:AN9) -> 火焰伤害 {0}% 火焰减抗 {1}% 施加灼烧时间提升 {2}% 灼烧系数 {3}% 附加火焰伤害 {4}% xxx | AP9: =SUBSTITUTE(AO9,"xxx","") -> 火焰伤害 {0}% 火焰减抗 {1}% 施加灼烧时间提升 {2}% 灼烧系数 {3}% 附加火焰伤害 {4}% | AQ9: 智力+（10~20） 对灼烧中的敌人伤害提高（15%~30%） 击杀灼烧中的敌人时有（25%~35%）的几率触发 3 级的【召唤灰烬之灵】 | AR9: =IFERROR(IF(AP9="",AQ9,AP9),AP9) -> 火焰伤害 {0}% 火焰减抗 {1}% 施加灼烧时间提升 {2}% 灼烧系数 {3}% 附加火焰伤害 {4}% | AS9: =IF(AR9<>AQ9,IF(ISNUMBER(SEARCH(CHAR(10),AR9)),SUBSTITUTE(AR9,CHAR(10),"",LEN(AR9)-LEN(SUBSTITUTE(AR9,CHAR(10),""))),AR9),AR9) -> 火焰伤害 {0}% 火焰减抗 {1}% 施加灼烧时间提升 {2}% 灼烧系数 {3}% 附加火焰伤害 {4}% | BE9: 敏捷 | BF9: 固定值 | BG9: 102 | BH9: 10 | BI9: =COUNTIF($I$8:$I$1040,BE9)/COUNT($C$8:$C$1040)+COUNTIF($L$8:$L$1040,BE9)/COUNT($C$8:$C$1040)+COUNTIF($O$8:$O$1040,BE9)/COUNT($C$8:$C$1040)+COUNTIF($R$8:$R$1040,BE9)/COUNT($C$8:$C$1040)+COUNTIF($U$8:$U$1040,BE9)/COUNT($C$8:$C$1040)+COUNTIF($X$8:$X$1040,BE9)/COUNT($C$8:$C$1040) -> 0.071895425 | BK9: 1
C10: 14696 | D10: 时间之杖 | E10: -1 | F10: 法杖 | H10: 0 | AA10: ="1:"&IF(I10<>"",VLOOKUP(I10,$BE$8:$BH$260,3,FALSE)&","&VLOOKUP(I10,$BE$8:$BH$260,4,FALSE)*(1-K10)*J10&","&VLOOKUP(I10,$BE$8:$BH$260,4,FALSE)*(1+K10)*J10&",","xxx")&IF(L10<>"",VLOOKUP(L10,$BE$8:$BH$260,3,FALSE)&","&VLOOKUP(L10,$BE$8:$BH$260,4,FALSE)*(1-N10)*M10&","&VLOOKUP(L10,$BE$8:$BH$260,4,FALSE)*(1+N10)*M10&",","xxx")&IF(O10<>"",VLOOKUP(O10,$BE$8:$BH$260,3,FALSE)&","&VLOOKUP(O10,$BE$8:$BH$260,4,FALSE)*(1-Q10)*P10&","&VLOOKUP(O10,$BE$8:$BH$260,4,FALSE)*(1+Q10)*P10&",","xxx")&IF(R10<>"",VLOOKUP(R10,$BE$8:$BH$260,3,FALSE)&","&VLOOKUP(R10,$BE$8:$BH$260,4,FALSE)*(1-T10)*S10&","&VLOOKUP(R10,$BE$8:$BH$260,4,FALSE)*(1+T10)*S10&",","xxx")&IF(U10<>"",VLOOKUP(U10,$BE$8:$BH$260,3,FALSE)&","&VLOOKUP(U10,$BE$8:$BH$260,4,FALSE)*(1-W10)*V10&","&VLOOKUP(U10,$BE$8:$BH$260,4,FALSE)*(1+W10)*V10&",","xxx")&IF(X10<>"",VLOOKUP(X10,$BE$8:$BH$260,3,FALSE)&","&VLOOKUP(X10,$BE$8:$BH$260,4,FALSE)*(1-Z10)*Y10&","&VLOOKUP(X10,$BE$8:$BH$260,4,FALSE)*(1+Z10)*Y10&",","xxx") -> 1:xxxxxxxxxxxxxxxxxx | AB10: =IF(LEFT(SUBSTITUTE(AA10,"x",""),LEN(SUBSTITUTE(AA10,"x",""))-1)="1","",LEFT(SUBSTITUTE(AA10,"x",""),LEN(SUBSTITUTE(AA10,"x",""))-1)) | AC10: =IF(J10>0,I10&" "&"{"&J$6&"}","xxx") -> xxx | AD10: =IF(M10>0,L10&" "&"{"&M$6&"}","xxx") -> xxx | AE10: =IF(P10>0,O10&" "&"{"&P$6&"}","xxx") -> xxx | AF10: =IF(S10>0,R10&" "&"{"&S$6&"}","xxx") -> xxx | AG10: =IF(V10>0,U10&" "&"{"&V$6&"}","xxx") -> xxx | AH10: =IF(Y10>0,X10&" "&"{"&Y$6&"}","xxx") -> xxx | AI10: =_xlfn.IFNA(IF(AC10="xxx","xxx",IF(VLOOKUP(I10,$BE$8:$BK$260,7,FALSE)=1,AC10&CHAR(10),SUBSTITUTE(AC10,"%","")&"%"&CHAR(10))),"xxx") -> xxx | AJ10: =_xlfn.IFNA(IF(AC10="xxx","xxx",IF(VLOOKUP(L10,$BE$8:$BK$260,7,FALSE)=1,AD10&CHAR(10),SUBSTITUTE(AD10,"%","")&"%"&CHAR(10))),"xxx") -> xxx | AK10: =_xlfn.IFNA(IF(AC10="xxx","xxx",IF(VLOOKUP(O10,$BE$8:$BK$260,7,FALSE)=1,AE10&CHAR(10),SUBSTITUTE(AE10,"%","")&"%"&CHAR(10))),"xxx") -> xxx | AL10: =_xlfn.IFNA(IF(AC10="xxx","xxx",IF(VLOOKUP(R10,$BE$8:$BK$260,7,FALSE)=1,AF10&CHAR(10),SUBSTITUTE(AF10,"%","")&"%"&CHAR(10))),"xxx") -> xxx | AM10: =_xlfn.IFNA(IF(AC10="xxx","xxx",IF(VLOOKUP(U10,$BE$8:$BK$260,7,FALSE)=1,AG10&CHAR(10),SUBSTITUTE(AG10,"%","")&"%"&CHAR(10))),"xxx") -> xxx | AN10: =_xlfn.IFNA(IF(AC10="xxx","xxx",IF(VLOOKUP(X10,$BE$8:$BK$260,7,FALSE)=1,AH10&CHAR(10),SUBSTITUTE(AH10,"%","")&"%"&CHAR(10))),"xxx") -> xxx | AO10: =_xlfn.CONCAT(AI10:AN10) -> xxxxxxxxxxxxxxxxxx | AP10: =SUBSTITUTE(AO10,"xxx","") | AQ10: 元素伤害提高 +{0}% 技能冷却缩减 {1}% 技能范围 +{2}% | AR10: =IFERROR(IF(AP10="",AQ10,AP10),AP10) -> 元素伤害提高 +{0}% 技能冷却缩减 {1}% 技能范围 +{2}% | AS10: =IF(AR10<>AQ10,IF(ISNUMBER(SEARCH(CHAR(10),AR10)),SUBSTITUTE(AR10,CHAR(10),"",LEN(AR10)-LEN(SUBSTITUTE(AR10,CHAR(10),""))),AR10),AR10) -> 元素伤害提高 +{0}% 技能冷却缩减 {1}% 技能范围 +{2}% | BE10: 智力 | BF10: 固定值 | BG10: 103 | BH10: 10 | BI10: =COUNTIF($I$8:$I$1040,BE10)/COUNT($C$8:$C$1040)+COUNTIF($L$8:$L$1040,BE10)/COUNT($C$8:$C$1040)+COUNTIF($O$8:$O$1040,BE10)/COUNT($C$8:$C$1040)+COUNTIF($R$8:$R$1040,BE10)/COUNT($C$8:$C$1040)+COUNTIF($U$8:$U$1040,BE10)/COUNT($C$8:$C$1040)+COUNTIF($X$8:$X$1040,BE10)/COUNT($C$8:$C$1040) -> 0.081699346 | BK10: 1
C11: 14697 | D11: 骸骨主宰 | E11: 1 | F11: 法杖 | H11: 11 | I11: 召唤物物理伤害% | J11: 3 | K11: 0.2 | L11: 召唤物生命值% | M11: 3 | N11: 0.2 | O11: 召唤物暴击几率% | P11: 2 | Q11: 0.2 | R11: 召唤物暴击伤害% | S11: 2 | T11: 0.2 | U11: 召唤物物理抗性% | V11: 1 | AA11: ="1:"&IF(I11<>"",VLOOKUP(I11,$BE$8:$BH$260,3,FALSE)&","&VLOOKUP(I11,$BE$8:$BH$260,4,FALSE)*(1-K11)*J11&","&VLOOKUP(I11,$BE$8:$BH$260,4,FALSE)*(1+K11)*J11&",","xxx")&IF(L11<>"",VLOOKUP(L11,$BE$8:$BH$260,3,FALSE)&","&VLOOKUP(L11,$BE$8:$BH$260,4,FALSE)*(1-N11)*M11&","&VLOOKUP(L11,$BE$8:$BH$260,4,FALSE)*(1+N11)*M11&",","xxx")&IF(O11<>"",VLOOKUP(O11,$BE$8:$BH$260,3,FALSE)&","&VLOOKUP(O11,$BE$8:$BH$260,4,FALSE)*(1-Q11)*P11&","&VLOOKUP(O11,$BE$8:$BH$260,4,FALSE)*(1+Q11)*P11&",","xxx")&IF(R11<>"",VLOOKUP(R11,$BE$8:$BH$260,3,FALSE)&","&VLOOKUP(R11,$BE$8:$BH$260,4,FALSE)*(1-T11)*S11&","&VLOOKUP(R11,$BE$8:$BH$260,4,FALSE)*(1+T11)*S11&",","xxx")&IF(U11<>"",VLOOKUP(U11,$BE$8:$BH$260,3,FALSE)&","&VLOOKUP(U11,$BE$8:$BH$260,4,FALSE)*(1-W11)*V11&","&VLOOKUP(U11,$BE$8:$BH$260,4,FALSE)*(1+W11)*V11&",","xxx")&IF(X11<>"",VLOOKUP(X11,$BE$8:$BH$260,3,FALSE)&","&VLOOKUP(X11,$BE$8:$BH$260,4,FALSE)*(1-Z11)*Y11&","&VLOOKUP(X11,$BE$8:$BH$260,4,FALSE)*(1+Z11)*Y11&",","xxx") -> 1:705,48,72,702,24,36,716,8,12,717,16,24,714,10,10,xxx | AB11: =IF(LEFT(SUBSTITUTE(AA11,"x",""),LEN(SUBSTITUTE(AA11,"x",""))-1)="1","",LEFT(SUBSTITUTE(AA11,"x",""),LEN(SUBSTITUTE(AA11,"x",""))-1)) -> 1:705,48,72,702,24,36,716,8,12,717,16,24,714,10,10 | AC11: =IF(J11>0,I11&" "&"{"&J$6&"}","xxx") -> 召唤物物理伤害% {0} | AD11: =IF(M11>0,L11&" "&"{"&M$6&"}","xxx") -> 召唤物生命值% {1} | AE11: =IF(P11>0,O11&" "&"{"&P$6&"}","xxx") -> 召唤物暴击几率% {2} | AF11: =IF(S11>0,R11&" "&"{"&S$6&"}","xxx") -> 召唤物暴击伤害% {3} | AG11: =IF(V11>0,U11&" "&"{"&V$6&"}","xxx") -> 召唤物物理抗性% {4} | AH11: =IF(Y11>0,X11&" "&"{"&Y$6&"}","xxx") -> xxx | AI11: =_xlfn.IFNA(IF(AC11="xxx","xxx",IF(VLOOKUP(I11,$BE$8:$BK$260,7,FALSE)=1,AC11&CHAR(10),SUBSTITUTE(AC11,"%","")&"%"&CHAR(10))),"xxx") -> 召唤物物理伤害 {0}% | AJ11: =_xlfn.IFNA(IF(AC11="xxx","xxx",IF(VLOOKUP(L11,$BE$8:$BK$260,7,FALSE)=1,AD11&CHAR(10),SUBSTITUTE(AD11,"%","")&"%"&CHAR(10))),"xxx") -> 召唤物生命值 {1}% | AK11: =_xlfn.IFNA(IF(AC11="xxx","xxx",IF(VLOOKUP(O11,$BE$8:$BK$260,7,FALSE)=1,AE11&CHAR(10),SUBSTITUTE(AE11,"%","")&"%"&CHAR(10))),"xxx") -> 召唤物暴击几率 {2}% | AL11: =_xlfn.IFNA(IF(AC11="xxx","xxx",IF(VLOOKUP(R11,$BE$8:$BK$260,7,FALSE)=1,AF11&CHAR(10),SUBSTITUTE(AF11,"%","")&"%"&CHAR(10))),"xxx") -> 召唤物暴击伤害 {3}% | AM11: =_xlfn.IFNA(IF(AC11="xxx","xxx",IF(VLOOKUP(U11,$BE$8:$BK$260,7,FALSE)=1,AG11&CHAR(10),SUBSTITUTE(AG11,"%","")&"%"&CHAR(10))),"xxx") -> 召唤物物理抗性 {4}% | AN11: =_xlfn.IFNA(IF(AC11="xxx","xxx",IF(VLOOKUP(X11,$BE$8:$BK$260,7,FALSE)=1,AH11&CHAR(10),SUBSTITUTE(AH11,"%","")&"%"&CHAR(10))),"xxx") -> xxx | AO11: =_xlfn.CONCAT(AI11:AN11) -> 召唤物物理伤害 {0}% 召唤物生命值 {1}% 召唤物暴击几率 {2}% 召唤物暴击伤害 {3}% 召唤物物理抗性 {4}% xxx | AP11: =SUBSTITUTE(AO11,"xxx","") -> 召唤物物理伤害 {0}% 召唤物生命值 {1}% 召唤物暴击几率 {2}% 召唤物暴击伤害 {3}% 召唤物物理抗性 {4}% | AQ11: 骷髅伤害+（30%~45%） 骷髅移动速度+（30%~45%） 骷髅上限+1 | AR11: =IFERROR(IF(AP11="",AQ11,AP11),AP11) -> 召唤物物理伤害 {0}% 召唤物生命值 {1}% 召唤物暴击几率 {2}% 召唤物暴击伤害 {3}% 召唤物物理抗性 {4}% | AS11: =IF(AR11<>AQ11,IF(ISNUMBER(SEARCH(CHAR(10),AR11)),SUBSTITUTE(AR11,CHAR(10),"",LEN(AR11)-LEN(SUBSTITUTE(AR11,CHAR(10),""))),AR11),AR11) -> 召唤物物理伤害 {0}% 召唤物生命值 {1}% 召唤物暴击几率 {2}% 召唤物暴击伤害 {3}% 召唤物物理抗性 {4}% | BE11: 幸运 | BF11: 固定值 | BG11: 104 | BH11: 10 | BI11: =COUNTIF($I$8:$I$1040,BE11)/COUNT($C$8:$C$1040)+COUNTIF($L$8:$L$1040,BE11)/COUNT($C$8:$C$1040)+COUNTIF($O$8:$O$1040,BE11)/COUNT($C$8:$C$1040)+COUNTIF($R$8:$R$1040,BE11)/COUNT($C$8:$C$1040)+COUNTIF($U$8:$U$1040,BE11)/COUNT($C$8:$C$1040)+COUNTIF($X$8:$X$1040,BE11)/COUNT($C$8:$C$1040) -> 0.029411765 | BK11: 1
C12: 14698 | D12: 瘟毒之杖 | E12: 6 | F12: 法杖 | H12: 11 | I12: 附加混沌伤害 | J12: 3 | K12: 0.2 | L12: 施加中毒时间提升 | M12: 3 | N12: 0 | O12: 冷却缩减% | P12: 2 | Q12: 0 | R12: 混沌伤害 | S12: 3 | T12: 0.2 | AA12: ="1:"&IF(I12<>"",VLOOKUP(I12,$BE$8:$BH$260,3,FALSE)&","&VLOOKUP(I12,$BE$8:$BH$260,4,FALSE)*(1-K12)*J12&","&VLOOKUP(I12,$BE$8:$BH$260,4,FALSE)*(1+K12)*J12&",","xxx")&IF(L12<>"",VLOOKUP(L12,$BE$8:$BH$260,3,FALSE)&","&VLOOKUP(L12,$BE$8:$BH$260,4,FALSE)*(1-N12)*M12&","&VLOOKUP(L12,$BE$8:$BH$260,4,FALSE)*(1+N12)*M12&",","xxx")&IF(O12<>"",VLOOKUP(O12,$BE$8:$BH$260,3,FALSE)&","&VLOOKUP(O12,$BE$8:$BH$260,4,FALSE)*(1-Q12)*P12&","&VLOOKUP(O12,$BE$8:$BH$260,4,FALSE)*(1+Q12)*P12&",","xxx")&IF(R12<>"",VLOOKUP(R12,$BE$8:$BH$260,3,FALSE)&","&VLOOKUP(R12,$BE$8:$BH$260,4,FALSE)*(1-T12)*S12&","&VLOOKUP(R12,$BE$8:$BH$260,4,FALSE)*(1+T12)*S12&",","xxx")&IF(U12<>"",VLOOKUP(U12,$BE$8:$BH$260,3,FALSE)&","&VLOOKUP(U12,$BE$8:$BH$260,4,FALSE)*(1-W12)*V12&","&VLOOKUP(U12,$BE$8:$BH$260,4,FALSE)*(1+W12)*V12&",","xxx")&IF(X12<>"",VLOOKUP(X12,$BE$8:$BH$260,3,FALSE)&","&VLOOKUP(X12,$BE$8:$BH$260,4,FALSE)*(1-Z12)*Y12&","&VLOOKUP(X12,$BE$8:$BH$260,4,FALSE)*(1+Z12)*Y12&",","xxx") -> 1:232,24,36,250,30,30,409,10,10,209,24,36,xxxxxx | AB12: =IF(LEFT(SUBSTITUTE(AA12,"x",""),LEN(SUBSTITUTE(AA12,"x",""))-1)="1","",LEFT(SUBSTITUTE(AA12,"x",""),LEN(SUBSTITUTE(AA12,"x",""))-1)) -> 1:232,24,36,250,30,30,409,10,10,209,24,36 | AC12: =IF(J12>0,I12&" "&"{"&J$6&"}","xxx") -> 附加混沌伤害 {0} | AD12: =IF(M12>0,L12&" "&"{"&M$6&"}","xxx") -> 施加中毒时间提升 {1} | AE12: =IF(P12>0,O12&" "&"{"&P$6&"}","xxx") -> 冷却缩减% {2} | AF12: =IF(S12>0,R12&" "&"{"&S$6&"}","xxx") -> 混沌伤害 {3} | AG12: =IF(V12>0,U12&" "&"{"&V$6&"}","xxx") -> xxx | AH12: =IF(Y12>0,X12&" "&"{"&Y$6&"}","xxx") -> xxx | AI12: =_xlfn.IFNA(IF(AC12="xxx","xxx",IF(VLOOKUP(I12,$BE$8:$BK$260,7,FALSE)=1,AC12&CHAR(10),SUBSTITUTE(AC12,"%","")&"%"&CHAR(10))),"xxx") -> 附加混沌伤害 {0}% | AJ12: =_xlfn.IFNA(IF(AC12="xxx","xxx",IF(VLOOKUP(L12,$BE$8:$BK$260,7,FALSE)=1,AD12&CHAR(10),SUBSTITUTE(AD12,"%","")&"%"&CHAR(10))),"xxx") -> 施加中毒时间提升 {1}% | AK12: =_xlfn.IFNA(IF(AC12="xxx","xxx",IF(VLOOKUP(O12,$BE$8:$BK$260,7,FALSE)=1,AE12&CHAR(10),SUBSTITUTE(AE12,"%","")&"%"&CHAR(10))),"xxx") -> 冷却缩减 {2}% | AL12: =_xlfn.IFNA(IF(AC12="xxx","xxx",IF(VLOOKUP(R12,$BE$8:$BK$260,7,FALSE)=1,AF12&CHAR(10),SUBSTITUTE(AF12,"%","")&"%"&CHAR(10))),"xxx") -> 混沌伤害 {3} | AM12: =_xlfn.IFNA(IF(AC12="xxx","xxx",IF(VLOOKUP(U12,$BE$8:$BK$260,7,FALSE)=1,AG12&CHAR(10),SUBSTITUTE(AG12,"%","")&"%"&CHAR(10))),"xxx") -> xxx | AN12: =_xlfn.IFNA(IF(AC12="xxx","xxx",IF(VLOOKUP(X12,$BE$8:$BK$260,7,FALSE)=1,AH12&CHAR(10),SUBSTITUTE(AH12,"%","")&"%"&CHAR(10))),"xxx") -> xxx | AO12: =_xlfn.CONCAT(AI12:AN12) -> 附加混沌伤害 {0}% 施加中毒时间提升 {1}% 冷却缩减 {2}% 混沌伤害 {3} xxxxxx | AP12: =SUBSTITUTE(AO12,"xxx","") -> 附加混沌伤害 {0}% 施加中毒时间提升 {1}% 冷却缩减 {2}% 混沌伤害 {3} | AQ12: 混沌伤害提高（20%~30%） 中毒的持续时间+（20%~30%） 对中毒状态的敌人伤害提高（15%~25%） | AR12: =IFERROR(IF(AP12="",AQ12,AP12),AP12) -> 附加混沌伤害 {0}% 施加中毒时间提升 {1}% 冷却缩减 {2}% 混沌伤害 {3} | AS12: =IF(AR12<>AQ12,IF(ISNUMBER(SEARCH(CHAR(10),AR12)),SUBSTITUTE(AR12,CHAR(10),"",LEN(AR12)-LEN(SUBSTITUTE(AR12,CHAR(10),""))),AR12),AR12) -> 附加混沌伤害 {0}% 施加中毒时间提升 {1}% 冷却缩减 {2}% 混沌伤害 {3} | BE12: 攻击力 | BF12: 固定值 | BG12: 201 | BH12: 5 | BI12: =COUNTIF($I$8:$I$1040,BE12)/COUNT($C$8:$C$1040)+COUNTIF($L$8:$L$1040,BE12)/COUNT($C$8:$C$1040)+COUNTIF($O$8:$O$1040,BE12)/COUNT($C$8:$C$1040)+COUNTIF($R$8:$R$1040,BE12)/COUNT($C$8:$C$1040)+COUNTIF($U$8:$U$1040,BE12)/COUNT($C$8:$C$1040)+COUNTIF($X$8:$X$1040,BE12)/COUNT($C$8:$C$1040) -> 0.029411765 | BK12: 1
C13: 14699 | D13: 混沌挽歌 | E13: 3 | F13: 法杖 | H13: 12 | I13: 混沌伤害% | J13: 5 | K13: 0.2 | L13: 混沌减抗% | M13: 2 | N13: 0.2 | O13: 附加混沌伤害% | P13: 3 | Q13: 0.2 | R13: 区域技能范围% | S13: 2 | T13: 0.2 | AA13: ="1:"&IF(I13<>"",VLOOKUP(I13,$BE$8:$BH$260,3,FALSE)&","&VLOOKUP(I13,$BE$8:$BH$260,4,FALSE)*(1-K13)*J13&","&VLOOKUP(I13,$BE$8:$BH$260,4,FALSE)*(1+K13)*J13&",","xxx")&IF(L13<>"",VLOOKUP(L13,$BE$8:$BH$260,3,FALSE)&","&VLOOKUP(L13,$BE$8:$BH$260,4,FALSE)*(1-N13)*M13&","&VLOOKUP(L13,$BE$8:$BH$260,4,FALSE)*(1+N13)*M13&",","xxx")&IF(O13<>"",VLOOKUP(O13,$BE$8:$BH$260,3,FALSE)&","&VLOOKUP(O13,$BE$8:$BH$260,4,FALSE)*(1-Q13)*P13&","&VLOOKUP(O13,$BE$8:$BH$260,4,FALSE)*(1+Q13)*P13&",","xxx")&IF(R13<>"",VLOOKUP(R13,$BE$8:$BH$260,3,FALSE)&","&VLOOKUP(R13,$BE$8:$BH$260,4,FALSE)*(1-T13)*S13&","&VLOOKUP(R13,$BE$8:$BH$260,4,FALSE)*(1+T13)*S13&",","xxx")&IF(U13<>"",VLOOKUP(U13,$BE$8:$BH$260,3,FALSE)&","&VLOOKUP(U13,$BE$8:$BH$260,4,FALSE)*(1-W13)*V13&","&VLOOKUP(U13,$BE$8:$BH$260,4,FALSE)*(1+W13)*V13&",","xxx")&IF(X13<>"",VLOOKUP(X13,$BE$8:$BH$260,3,FALSE)&","&VLOOKUP(X13,$BE$8:$BH$260,4,FALSE)*(1-Z13)*Y13&","&VLOOKUP(X13,$BE$8:$BH$260,4,FALSE)*(1+Z13)*Y13&",","xxx") -> 1:216,40,60,225,8,12,239,24,36,432,16,24,xxxxxx | AB13: =IF(LEFT(SUBSTITUTE(AA13,"x",""),LEN(SUBSTITUTE(AA13,"x",""))-1)="1","",LEFT(SUBSTITUTE(AA13,"x",""),LEN(SUBSTITUTE(AA13,"x",""))-1)) -> 1:216,40,60,225,8,12,239,24,36,432,16,24 | AC13: =IF(J13>0,I13&" "&"{"&J$6&"}","xxx") -> 混沌伤害% {0} | AD13: =IF(M13>0,L13&" "&"{"&M$6&"}","xxx") -> 混沌减抗% {1} | AE13: =IF(P13>0,O13&" "&"{"&P$6&"}","xxx") -> 附加混沌伤害% {2} | AF13: =IF(S13>0,R13&" "&"{"&S$6&"}","xxx") -> 区域技能范围% {3} | AG13: =IF(V13>0,U13&" "&"{"&V$6&"}","xxx") -> xxx | AH13: =IF(Y13>0,X13&" "&"{"&Y$6&"}","xxx") -> xxx | AI13: =_xlfn.IFNA(IF(AC13="xxx","xxx",IF(VLOOKUP(I13,$BE$8:$BK$260,7,FALSE)=1,AC13&CHAR(10),SUBSTITUTE(AC13,"%","")&"%"&CHAR(10))),"xxx") -> 混沌伤害 {0}% | AJ13: =_xlfn.IFNA(IF(AC13="xxx","xxx",IF(VLOOKUP(L13,$BE$8:$BK$260,7,FALSE)=1,AD13&CHAR(10),SUBSTITUTE(AD13,"%","")&"%"&CHAR(10))),"xxx") -> 混沌减抗 {1}% | AK13: =_xlfn.IFNA(IF(AC13="xxx","xxx",IF(VLOOKUP(O13,$BE$8:$BK$260,7,FALSE)=1,AE13&CHAR(10),SUBSTITUTE(AE13,"%","")&"%"&CHAR(10))),"xxx") -> 附加混沌伤害 {2}% | AL13: =_xlfn.IFNA(IF(AC13="xxx","xxx",IF(VLOOKUP(R13,$BE$8:$BK$260,7,FALSE)=1,AF13&CHAR(10),SUBSTITUTE(AF13,"%","")&"%"&CHAR(10))),"xxx") -> 区域技能范围 {3}% | AM13: =_xlfn.IFNA(IF(AC13="xxx","xxx",IF(VLOOKUP(U13,$BE$8:$BK$260,7,FALSE)=1,AG13&CHAR(10),SUBSTITUTE(AG13,"%","")&"%"&CHAR(10))),"xxx") -> xxx | AN13: =_xlfn.IFNA(IF(AC13="xxx","xxx",IF(VLOOKUP(X13,$BE$8:$BK$260,7,FALSE)=1,AH13&CHAR(10),SUBSTITUTE(AH13,"%","")&"%"&CHAR(10))),"xxx") -> xxx | AO13: =_xlfn.CONCAT(AI13:AN13) -> 混沌伤害 {0}% 混沌减抗 {1}% 附加混沌伤害 {2}% 区域技能范围 {3}% xxxxxx | AP13: =SUBSTITUTE(AO13,"xxx","") -> 混沌伤害 {0}% 混沌减抗 {1}% 附加混沌伤害 {2}% 区域技能范围 {3}% | AQ13: 火焰伤害 + {1} 智力 + {2} 火焰伤害 + {3}% 火焰减抗 + {4}% 暴击率增幅 + 20% 刷新次数 + 2 | AR13: =IFERROR(IF(AP13="",AQ13,AP13),AP13) -> 混沌伤害 {0}% 混沌减抗 {1}% 附加混沌伤害 {2}% 区域技能范围 {3}% | AS13: =IF(AR13<>AQ13,IF(ISNUMBER(SEARCH(CHAR(10),AR13)),SUBSTITUTE(AR13,CHAR(10),"",LEN(AR13)-LEN(SUBSTITUTE(AR13,CHAR(10),""))),AR13),AR13) -> 混沌伤害 {0}% 混沌减抗 {1}% 附加混沌伤害 {2}% 区域技能范围 {3}% | BE13: 所有伤害增加% | BF13: 百分比 | BG13: 202 | BH13: 10 | BI13: =COUNTIF($I$8:$I$1040,BE13)/COUNT($C$8:$C$1040)+COUNTIF($L$8:$L$1040,BE13)/COUNT($C$8:$C$1040)+COUNTIF($O$8:$O$1040,BE13)/COUNT($C$8:$C$1040)+COUNTIF($R$8:$R$1040,BE13)/COUNT($C$8:$C$1040)+COUNTIF($U$8:$U$1040,BE13)/COUNT($C$8:$C$1040)+COUNTIF($X$8:$X$1040,BE13)/COUNT($C$8:$C$1040) -> 0.035947712 | BK13: 2
C14: 14700 | D14: 群星之怒 | E14: 2 | F14: 法杖 | H14: 0 | AA14: ="1:"&IF(I14<>"",VLOOKUP(I14,$BE$8:$BH$260,3,FALSE)&","&VLOOKUP(I14,$BE$8:$BH$260,4,FALSE)*(1-K14)*J14&","&VLOOKUP(I14,$BE$8:$BH$260,4,FALSE)*(1+K14)*J14&",","xxx")&IF(L14<>"",VLOOKUP(L14,$BE$8:$BH$260,3,FALSE)&","&VLOOKUP(L14,$BE$8:$BH$260,4,FALSE)*(1-N14)*M14&","&VLOOKUP(L14,$BE$8:$BH$260,4,FALSE)*(1+N14)*M14&",","xxx")&IF(O14<>"",VLOOKUP(O14,$BE$8:$BH$260,3,FALSE)&","&VLOOKUP(O14,$BE$8:$BH$260,4,FALSE)*(1-Q14)*P14&","&VLOOKUP(O14,$BE$8:$BH$260,4,FALSE)*(1+Q14)*P14&",","xxx")&IF(R14<>"",VLOOKUP(R14,$BE$8:$BH$260,3,FALSE)&","&VLOOKUP(R14,$BE$8:$BH$260,4,FALSE)*(1-T14)*S14&","&VLOOKUP(R14,$BE$8:$BH$260,4,FALSE)*(1+T14)*S14&",","xxx")&IF(U14<>"",VLOOKUP(U14,$BE$8:$BH$260,3,FALSE)&","&VLOOKUP(U14,$BE$8:$BH$260,4,FALSE)*(1-W14)*V14&","&VLOOKUP(U14,$BE$8:$BH$260,4,FALSE)*(1+W14)*V14&",","xxx")&IF(X14<>"",VLOOKUP(X14,$BE$8:$BH$260,3,FALSE)&","&VLOOKUP(X14,$BE$8:$BH$260,4,FALSE)*(1-Z14)*Y14&","&VLOOKUP(X14,$BE$8:$BH$260,4,FALSE)*(1+Z14)*Y14&",","xxx") -> 1:xxxxxxxxxxxxxxxxxx | AB14: =IF(LEFT(SUBSTITUTE(AA14,"x",""),LEN(SUBSTITUTE(AA14,"x",""))-1)="1","",LEFT(SUBSTITUTE(AA14,"x",""),LEN(SUBSTITUTE(AA14,"x",""))-1)) | AC14: =IF(J14>0,I14&" "&"{"&J$6&"}","xxx") -> xxx | AD14: =IF(M14>0,L14&" "&"{"&M$6&"}","xxx") -> xxx | AE14: =IF(P14>0,O14&" "&"{"&P$6&"}","xxx") -> xxx | AF14: =IF(S14>0,R14&" "&"{"&S$6&"}","xxx") -> xxx | AG14: =IF(V14>0,U14&" "&"{"&V$6&"}","xxx") -> xxx | AH14: =IF(Y14>0,X14&" "&"{"&Y$6&"}","xxx") -> xxx | AI14: =_xlfn.IFNA(IF(AC14="xxx","xxx",IF(VLOOKUP(I14,$BE$8:$BK$260,7,FALSE)=1,AC14&CHAR(10),SUBSTITUTE(AC14,"%","")&"%"&CHAR(10))),"xxx") -> xxx | AJ14: =_xlfn.IFNA(IF(AC14="xxx","xxx",IF(VLOOKUP(L14,$BE$8:$BK$260,7,FALSE)=1,AD14&CHAR(10),SUBSTITUTE(AD14,"%","")&"%"&CHAR(10))),"xxx") -> xxx | AK14: =_xlfn.IFNA(IF(AC14="xxx","xxx",IF(VLOOKUP(O14,$BE$8:$BK$260,7,FALSE)=1,AE14&CHAR(10),SUBSTITUTE(AE14,"%","")&"%"&CHAR(10))),"xxx") -> xxx | AL14: =_xlfn.IFNA(IF(AC14="xxx","xxx",IF(VLOOKUP(R14,$BE$8:$BK$260,7,FALSE)=1,AF14&CHAR(10),SUBSTITUTE(AF14,"%","")&"%"&CHAR(10))),"xxx") -> xxx | AM14: =_xlfn.IFNA(IF(AC14="xxx","xxx",IF(VLOOKUP(U14,$BE$8:$BK$260,7,FALSE)=1,AG14&CHAR(10),SUBSTITUTE(AG14,"%","")&"%"&CHAR(10))),"xxx") -> xxx | AN14: =_xlfn.IFNA(IF(AC14="xxx","xxx",IF(VLOOKUP(X14,$BE$8:$BK$260,7,FALSE)=1,AH14&CHAR(10),SUBSTITUTE(AH14,"%","")&"%"&CHAR(10))),"xxx") -> xxx | AO14: =_xlfn.CONCAT(AI14:AN14) -> xxxxxxxxxxxxxxxxxx | AP14: =SUBSTITUTE(AO14,"xxx","") | AQ14: 投射物数量 +{0} 投射物大小 +{1}% 投射物穿透 +1 | AR14: =IFERROR(IF(AP14="",AQ14,AP14),AP14) -> 投射物数量 +{0} 投射物大小 +{1}% 投射物穿透 +1 | AS14: =IF(AR14<>AQ14,IF(ISNUMBER(SEARCH(CHAR(10),AR14)),SUBSTITUTE(AR14,CHAR(10),"",LEN(AR14)-LEN(SUBSTITUTE(AR14,CHAR(10),""))),AR14),AR14) -> 投射物数量 +{0} 投射物大小 +{1}% 投射物穿透 +1 | BE14: 额外伤害增加% | BF14: 百分比 | BG14: 203 | BH14: 10 | BI14: =COUNTIF($I$8:$I$1040,BE14)/COUNT($C$8:$C$1040)+COUNTIF($L$8:$L$1040,BE14)/COUNT($C$8:$C$1040)+COUNTIF($O$8:$O$1040,BE14)/COUNT($C$8:$C$1040)+COUNTIF($R$8:$R$1040,BE14)/COUNT($C$8:$C$1040)+COUNTIF($U$8:$U$1040,BE14)/COUNT($C$8:$C$1040)+COUNTIF($X$8:$X$1040,BE14)/COUNT($C$8:$C$1040) -> 0.016339869 | BK14: 2
C15: 14701 | D15: 冰魄之刃 | E15: 4 | F15: 单手剑 | H15: 7 | I15: 冰霜伤害 | J15: 2 | K15: 0.2 | L15: 冰霜伤害% | M15: 2 | N15: 0.2 | O15: 冰霜减抗% | P15: 1 | Q15: 0.2 | R15: 子弹数量 | S15: 2 | T15: 0 | AA15: ="1:"&IF(I15<>"",VLOOKUP(I15,$BE$8:$BH$260,3,FALSE)&","&VLOOKUP(I15,$BE$8:$BH$260,4,FALSE)*(1-K15)*J15&","&VLOOKUP(I15,$BE$8:$BH$260,4,FALSE)*(1+K15)*J15&",","xxx")&IF(L15<>"",VLOOKUP(L15,$BE$8:$BH$260,3,FALSE)&","&VLOOKUP(L15,$BE$8:$BH$260,4,FALSE)*(1-N15)*M15&","&VLOOKUP(L15,$BE$8:$BH$260,4,FALSE)*(1+N15)*M15&",","xxx")&IF(O15<>"",VLOOKUP(O15,$BE$8:$BH$260,3,FALSE)&","&VLOOKUP(O15,$BE$8:$BH$260,4,FALSE)*(1-Q15)*P15&","&VLOOKUP(O15,$BE$8:$BH$260,4,FALSE)*(1+Q15)*P15&",","xxx")&IF(R15<>"",VLOOKUP(R15,$BE$8:$BH$260,3,FALSE)&","&VLOOKUP(R15,$BE$8:$BH$260,4,FALSE)*(1-T15)*S15&","&VLOOKUP(R15,$BE$8:$BH$260,4,FALSE)*(1+T15)*S15&",","xxx")&IF(U15<>"",VLOOKUP(U15,$BE$8:$BH$260,3,FALSE)&","&VLOOKUP(U15,$BE$8:$BH$260,4,FALSE)*(1-W15)*V15&","&VLOOKUP(U15,$BE$8:$BH$260,4,FALSE)*(1+W15)*V15&",","xxx")&IF(X15<>"",VLOOKUP(X15,$BE$8:$BH$260,3,FALSE)&","&VLOOKUP(X15,$BE$8:$BH$260,4,FALSE)*(1-Z15)*Y15&","&VLOOKUP(X15,$BE$8:$BH$260,4,FALSE)*(1+Z15)*Y15&",","xxx") -> 1:206,16,24,213,16,24,222,4,6,404,1,1,xxxxxx | AB15: =IF(LEFT(SUBSTITUTE(AA15,"x",""),LEN(SUBSTITUTE(AA15,"x",""))-1)="1","",LEFT(SUBSTITUTE(AA15,"x",""),LEN(SUBSTITUTE(AA15,"x",""))-1)) -> 1:206,16,24,213,16,24,222,4,6,404,1,1 | AC15: =IF(J15>0,I15&" "&"{"&J$6&"}","xxx") -> 冰霜伤害 {0} | AD15: =IF(M15>0,L15&" "&"{"&M$6&"}","xxx") -> 冰霜伤害% {1} | AE15: =IF(P15>0,O15&" "&"{"&P$6&"}","xxx") -> 冰霜减抗% {2} | AF15: =IF(S15>0,R15&" "&"{"&S$6&"}","xxx") -> 子弹数量 {3} | AG15: =IF(V15>0,U15&" "&"{"&V$6&"}","xxx") -> xxx | AH15: =IF(Y15>0,X15&" "&"{"&Y$6&"}","xxx") -> xxx | AI15: =_xlfn.IFNA(IF(AC15="xxx","xxx",IF(VLOOKUP(I15,$BE$8:$BK$260,7,FALSE)=1,AC15&CHAR(10),SUBSTITUTE(AC15,"%","")&"%"&CHAR(10))),"xxx") -> 冰霜伤害 {0} | AJ15: =_xlfn.IFNA(IF(AC15="xxx","xxx",IF(VLOOKUP(L15,$BE$8:$BK$260,7,FALSE)=1,AD15&CHAR(10),SUBSTITUTE(AD15,"%","")&"%"&CHAR(10))),"xxx") -> 冰霜伤害 {1}% | AK15: =_xlfn.IFNA(IF(AC15="xxx","xxx",IF(VLOOKUP(O15,$BE$8:$BK$260,7,FALSE)=1,AE15&CHAR(10),SUBSTITUTE(AE15,"%","")&"%"&CHAR(10))),"xxx") -> 冰霜减抗 {2}% | AL15: =_xlfn.IFNA(IF(AC15="xxx","xxx",IF(VLOOKUP(R15,$BE$8:$BK$260,7,FALSE)=1,AF15&CHAR(10),SUBSTITUTE(AF15,"%","")&"%"&CHAR(10))),"xxx") -> 子弹数量 {3} | AM15: =_xlfn.IFNA(IF(AC15="xxx","xxx",IF(VLOOKUP(U15,$BE$8:$BK$260,7,FALSE)=1,AG15&CHAR(10),SUBSTITUTE(AG15,"%","")&"%"&CHAR(10))),"xxx") -> xxx | AN15: =_xlfn.IFNA(IF(AC15="xxx","xxx",IF(VLOOKUP(X15,$BE$8:$BK$260,7,FALSE)=1,AH15&CHAR(10),SUBSTITUTE(AH15,"%","")&"%"&CHAR(10))),"xxx") -> xxx | AO15: =_xlfn.CONCAT(AI15:AN15) -> 冰霜伤害 {0} 冰霜伤害 {1}% 冰霜减抗 {2}% 子弹数量 {3} xxxxxx | AP15: =SUBSTITUTE(AO15,"xxx","") -> 冰霜伤害 {0} 冰霜伤害 {1}% 冰霜减抗 {2}% 子弹数量 {3} | AQ15: 冰霜伤害+（15-25） 对冻结敌人的伤害+（20%~35%） 击败冻结状态的敌人时，（25%~35%）的几率触发【冰霜爆炸】 | AR15: =IFERROR(IF(AP15="",AQ15,AP15),AP15) -> 冰霜伤害 {0} 冰霜伤害 {1}% 冰霜减抗 {2}% 子弹数量 {3} | AS15: =IF(AR15<>AQ15,IF(ISNUMBER(SEARCH(CHAR(10),AR15)),SUBSTITUTE(AR15,CHAR(10),"",LEN(AR15)-LEN(SUBSTITUTE(AR15,CHAR(10),""))),AR15),AR15) -> 冰霜伤害 {0} 冰霜伤害 {1}% 冰霜减抗 {2}% 子弹数量 {3} | BE15: 物理伤害 | BF15: 固定值 | BG15: 204 | BH15: 10 | BI15: =COUNTIF($I$8:$I$1040,BE15)/COUNT($C$8:$C$1040)+COUNTIF($L$8:$L$1040,BE15)/COUNT($C$8:$C$1040)+COUNTIF($O$8:$O$1040,BE15)/COUNT($C$8:$C$1040)+COUNTIF($R$8:$R$1040,BE15)/COUNT($C$8:$C$1040)+COUNTIF($U$8:$U$1040,BE15)/COUNT($C$8:$C$1040)+COUNTIF($X$8:$X$1040,BE15)/COUNT($C$8:$C$1040) -> 0.029411765 | BK15: 1
C16: 14702 | D16: 血契之刃 | F16: 单手剑 | H16: 0 | AA16: ="1:"&IF(I16<>"",VLOOKUP(I16,$BE$8:$BH$260,3,FALSE)&","&VLOOKUP(I16,$BE$8:$BH$260,4,FALSE)*(1-K16)*J16&","&VLOOKUP(I16,$BE$8:$BH$260,4,FALSE)*(1+K16)*J16&",","xxx")&IF(L16<>"",VLOOKUP(L16,$BE$8:$BH$260,3,FALSE)&","&VLOOKUP(L16,$BE$8:$BH$260,4,FALSE)*(1-N16)*M16&","&VLOOKUP(L16,$BE$8:$BH$260,4,FALSE)*(1+N16)*M16&",","xxx")&IF(O16<>"",VLOOKUP(O16,$BE$8:$BH$260,3,FALSE)&","&VLOOKUP(O16,$BE$8:$BH$260,4,FALSE)*(1-Q16)*P16&","&VLOOKUP(O16,$BE$8:$BH$260,4,FALSE)*(1+Q16)*P16&",","xxx")&IF(R16<>"",VLOOKUP(R16,$BE$8:$BH$260,3,FALSE)&","&VLOOKUP(R16,$BE$8:$BH$260,4,FALSE)*(1-T16)*S16&","&VLOOKUP(R16,$BE$8:$BH$260,4,FALSE)*(1+T16)*S16&",","xxx")&IF(U16<>"",VLOOKUP(U16,$BE$8:$BH$260,3,FALSE)&","&VLOOKUP(U16,$BE$8:$BH$260,4,FALSE)*(1-W16)*V16&","&VLOOKUP(U16,$BE$8:$BH$260,4,FALSE)*(1+W16)*V16&",","xxx")&IF(X16<>"",VLOOKUP(X16,$BE$8:$BH$260,3,FALSE)&","&VLOOKUP(X16,$BE$8:$BH$260,4,FALSE)*(1-Z16)*Y16&","&VLOOKUP(X16,$BE$8:$BH$260,4,FALSE)*(1+Z16)*Y16&",","xxx") -> 1:xxxxxxxxxxxxxxxxxx | AB16: =IF(LEFT(SUBSTITUTE(AA16,"x",""),LEN(SUBSTITUTE(AA16,"x",""))-1)="1","",LEFT(SUBSTITUTE(AA16,"x",""),LEN(SUBSTITUTE(AA16,"x",""))-1)) | AC16: =IF(J16>0,I16&" "&"{"&J$6&"}","xxx") -> xxx | AD16: =IF(M16>0,L16&" "&"{"&M$6&"}","xxx") -> xxx | AE16: =IF(P16>0,O16&" "&"{"&P$6&"}","xxx") -> xxx | AF16: =IF(S16>0,R16&" "&"{"&S$6&"}","xxx") -> xxx | AG16: =IF(V16>0,U16&" "&"{"&V$6&"}","xxx") -> xxx | AH16: =IF(Y16>0,X16&" "&"{"&Y$6&"}","xxx") -> xxx | AI16: =_xlfn.IFNA(IF(AC16="xxx","xxx",IF(VLOOKUP(I16,$BE$8:$BK$260,7,FALSE)=1,AC16&CHAR(10),SUBSTITUTE(AC16,"%","")&"%"&CHAR(10))),"xxx") -> xxx | AJ16: =_xlfn.IFNA(IF(AC16="xxx","xxx",IF(VLOOKUP(L16,$BE$8:$BK$260,7,FALSE)=1,AD16&CHAR(10),SUBSTITUTE(AD16,"%","")&"%"&CHAR(10))),"xxx") -> xxx | AK16: =_xlfn.IFNA(IF(AC16="xxx","xxx",IF(VLOOKUP(O16,$BE$8:$BK$260,7,FALSE)=1,AE16&CHAR(10),SUBSTITUTE(AE16,"%","")&"%"&CHAR(10))),"xxx") -> xxx | AL16: =_xlfn.IFNA(IF(AC16="xxx","xxx",IF(VLOOKUP(R16,$BE$8:$BK$260,7,FALSE)=1,AF16&CHAR(10),SUBSTITUTE(AF16,"%","")&"%"&CHAR(10))),"xxx") -> xxx | AM16: =_xlfn.IFNA(IF(AC16="xxx","xxx",IF(VLOOKUP(U16,$BE$8:$BK$260,7,FALSE)=1,AG16&CHAR(10),SUBSTITUTE(AG16,"%","")&"%"&CHAR(10))),"xxx") -> xxx | AN16: =_xlfn.IFNA(IF(AC16="xxx","xxx",IF(VLOOKUP(X16,$BE$8:$BK$260,7,FALSE)=1,AH16&CHAR(10),SUBSTITUTE(AH16,"%","")&"%"&CHAR(10))),"xxx") -> xxx | AO16: =_xlfn.CONCAT(AI16:AN16) -> xxxxxxxxxxxxxxxxxx | AP16: =SUBSTITUTE(AO16,"xxx","") | AQ16: 暴击率+{0}% 对流血敌人造成的暴击伤害+40% 武器攻击对流血敌人吸血+1 | AR16: =IFERROR(IF(AP16="",AQ16,AP16),AP16) -> 暴击率+{0}% 对流血敌人造成的暴击伤害+40% 武器攻击对流血敌人吸血+1 | AS16: =IF(AR16<>AQ16,IF(ISNUMBER(SEARCH(CHAR(10),AR16)),SUBSTITUTE(AR16,CHAR(10),"",LEN(AR16)-LEN(SUBSTITUTE(AR16,CHAR(10),""))),AR16),AR16) -> 暴击率+{0}% 对流血敌人造成的暴击伤害+40% 武器攻击对流血敌人吸血+1 | BE16: 元素伤害 | BF16: 固定值 | BG16: 205 | BH16: 5 | BI16: =COUNTIF($I$8:$I$1040,BE16)/COUNT($C$8:$C$1040)+COUNTIF($L$8:$L$1040,BE16)/COUNT($C$8:$C$1040)+COUNTIF($O$8:$O$1040,BE16)/COUNT($C$8:$C$1040)+COUNTIF($R$8:$R$1040,BE16)/COUNT($C$8:$C$1040)+COUNTIF($U$8:$U$1040,BE16)/COUNT($C$8:$C$1040)+COUNTIF($X$8:$X$1040,BE16)/COUNT($C$8:$C$1040) -> 0.035947712 | BK16: 1
C17: 14703 | D17: 血痕之刃 | E17: 3 | F17: 单手剑 | H17: 8 | I17: 攻击速度% | J17: 1 | K17: 0.2 | L17: 施加流血时间提升 | M17: 2 | N17: 0.2 | O17: 流血系数 | P17: 2 | Q17: 0.2 | R17: 击杀加伤害 | S17: 2 | T17: 0 | U17: 击杀加生命值 | V17: 1 | W17: 0 | AA17: ="1:"&IF(I17<>"",VLOOKUP(I17,$BE$8:$BH$260,3,FALSE)&","&VLOOKUP(I17,$BE$8:$BH$260,4,FALSE)*(1-K17)*J17&","&VLOOKUP(I17,$BE$8:$BH$260,4,FALSE)*(1+K17)*J17&",","xxx")&IF(L17<>"",VLOOKUP(L17,$BE$8:$BH$260,3,FALSE)&","&VLOOKUP(L17,$BE$8:$BH$260,4,FALSE)*(1-N17)*M17&","&VLOOKUP(L17,$BE$8:$BH$260,4,FALSE)*(1+N17)*M17&",","xxx")&IF(O17<>"",VLOOKUP(O17,$BE$8:$BH$260,3,FALSE)&","&VLOOKUP(O17,$BE$8:$BH$260,4,FALSE)*(1-Q17)*P17&","&VLOOKUP(O17,$BE$8:$BH$260,4,FALSE)*(1+Q17)*P17&",","xxx")&IF(R17<>"",VLOOKUP(R17,$BE$8:$BH$260,3,FALSE)&","&VLOOKUP(R17,$BE$8:$BH$260,4,FALSE)*(1-T17)*S17&","&VLOOKUP(R17,$BE$8:$BH$260,4,FALSE)*(1+T17)*S17&",","xxx")&IF(U17<>"",VLOOKUP(U17,$BE$8:$BH$260,3,FALSE)&","&VLOOKUP(U17,$BE$8:$BH$260,4,FALSE)*(1-W17)*V17&","&VLOOKUP(U17,$BE$8:$BH$260,4,FALSE)*(1+W17)*V17&",","xxx")&IF(X17<>"",VLOOKUP(X17,$BE$8:$BH$260,3,FALSE)&","&VLOOKUP(X17,$BE$8:$BH$260,4,FALSE)*(1-Z17)*Y17&","&VLOOKUP(X17,$BE$8:$BH$260,4,FALSE)*(1+Z17)*Y17&",","xxx") -> 1:217,8,12,249,16,24,240,16,24,601,2,2,607,1,1,xxx | AB17: =IF(LEFT(SUBSTITUTE(AA17,"x",""),LEN(SUBSTITUTE(AA17,"x",""))-1)="1","",LEFT(SUBSTITUTE(AA17,"x",""),LEN(SUBSTITUTE(AA17,"x",""))-1)) -> 1:217,8,12,249,16,24,240,16,24,601,2,2,607,1,1 | AC17: =IF(J17>0,I17&" "&"{"&J$6&"}","xxx") -> 攻击速度% {0} | AD17: =IF(M17>0,L17&" "&"{"&M$6&"}","xxx") -> 施加流血时间提升 {1} | AE17: =IF(P17>0,O17&" "&"{"&P$6&"}","xxx") -> 流血系数 {2} | AF17: =IF(S17>0,R17&" "&"{"&S$6&"}","xxx") -> 击杀加伤害 {3} | AG17: =IF(V17>0,U17&" "&"{"&V$6&"}","xxx") -> 击杀加生命值 {4} | AH17: =IF(Y17>0,X17&" "&"{"&Y$6&"}","xxx") -> xxx | AI17: =_xlfn.IFNA(IF(AC17="xxx","xxx",IF(VLOOKUP(I17,$BE$8:$BK$260,7,FALSE)=1,AC17&CHAR(10),SUBSTITUTE(AC17,"%","")&"%"&CHAR(10))),"xxx") -> 攻击速度 {0}% | AJ17: =_xlfn.IFNA(IF(AC17="xxx","xxx",IF(VLOOKUP(L17,$BE$8:$BK$260,7,FALSE)=1,AD17&CHAR(10),SUBSTITUTE(AD17,"%","")&"%"&CHAR(10))),"xxx") -> 施加流血时间提升 {1}% | AK17: =_xlfn.IFNA(IF(AC17="xxx","xxx",IF(VLOOKUP(O17,$BE$8:$BK$260,7,FALSE)=1,AE17&CHAR(10),SUBSTITUTE(AE17,"%","")&"%"&CHAR(10))),"xxx") -> 流血系数 {2}% | AL17: =_xlfn.IFNA(IF(AC17="xxx","xxx",IF(VLOOKUP(R17,$BE$8:$BK$260,7,FALSE)=1,AF17&CHAR(10),SUBSTITUTE(AF17,"%","")&"%"&CHAR(10))),"xxx") -> 击杀加伤害 {3}% | AM17: =_xlfn.IFNA(IF(AC17="xxx","xxx",IF(VLOOKUP(U17,$BE$8:$BK$260,7,FALSE)=1,AG17&CHAR(10),SUBSTITUTE(AG17,"%","")&"%"&CHAR(10))),"xxx") -> 击杀加生命值 {4} | AN17: =_xlfn.IFNA(IF(AC17="xxx","xxx",IF(VLOOKUP(X17,$BE$8:$BK$260,7,FALSE)=1,AH17&CHAR(10),SUBSTITUTE(AH17,"%","")&"%"&CHAR(10))),"xxx") -> xxx | AO17: =_xlfn.CONCAT(AI17:AN17) -> 攻击速度 {0}% 施加流血时间提升 {1}% 流血系数 {2}% 击杀加伤害 {3}% 击杀加生命值 {4} xxx | AP17: =SUBSTITUTE(AO17,"xxx","") -> 攻击速度 {0}% 施加流血时间提升 {1}% 流血系数 {2}% 击杀加伤害 {3}% 击杀加生命值 {4} | AQ17: 武器攻击命中时有（25%~35%）的概率造成流血 对流血敌人造成的伤害+（30%~40%） 受到流血敌人的伤害减少（20%~30%） | AR17: =IFERROR(IF(AP17="",AQ17,AP17),AP17) -> 攻击速度 {0}% 施加流血时间提升 {1}% 流血系数 {2}% 击杀加伤害 {3}% 击杀加生命值 {4} | AS17: =IF(AR17<>AQ17,IF(ISNUMBER(SEARCH(CHAR(10),AR17)),SUBSTITUTE(AR17,CHAR(10),"",LEN(AR17)-LEN(SUBSTITUTE(AR17,CHAR(10),""))),AR17),AR17) -> 攻击速度 {0}% 施加流血时间提升 {1}% 流血系数 {2}% 击杀加伤害 {3}% 击杀加生命值 {4} | BE17: 冰霜伤害 | BF17: 固定值 | BG17: 206 | BH17: 10 | BI17: =COUNTIF($I$8:$I$1040,BE17)/COUNT($C$8:$C$1040)+COUNTIF($L$8:$L$1040,BE17)/COUNT($C$8:$C$1040)+COUNTIF($O$8:$O$1040,BE17)/COUNT($C$8:$C$1040)+COUNTIF($R$8:$R$1040,BE17)/COUNT($C$8:$C$1040)+COUNTIF($U$8:$U$1040,BE17)/COUNT($C$8:$C$1040)+COUNTIF($X$8:$X$1040,BE17)/COUNT($C$8:$C$1040) -> 0.062091503 | BK17: 1
C18: 14704 | D18: 恒辉之刃 | F18: 单手剑 | H18: 0 | AA18: ="1:"&IF(I18<>"",VLOOKUP(I18,$BE$8:$BH$260,3,FALSE)&","&VLOOKUP(I18,$BE$8:$BH$260,4,FALSE)*(1-K18)*J18&","&VLOOKUP(I18,$BE$8:$BH$260,4,FALSE)*(1+K18)*J18&",","xxx")&IF(L18<>"",VLOOKUP(L18,$BE$8:$BH$260,3,FALSE)&","&VLOOKUP(L18,$BE$8:$BH$260,4,FALSE)*(1-N18)*M18&","&VLOOKUP(L18,$BE$8:$BH$260,4,FALSE)*(1+N18)*M18&",","xxx")&IF(O18<>"",VLOOKUP(O18,$BE$8:$BH$260,3,FALSE)&","&VLOOKUP(O18,$BE$8:$BH$260,4,FALSE)*(1-Q18)*P18&","&VLOOKUP(O18,$BE$8:$BH$260,4,FALSE)*(1+Q18)*P18&",","xxx")&IF(R18<>"",VLOOKUP(R18,$BE$8:$BH$260,3,FALSE)&","&VLOOKUP(R18,$BE$8:$BH$260,4,FALSE)*(1-T18)*S18&","&VLOOKUP(R18,$BE$8:$BH$260,4,FALSE)*(1+T18)*S18&",","xxx")&IF(U18<>"",VLOOKUP(U18,$BE$8:$BH$260,3,FALSE)&","&VLOOKUP(U18,$BE$8:$BH$260,4,FALSE)*(1-W18)*V18&","&VLOOKUP(U18,$BE$8:$BH$260,4,FALSE)*(1+W18)*V18&",","xxx")&IF(X18<>"",VLOOKUP(X18,$BE$8:$BH$260,3,FALSE)&","&VLOOKUP(X18,$BE$8:$BH$260,4,FALSE)*(1-Z18)*Y18&","&VLOOKUP(X18,$BE$8:$BH$260,4,FALSE)*(1+Z18)*Y18&",","xxx") -> 1:xxxxxxxxxxxxxxxxxx | AB18: =IF(LEFT(SUBSTITUTE(AA18,"x",""),LEN(SUBSTITUTE(AA18,"x",""))-1)="1","",LEFT(SUBSTITUTE(AA18,"x",""),LEN(SUBSTITUTE(AA18,"x",""))-1)) | AC18: =IF(J18>0,I18&" "&"{"&J$6&"}","xxx") -> xxx | AD18: =IF(M18>0,L18&" "&"{"&M$6&"}","xxx") -> xxx | AE18: =IF(P18>0,O18&" "&"{"&P$6&"}","xxx") -> xxx | AF18: =IF(S18>0,R18&" "&"{"&S$6&"}","xxx") -> xxx | AG18: =IF(V18>0,U18&" "&"{"&V$6&"}","xxx") -> xxx | AH18: =IF(Y18>0,X18&" "&"{"&Y$6&"}","xxx") -> xxx | AI18: =_xlfn.IFNA(IF(AC18="xxx","xxx",IF(VLOOKUP(I18,$BE$8:$BK$260,7,FALSE)=1,AC18&CHAR(10),SUBSTITUTE(AC18,"%","")&"%"&CHAR(10))),"xxx") -> xxx | AJ18: =_xlfn.IFNA(IF(AC18="xxx","xxx",IF(VLOOKUP(L18,$BE$8:$BK$260,7,FALSE)=1,AD18&CHAR(10),SUBSTITUTE(AD18,"%","")&"%"&CHAR(10))),"xxx") -> xxx | AK18: =_xlfn.IFNA(IF(AC18="xxx","xxx",IF(VLOOKUP(O18,$BE$8:$BK$260,7,FALSE)=1,AE18&CHAR(10),SUBSTITUTE(AE18,"%","")&"%"&CHAR(10))),"xxx") -> xxx | AL18: =_xlfn.IFNA(IF(AC18="xxx","xxx",IF(VLOOKUP(R18,$BE$8:$BK$260,7,FALSE)=1,AF18&CHAR(10),SUBSTITUTE(AF18,"%","")&"%"&CHAR(10))),"xxx") -> xxx | AM18: =_xlfn.IFNA(IF(AC18="xxx","xxx",IF(VLOOKUP(U18,$BE$8:$BK$260,7,FALSE)=1,AG18&CHAR(10),SUBSTITUTE(AG18,"%","")&"%"&CHAR(10))),"xxx") -> xxx | AN18: =_xlfn.IFNA(IF(AC18="xxx","xxx",IF(VLOOKUP(X18,$BE$8:$BK$260,7,FALSE)=1,AH18&CHAR(10),SUBSTITUTE(AH18,"%","")&"%"&CHAR(10))),"xxx") -> xxx | AO18: =_xlfn.CONCAT(AI18:AN18) -> xxxxxxxxxxxxxxxxxx | AP18: =SUBSTITUTE(AO18,"xxx","") | AQ18: 力量+{0} 敏捷+{1} 智力+{2} 元素伤害+{3}% 元素抗性+{4}% | AR18: =IFERROR(IF(AP18="",AQ18,AP18),AP18) -> 力量+{0} 敏捷+{1} 智力+{2} 元素伤害+{3}% 元素抗性+{4}% | AS18: =IF(AR18<>AQ18,IF(ISNUMBER(SEARCH(CHAR(10),AR18)),SUBSTITUTE(AR18,CHAR(10),"",LEN(AR18)-LEN(SUBSTITUTE(AR18,CHAR(10),""))),AR18),AR18) -> 力量+{0} 敏捷+{1} 智力+{2} 元素伤害+{3}% 元素抗性+{4}% | BE18: 火焰伤害 | BF18: 固定值 | BG18: 207 | BH18: 10 | BI18: =COUNTIF($I$8:$I$1040,BE18)/COUNT($C$8:$C$1040)+COUNTIF($L$8:$L$1040,BE18)/COUNT($C$8:$C$1040)+COUNTIF($O$8:$O$1040,BE18)/COUNT($C$8:$C$1040)+COUNTIF($R$8:$R$1040,BE18)/COUNT($C$8:$C$1040)+COUNTIF($U$8:$U$1040,BE18)/COUNT($C$8:$C$1040)+COUNTIF($X$8:$X$1040,BE18)/COUNT($C$8:$C$1040) -> 0.049019608 | BK18: 1
C19: 14705 | D19: 陨星之刃 | E19: 2 | F19: 单手剑 | H19: 8 | I19: 闪电伤害% | J19: 2 | K19: 0.2 | L19: 闪电减抗% | M19: 1 | N19: 0.2 | O19: 攻击速度% | P19: 2 | Q19: 0.2 | R19: 闪电伤害 | S19: 2 | T19: 0.2 | U19: 附加闪电伤害% | V19: 1 | W19: 0 | AA19: ="1:"&IF(I19<>"",VLOOKUP(I19,$BE$8:$BH$260,3,FALSE)&","&VLOOKUP(I19,$BE$8:$BH$260,4,FALSE)*(1-K19)*J19&","&VLOOKUP(I19,$BE$8:$BH$260,4,FALSE)*(1+K19)*J19&",","xxx")&IF(L19<>"",VLOOKUP(L19,$BE$8:$BH$260,3,FALSE)&","&VLOOKUP(L19,$BE$8:$BH$260,4,FALSE)*(1-N19)*M19&","&VLOOKUP(L19,$BE$8:$BH$260,4,FALSE)*(1+N19)*M19&",","xxx")&IF(O19<>"",VLOOKUP(O19,$BE$8:$BH$260,3,FALSE)&","&VLOOKUP(O19,$BE$8:$BH$260,4,FALSE)*(1-Q19)*P19&","&VLOOKUP(O19,$BE$8:$BH$260,4,FALSE)*(1+Q19)*P19&",","xxx")&IF(R19<>"",VLOOKUP(R19,$BE$8:$BH$260,3,FALSE)&","&VLOOKUP(R19,$BE$8:$BH$260,4,FALSE)*(1-T19)*S19&","&VLOOKUP(R19,$BE$8:$BH$260,4,FALSE)*(1+T19)*S19&",","xxx")&IF(U19<>"",VLOOKUP(U19,$BE$8:$BH$260,3,FALSE)&","&VLOOKUP(U19,$BE$8:$BH$260,4,FALSE)*(1-W19)*V19&","&VLOOKUP(U19,$BE$8:$BH$260,4,FALSE)*(1+W19)*V19&",","xxx")&IF(X19<>"",VLOOKUP(X19,$BE$8:$BH$260,3,FALSE)&","&VLOOKUP(X19,$BE$8:$BH$260,4,FALSE)*(1-Z19)*Y19&","&VLOOKUP(X19,$BE$8:$BH$260,4,FALSE)*(1+Z19)*Y19&",","xxx") -> 1:215,16,24,224,4,6,217,16,24,208,16,24,238,10,10,xxx | AB19: =IF(LEFT(SUBSTITUTE(AA19,"x",""),LEN(SUBSTITUTE(AA19,"x",""))-1)="1","",LEFT(SUBSTITUTE(AA19,"x",""),LEN(SUBSTITUTE(AA19,"x",""))-1)) -> 1:215,16,24,224,4,6,217,16,24,208,16,24,238,10,10 | AC19: =IF(J19>0,I19&" "&"{"&J$6&"}","xxx") -> 闪电伤害% {0} | AD19: =IF(M19>0,L19&" "&"{"&M$6&"}","xxx") -> 闪电减抗% {1} | AE19: =IF(P19>0,O19&" "&"{"&P$6&"}","xxx") -> 攻击速度% {2} | AF19: =IF(S19>0,R19&" "&"{"&S$6&"}","xxx") -> 闪电伤害 {3} | AG19: =IF(V19>0,U19&" "&"{"&V$6&"}","xxx") -> 附加闪电伤害% {4} | AH19: =IF(Y19>0,X19&" "&"{"&Y$6&"}","xxx") -> xxx | AI19: =_xlfn.IFNA(IF(AC19="xxx","xxx",IF(VLOOKUP(I19,$BE$8:$BK$260,7,FALSE)=1,AC19&CHAR(10),SUBSTITUTE(AC19,"%","")&"%"&CHAR(10))),"xxx") -> 闪电伤害 {0}% | AJ19: =_xlfn.IFNA(IF(AC19="xxx","xxx",IF(VLOOKUP(L19,$BE$8:$BK$260,7,FALSE)=1,AD19&CHAR(10),SUBSTITUTE(AD19,"%","")&"%"&CHAR(10))),"xxx") -> 闪电减抗 {1}% | AK19: =_xlfn.IFNA(IF(AC19="xxx","xxx",IF(VLOOKUP(O19,$BE$8:$BK$260,7,FALSE)=1,AE19&CHAR(10),SUBSTITUTE(AE19,"%","")&"%"&CHAR(10))),"xxx") -> 攻击速度 {2}% | AL19: =_xlfn.IFNA(IF(AC19="xxx","xxx",IF(VLOOKUP(R19,$BE$8:$BK$260,7,FALSE)=1,AF19&CHAR(10),SUBSTITUTE(AF19,"%","")&"%"&CHAR(10))),"xxx") -> 闪电伤害 {3} | AM19: =_xlfn.IFNA(IF(AC19="xxx","xxx",IF(VLOOKUP(U19,$BE$8:$BK$260,7,FALSE)=1,AG19&CHAR(10),SUBSTITUTE(AG19,"%","")&"%"&CHAR(10))),"xxx") -> 附加闪电伤害 {4}% | AN19: =_xlfn.IFNA(IF(AC19="xxx","xxx",IF(VLOOKUP(X19,$BE$8:$BK$260,7,FALSE)=1,AH19&CHAR(10),SUBSTITUTE(AH19,"%","")&"%"&CHAR(10))),"xxx") -> xxx | AO19: =_xlfn.CONCAT(AI19:AN19) -> 闪电伤害 {0}% 闪电减抗 {1}% 攻击速度 {2}% 闪电伤害 {3} 附加闪电伤害 {4}% xxx | AP19: =SUBSTITUTE(AO19,"xxx","") -> 闪电伤害 {0}% 闪电减抗 {1}% 攻击速度 {2}% 闪电伤害 {3} 附加闪电伤害 {4}% | AQ19: 暴击率+（5%~15%） 暴击时有（35%-45%）的概率释放 5 级的【陨石术】 陨石术冷却时间减少（40%~50%） | AR19: =IFERROR(IF(AP19="",AQ19,AP19),AP19) -> 闪电伤害 {0}% 闪电减抗 {1}% 攻击速度 {2}% 闪电伤害 {3} 附加闪电伤害 {4}% | AS19: =IF(AR19<>AQ19,IF(ISNUMBER(SEARCH(CHAR(10),AR19)),SUBSTITUTE(AR19,CHAR(10),"",LEN(AR19)-LEN(SUBSTITUTE(AR19,CHAR(10),""))),AR19),AR19) -> 闪电伤害 {0}% 闪电减抗 {1}% 攻击速度 {2}% 闪电伤害 {3} 附加闪电伤害 {4}% | BE19: 闪电伤害 | BF19: 固定值 | BG19: 208 | BH19: 10 | BI19: =COUNTIF($I$8:$I$1040,BE19)/COUNT($C$8:$C$1040)+COUNTIF($L$8:$L$1040,BE19)/COUNT($C$8:$C$1040)+COUNTIF($O$8:$O$1040,BE19)/COUNT($C$8:$C$1040)+COUNTIF($R$8:$R$1040,BE19)/COUNT($C$8:$C$1040)+COUNTIF($U$8:$U$1040,BE19)/COUNT($C$8:$C$1040)+COUNTIF($X$8:$X$1040,BE19)/COUNT($C$8:$C$1040) -> 0.052287582 | BK19: 1
